/*
 *** MADE BY MITHION'S .SCHEMATIC TO JAVA CONVERTING TOOL v1.6 ***
 */

package oceania.gen;

import java.util.ArrayList;
import java.util.List;
import java.util.Random;

import oceania.blocks.Blocks;

import cpw.mods.fml.common.IWorldGenerator;

import net.minecraft.block.Block;
import net.minecraft.world.World;
import net.minecraft.world.biome.BiomeGenBase;
import net.minecraft.world.chunk.IChunkProvider;

public class WorldGenUnderwaterVillage implements IWorldGenerator
{
	
	private boolean locationIsValidSpawn(World world, int x, int y, int z)
	{
		List<Integer> validDirt = new ArrayList<Integer>();
		List<Integer> validWater = new ArrayList<Integer>();
		validWater.add(world.getBlockId(x + 8, y + 7, z + 8));
		validWater.add(world.getBlockId(x, y + 7, z));
		validWater.add(world.getBlockId(x + 16, y + 7, z + 8));
		validWater.add(world.getBlockId(x + 8, y + 7, z + 16));
		validWater.add(world.getBlockId(x + 16, y + 7, z + 16));
		
		validDirt.add(world.getBlockId(x + 8, y + 1, z + 8));
		validDirt.add(world.getBlockId(x, y + 1, z));
		validDirt.add(world.getBlockId(x + 16, y + 1, z + 8));
		validDirt.add(world.getBlockId(x + 8, y + 1, z + 16));
		validDirt.add(world.getBlockId(x + 16, y + 1, z + 16));
		
		if (world.rand.nextInt(50) != 1)
			return false;
		
		for (int validID : validWater)
		{
			if (!(validID == Block.waterStill.blockID || validID == Block.waterMoving.blockID))
				return false;
		}
		
		for (int validID : validDirt)
		{
			if (!(validID == Block.dirt.blockID || validID == Block.blockClay.blockID || validID == Block.sand.blockID))
				return false;
		}
		
		return true;
	}
	
	@Override
	public void generate(Random random, int chunkX, int chunkZ, World world, IChunkProvider chunkGenerator, IChunkProvider chunkProvider)
	{
		int x = (chunkX * 16) + random.nextInt(16); // x
		int y = 0; // y
		int z = (chunkZ * 16) + random.nextInt(16); // z
		
		for (int count = 40; count <= 60; count++)
		{
			int blockID = world.getBlockId(x, count + 1, z);
			int blockAboveID = world.getBlockId(x, count + 2, z);
			if ((blockID == Block.sand.blockID || blockID == Block.dirt.blockID) && (blockAboveID == Block.waterStill.blockID || blockAboveID == Block.waterMoving.blockID))
			{
				y = count - 1;
				break;
			}
		}
		
		if (world.getBiomeGenForCoords(x, z) != BiomeGenBase.ocean || !locationIsValidSpawn(world, x, y, z) || y == 0)
		{
			return;
		}
		
		System.out.println("New Underwater Village at " + x + " " + y + " " + z + " ");
		world.setBlock(x + 0, y + 0, z + 0, Block.dirt.blockID);
		world.setBlock(x + 0, y + 0, z + 1, Block.dirt.blockID);
		world.setBlock(x + 0, y + 0, z + 2, Block.dirt.blockID);
		world.setBlock(x + 0, y + 0, z + 3, Block.dirt.blockID);
		world.setBlock(x + 0, y + 0, z + 4, Block.dirt.blockID);
		world.setBlock(x + 0, y + 0, z + 5, Block.dirt.blockID);
		world.setBlock(x + 0, y + 0, z + 6, Block.dirt.blockID);
		world.setBlock(x + 0, y + 0, z + 7, Block.dirt.blockID);
		world.setBlock(x + 0, y + 0, z + 8, Block.dirt.blockID);
		world.setBlock(x + 0, y + 0, z + 9, Block.dirt.blockID);
		world.setBlock(x + 0, y + 0, z + 10, Block.dirt.blockID);
		world.setBlock(x + 0, y + 0, z + 11, Block.dirt.blockID);
		world.setBlock(x + 0, y + 0, z + 12, Block.dirt.blockID);
		world.setBlock(x + 0, y + 0, z + 13, Block.dirt.blockID);
		world.setBlock(x + 0, y + 0, z + 14, Block.dirt.blockID);
		world.setBlock(x + 0, y + 0, z + 15, Block.dirt.blockID);
		world.setBlock(x + 0, y + 0, z + 16, Block.dirt.blockID);
		world.setBlock(x + 0, y + 1, z + 6, Block.stoneBrick.blockID);
		world.setBlock(x + 0, y + 1, z + 7, Block.stoneBrick.blockID);
		world.setBlock(x + 0, y + 1, z + 8, Block.stoneBrick.blockID);
		world.setBlock(x + 0, y + 1, z + 9, Block.stoneBrick.blockID);
		world.setBlock(x + 0, y + 1, z + 10, Block.stoneBrick.blockID);
		world.setBlock(x + 0, y + 2, z + 6, 155, 2, 3);
		world.setBlock(x + 0, y + 2, z + 7, Blocks.blockPlaceholder.blockID);
		world.setBlock(x + 0, y + 2, z + 8, Blocks.blockPlaceholder.blockID);
		world.setBlock(x + 0, y + 2, z + 9, Blocks.blockPlaceholder.blockID);
		world.setBlock(x + 0, y + 2, z + 10, 155, 2, 3);
		world.setBlock(x + 0, y + 3, z + 6, 155, 2, 3);
		world.setBlock(x + 0, y + 3, z + 7, Blocks.blockPlaceholder.blockID);
		world.setBlock(x + 0, y + 3, z + 8, Blocks.blockPlaceholder.blockID);
		world.setBlock(x + 0, y + 3, z + 9, Blocks.blockPlaceholder.blockID);
		world.setBlock(x + 0, y + 3, z + 10, 155, 2, 3);
		world.setBlock(x + 0, y + 4, z + 6, 155, 2, 3);
		world.setBlock(x + 0, y + 4, z + 7, Blocks.blockPlaceholder.blockID);
		world.setBlock(x + 0, y + 4, z + 8, Blocks.blockPlaceholder.blockID);
		world.setBlock(x + 0, y + 4, z + 9, Blocks.blockPlaceholder.blockID);
		world.setBlock(x + 0, y + 4, z + 10, 155, 2, 3);		
		world.setBlock(x + 0, y + 5, z + 6, Block.stoneBrick.blockID);
		world.setBlock(x + 0, y + 5, z + 7, Blocks.blockLimestone.blockID, 1, 3);
		world.setBlock(x + 0, y + 5, z + 8, Blocks.blockLimestone.blockID, 1, 3);
		world.setBlock(x + 0, y + 5, z + 9, Blocks.blockLimestone.blockID, 1, 3);
		world.setBlock(x + 0, y + 5, z + 10, Block.stoneBrick.blockID);
		world.setBlock(x + 1, y + 0, z + 0, Block.dirt.blockID);
		world.setBlock(x + 1, y + 0, z + 1, Block.dirt.blockID);
		world.setBlock(x + 1, y + 0, z + 2, Block.dirt.blockID);
		world.setBlock(x + 1, y + 0, z + 3, Block.dirt.blockID);
		world.setBlock(x + 1, y + 0, z + 4, Block.dirt.blockID);
		world.setBlock(x + 1, y + 0, z + 5, Block.dirt.blockID);
		world.setBlock(x + 1, y + 0, z + 6, Block.dirt.blockID);
		world.setBlock(x + 1, y + 0, z + 7, Block.dirt.blockID);
		world.setBlock(x + 1, y + 0, z + 8, Block.dirt.blockID);
		world.setBlock(x + 1, y + 0, z + 9, Block.dirt.blockID);
		world.setBlock(x + 1, y + 0, z + 10, Block.dirt.blockID);
		world.setBlock(x + 1, y + 0, z + 11, Block.dirt.blockID);
		world.setBlock(x + 1, y + 0, z + 12, Block.dirt.blockID);
		world.setBlock(x + 1, y + 0, z + 13, Block.dirt.blockID);
		world.setBlock(x + 1, y + 0, z + 14, Block.dirt.blockID);
		world.setBlock(x + 1, y + 0, z + 15, Block.dirt.blockID);
		world.setBlock(x + 1, y + 0, z + 16, Block.dirt.blockID);
		world.setBlock(x + 1, y + 1, z + 4, Block.stoneBrick.blockID);
		world.setBlock(x + 1, y + 1, z + 5, Block.stoneBrick.blockID);
		world.setBlock(x + 1, y + 1, z + 11, Block.stoneBrick.blockID);
		world.setBlock(x + 1, y + 1, z + 12, Block.stoneBrick.blockID);
		world.setBlock(x + 1, y + 2, z + 4, Block.glass.blockID);
		world.setBlock(x + 1, y + 2, z + 5, Block.glass.blockID);
		world.setBlock(x + 1, y + 2, z + 11, Block.glass.blockID);
		world.setBlock(x + 1, y + 2, z + 12, Block.glass.blockID);
		world.setBlock(x + 1, y + 3, z + 4, Block.glass.blockID);
		world.setBlock(x + 1, y + 3, z + 5, Block.glass.blockID);
		world.setBlock(x + 1, y + 3, z + 11, Block.glass.blockID);
		world.setBlock(x + 1, y + 3, z + 12, Block.glass.blockID);
		world.setBlock(x + 1, y + 4, z + 6, Block.glass.blockID);
		world.setBlock(x + 1, y + 4, z + 10, Block.glass.blockID);
		world.setBlock(x + 1, y + 5, z + 7, Block.glass.blockID);
		world.setBlock(x + 1, y + 5, z + 8, Block.glass.blockID);
		world.setBlock(x + 1, y + 5, z + 9, Block.glass.blockID);
		world.setBlock(x + 2, y + 0, z + 0, Block.dirt.blockID);
		world.setBlock(x + 2, y + 0, z + 1, Block.dirt.blockID);
		world.setBlock(x + 2, y + 0, z + 2, Block.dirt.blockID);
		world.setBlock(x + 2, y + 0, z + 3, Block.dirt.blockID);
		world.setBlock(x + 2, y + 0, z + 4, Block.dirt.blockID);
		world.setBlock(x + 2, y + 0, z + 5, Block.dirt.blockID);
		world.setBlock(x + 2, y + 0, z + 6, Block.dirt.blockID);
		world.setBlock(x + 2, y + 0, z + 7, Block.dirt.blockID);
		world.setBlock(x + 2, y + 0, z + 8, Block.dirt.blockID);
		world.setBlock(x + 2, y + 0, z + 9, Block.dirt.blockID);
		world.setBlock(x + 2, y + 0, z + 10, Block.dirt.blockID);
		world.setBlock(x + 2, y + 0, z + 11, Block.dirt.blockID);
		world.setBlock(x + 2, y + 0, z + 12, Block.dirt.blockID);
		world.setBlock(x + 2, y + 0, z + 13, Block.dirt.blockID);
		world.setBlock(x + 2, y + 0, z + 14, Block.dirt.blockID);
		world.setBlock(x + 2, y + 0, z + 15, Block.dirt.blockID);
		world.setBlock(x + 2, y + 0, z + 16, Block.dirt.blockID);
		world.setBlock(x + 2, y + 1, z + 3, Block.stoneBrick.blockID);
		world.setBlock(x + 2, y + 1, z + 13, Block.stoneBrick.blockID);
		world.setBlock(x + 2, y + 2, z + 3, Block.glass.blockID);
		world.setBlock(x + 2, y + 2, z + 13, Block.glass.blockID);
		world.setBlock(x + 2, y + 3, z + 3, Block.glass.blockID);
		world.setBlock(x + 2, y + 3, z + 13, Block.glass.blockID);
		world.setBlock(x + 2, y + 4, z + 4, Block.glass.blockID);
		world.setBlock(x + 2, y + 4, z + 5, Block.glass.blockID);
		world.setBlock(x + 2, y + 4, z + 11, Block.glass.blockID);
		world.setBlock(x + 2, y + 4, z + 12, Block.glass.blockID);
		world.setBlock(x + 2, y + 5, z + 6, Block.glass.blockID);
		world.setBlock(x + 2, y + 5, z + 7, Block.glass.blockID);
		world.setBlock(x + 2, y + 5, z + 8, Block.glass.blockID);
		world.setBlock(x + 2, y + 5, z + 9, Block.glass.blockID);
		world.setBlock(x + 2, y + 5, z + 10, Block.glass.blockID);
		world.setBlock(x + 3, y + 0, z + 0, Block.dirt.blockID);
		world.setBlock(x + 3, y + 0, z + 1, Block.dirt.blockID);
		world.setBlock(x + 3, y + 0, z + 2, Block.dirt.blockID);
		world.setBlock(x + 3, y + 0, z + 3, Block.dirt.blockID);
		world.setBlock(x + 3, y + 0, z + 4, Block.dirt.blockID);
		world.setBlock(x + 3, y + 0, z + 5, Block.dirt.blockID);
		world.setBlock(x + 3, y + 0, z + 6, Block.dirt.blockID);
		world.setBlock(x + 3, y + 0, z + 7, Block.dirt.blockID);
		world.setBlock(x + 3, y + 0, z + 8, Block.dirt.blockID);
		world.setBlock(x + 3, y + 0, z + 9, Block.dirt.blockID);
		world.setBlock(x + 3, y + 0, z + 10, Block.dirt.blockID);
		world.setBlock(x + 3, y + 0, z + 11, Block.dirt.blockID);
		world.setBlock(x + 3, y + 0, z + 12, Block.dirt.blockID);
		world.setBlock(x + 3, y + 0, z + 13, Block.dirt.blockID);
		world.setBlock(x + 3, y + 0, z + 14, Block.dirt.blockID);
		world.setBlock(x + 3, y + 0, z + 15, Block.dirt.blockID);
		world.setBlock(x + 3, y + 0, z + 16, Block.dirt.blockID);
		world.setBlock(x + 3, y + 1, z + 2, Block.stoneBrick.blockID);
		world.setBlock(x + 3, y + 1, z + 8, Blocks.blockDepulsor.blockID);
		world.setBlock(x + 3, y + 1, z + 14, Block.stoneBrick.blockID);
		world.setBlock(x + 3, y + 2, z + 2, Block.glass.blockID);
		world.setBlock(x + 3, y + 2, z + 14, Block.glass.blockID);
		world.setBlock(x + 3, y + 3, z + 2, Block.glass.blockID);
		world.setBlock(x + 3, y + 3, z + 14, Block.glass.blockID);
		world.setBlock(x + 3, y + 4, z + 3, Block.glass.blockID);
		world.setBlock(x + 3, y + 4, z + 13, Block.glass.blockID);
		world.setBlock(x + 3, y + 5, z + 4, Block.glass.blockID);
		world.setBlock(x + 3, y + 5, z + 5, Block.glass.blockID);
		world.setBlock(x + 3, y + 5, z + 11, Block.glass.blockID);
		world.setBlock(x + 3, y + 5, z + 12, Block.glass.blockID);
		world.setBlock(x + 3, y + 6, z + 6, Block.glass.blockID);
		world.setBlock(x + 3, y + 6, z + 7, Block.glass.blockID);
		world.setBlock(x + 3, y + 6, z + 8, Block.glass.blockID);
		world.setBlock(x + 3, y + 6, z + 9, Block.glass.blockID);
		world.setBlock(x + 3, y + 6, z + 10, Block.glass.blockID);
		world.setBlock(x + 4, y + 0, z + 0, Block.dirt.blockID);
		world.setBlock(x + 4, y + 0, z + 1, Block.dirt.blockID);
		world.setBlock(x + 4, y + 0, z + 2, Block.dirt.blockID);
		world.setBlock(x + 4, y + 0, z + 3, Block.dirt.blockID);
		world.setBlock(x + 4, y + 0, z + 4, Block.dirt.blockID);
		world.setBlock(x + 4, y + 0, z + 5, Block.dirt.blockID);
		world.setBlock(x + 4, y + 0, z + 6, Block.dirt.blockID);
		world.setBlock(x + 4, y + 0, z + 7, Block.dirt.blockID);
		world.setBlock(x + 4, y + 0, z + 8, Block.dirt.blockID);
		world.setBlock(x + 4, y + 0, z + 9, Block.dirt.blockID);
		world.setBlock(x + 4, y + 0, z + 10, Block.dirt.blockID);
		world.setBlock(x + 4, y + 0, z + 11, Block.dirt.blockID);
		world.setBlock(x + 4, y + 0, z + 12, Block.dirt.blockID);
		world.setBlock(x + 4, y + 0, z + 13, Block.dirt.blockID);
		world.setBlock(x + 4, y + 0, z + 14, Block.dirt.blockID);
		world.setBlock(x + 4, y + 0, z + 15, Block.dirt.blockID);
		world.setBlock(x + 4, y + 0, z + 16, Block.dirt.blockID);
		world.setBlock(x + 4, y + 1, z + 1, Block.stoneBrick.blockID);
		world.setBlock(x + 4, y + 1, z + 7, Block.stoneBrick.blockID);
		world.setBlock(x + 4, y + 1, z + 8, Block.stoneBrick.blockID);
		world.setBlock(x + 4, y + 1, z + 9, Block.stoneBrick.blockID);
		world.setBlock(x + 4, y + 1, z + 15, Block.stoneBrick.blockID);
		world.setBlock(x + 4, y + 2, z + 1, Block.glass.blockID);
		world.setBlock(x + 4, y + 2, z + 15, Block.glass.blockID);
		world.setBlock(x + 4, y + 3, z + 1, Block.glass.blockID);
		world.setBlock(x + 4, y + 3, z + 15, Block.glass.blockID);
		world.setBlock(x + 4, y + 4, z + 2, Block.glass.blockID);
		world.setBlock(x + 4, y + 4, z + 14, Block.glass.blockID);
		world.setBlock(x + 4, y + 5, z + 3, Block.glass.blockID);
		world.setBlock(x + 4, y + 5, z + 13, Block.glass.blockID);
		world.setBlock(x + 4, y + 6, z + 4, Block.glass.blockID);
		world.setBlock(x + 4, y + 6, z + 5, Block.glass.blockID);
		world.setBlock(x + 4, y + 6, z + 6, Block.glass.blockID);
		world.setBlock(x + 4, y + 6, z + 7, Block.glass.blockID);
		world.setBlock(x + 4, y + 6, z + 8, Block.glass.blockID);
		world.setBlock(x + 4, y + 6, z + 9, Block.glass.blockID);
		world.setBlock(x + 4, y + 6, z + 10, Block.glass.blockID);
		world.setBlock(x + 4, y + 6, z + 11, Block.glass.blockID);
		world.setBlock(x + 4, y + 6, z + 12, Block.glass.blockID);
		world.setBlock(x + 5, y + 0, z + 0, Block.dirt.blockID);
		world.setBlock(x + 5, y + 0, z + 1, Block.dirt.blockID);
		world.setBlock(x + 5, y + 0, z + 2, Block.dirt.blockID);
		world.setBlock(x + 5, y + 0, z + 3, Block.dirt.blockID);
		world.setBlock(x + 5, y + 0, z + 4, Block.dirt.blockID);
		world.setBlock(x + 5, y + 0, z + 5, Block.dirt.blockID);
		world.setBlock(x + 5, y + 0, z + 6, Block.dirt.blockID);
		world.setBlock(x + 5, y + 0, z + 7, Block.dirt.blockID);
		world.setBlock(x + 5, y + 0, z + 8, Block.dirt.blockID);
		world.setBlock(x + 5, y + 0, z + 9, Block.dirt.blockID);
		world.setBlock(x + 5, y + 0, z + 10, Block.dirt.blockID);
		world.setBlock(x + 5, y + 0, z + 11, Block.dirt.blockID);
		world.setBlock(x + 5, y + 0, z + 12, Block.dirt.blockID);
		world.setBlock(x + 5, y + 0, z + 13, Block.dirt.blockID);
		world.setBlock(x + 5, y + 0, z + 14, Block.dirt.blockID);
		world.setBlock(x + 5, y + 0, z + 15, Block.dirt.blockID);
		world.setBlock(x + 5, y + 0, z + 16, Block.dirt.blockID);
		world.setBlock(x + 5, y + 1, z + 1, Block.stoneBrick.blockID);
		world.setBlock(x + 5, y + 1, z + 6, Block.stoneBrick.blockID);
		world.setBlock(x + 5, y + 1, z + 7, Blocks.blockLimestone.blockID, 1, 3);
		world.setBlock(x + 5, y + 1, z + 8, Blocks.blockLimestone.blockID, 1, 3);
		world.setBlock(x + 5, y + 1, z + 9, Blocks.blockLimestone.blockID, 1, 3);
		world.setBlock(x + 5, y + 1, z + 10, Block.stoneBrick.blockID);
		world.setBlock(x + 5, y + 1, z + 15, Block.stoneBrick.blockID);
		world.setBlock(x + 5, y + 2, z + 1, Block.glass.blockID);
		world.setBlock(x + 5, y + 2, z + 15, Block.glass.blockID);
		world.setBlock(x + 5, y + 3, z + 1, Block.glass.blockID);
		world.setBlock(x + 5, y + 3, z + 15, Block.glass.blockID);
		world.setBlock(x + 5, y + 4, z + 2, Block.glass.blockID);
		world.setBlock(x + 5, y + 4, z + 14, Block.glass.blockID);
		world.setBlock(x + 5, y + 5, z + 3, Block.glass.blockID);
		world.setBlock(x + 5, y + 5, z + 13, Block.glass.blockID);
		world.setBlock(x + 5, y + 6, z + 4, Block.glass.blockID);
		world.setBlock(x + 5, y + 6, z + 5, Block.glass.blockID);
		world.setBlock(x + 5, y + 6, z + 11, Block.glass.blockID);
		world.setBlock(x + 5, y + 6, z + 12, Block.glass.blockID);
		world.setBlock(x + 5, y + 7, z + 6, Block.glass.blockID);
		world.setBlock(x + 5, y + 7, z + 7, Block.glass.blockID);
		world.setBlock(x + 5, y + 7, z + 8, Block.glass.blockID);
		world.setBlock(x + 5, y + 7, z + 9, Block.glass.blockID);
		world.setBlock(x + 5, y + 7, z + 10, Block.glass.blockID);
		world.setBlock(x + 6, y + 0, z + 0, Block.dirt.blockID);
		world.setBlock(x + 6, y + 0, z + 1, Block.dirt.blockID);
		world.setBlock(x + 6, y + 0, z + 2, Block.dirt.blockID);
		world.setBlock(x + 6, y + 0, z + 3, Block.dirt.blockID);
		world.setBlock(x + 6, y + 0, z + 4, Block.dirt.blockID);
		world.setBlock(x + 6, y + 0, z + 5, Block.dirt.blockID);
		world.setBlock(x + 6, y + 0, z + 6, Block.dirt.blockID);
		world.setBlock(x + 6, y + 0, z + 7, Block.dirt.blockID);
		world.setBlock(x + 6, y + 0, z + 8, Block.dirt.blockID);
		world.setBlock(x + 6, y + 0, z + 9, Block.dirt.blockID);
		world.setBlock(x + 6, y + 0, z + 10, Block.dirt.blockID);
		world.setBlock(x + 6, y + 0, z + 11, Block.dirt.blockID);
		world.setBlock(x + 6, y + 0, z + 12, Block.dirt.blockID);
		world.setBlock(x + 6, y + 0, z + 13, Block.dirt.blockID);
		world.setBlock(x + 6, y + 0, z + 14, Block.dirt.blockID);
		world.setBlock(x + 6, y + 0, z + 15, Block.dirt.blockID);
		world.setBlock(x + 6, y + 0, z + 16, Block.dirt.blockID);
		world.setBlock(x + 6, y + 1, z + 0, Block.stoneBrick.blockID);
		world.setBlock(x + 6, y + 1, z + 5, Block.stoneBrick.blockID);
		world.setBlock(x + 6, y + 1, z + 6, Blocks.blockLimestone.blockID, 1, 3);
		world.setBlock(x + 6, y + 1, z + 7, Blocks.blockLimestone.blockID, 1, 3);
		world.setBlock(x + 6, y + 1, z + 8, Blocks.blockLimestone.blockID, 1, 3);
		world.setBlock(x + 6, y + 1, z + 9, Blocks.blockLimestone.blockID, 1, 3);
		world.setBlock(x + 6, y + 1, z + 10, Blocks.blockLimestone.blockID, 1, 3);
		world.setBlock(x + 6, y + 1, z + 11, Block.stoneBrick.blockID);
		world.setBlock(x + 6, y + 1, z + 16, Block.stoneBrick.blockID);
		world.setBlock(x + 6, y + 2, z + 0, Block.glass.blockID);
		world.setBlock(x + 6, y + 2, z + 16, Block.glass.blockID);
		world.setBlock(x + 6, y + 3, z + 0, Block.glass.blockID);
		world.setBlock(x + 6, y + 3, z + 16, Block.glass.blockID);
		world.setBlock(x + 6, y + 4, z + 1, Block.glass.blockID);
		world.setBlock(x + 6, y + 4, z + 15, Block.glass.blockID);
		world.setBlock(x + 6, y + 5, z + 2, Block.glass.blockID);
		world.setBlock(x + 6, y + 5, z + 14, Block.glass.blockID);
		world.setBlock(x + 6, y + 6, z + 3, Block.glass.blockID);
		world.setBlock(x + 6, y + 6, z + 4, Block.glass.blockID);
		world.setBlock(x + 6, y + 6, z + 12, Block.glass.blockID);
		world.setBlock(x + 6, y + 6, z + 13, Block.glass.blockID);
		world.setBlock(x + 6, y + 7, z + 5, Block.glass.blockID);
		world.setBlock(x + 6, y + 7, z + 6, Block.glass.blockID);
		world.setBlock(x + 6, y + 7, z + 7, Block.glass.blockID);
		world.setBlock(x + 6, y + 7, z + 8, Block.glass.blockID);
		world.setBlock(x + 6, y + 7, z + 9, Block.glass.blockID);
		world.setBlock(x + 6, y + 7, z + 10, Block.glass.blockID);
		world.setBlock(x + 6, y + 7, z + 11, Block.glass.blockID);
		world.setBlock(x + 7, y + 0, z + 0, Block.dirt.blockID);
		world.setBlock(x + 7, y + 0, z + 1, Block.dirt.blockID);
		world.setBlock(x + 7, y + 0, z + 2, Block.dirt.blockID);
		world.setBlock(x + 7, y + 0, z + 3, Block.dirt.blockID);
		world.setBlock(x + 7, y + 0, z + 4, Block.dirt.blockID);
		world.setBlock(x + 7, y + 0, z + 5, Block.dirt.blockID);
		world.setBlock(x + 7, y + 0, z + 6, Block.dirt.blockID);
		world.setBlock(x + 7, y + 0, z + 7, Block.stoneBrick.blockID);
		world.setBlock(x + 7, y + 0, z + 8, Block.stoneBrick.blockID);
		world.setBlock(x + 7, y + 0, z + 9, Block.stoneBrick.blockID);
		world.setBlock(x + 7, y + 0, z + 10, Blocks.blockLimestone.blockID, 1, 3);
		world.setBlock(x + 7, y + 0, z + 11, Block.dirt.blockID);
		world.setBlock(x + 7, y + 0, z + 12, Block.dirt.blockID);
		world.setBlock(x + 7, y + 0, z + 13, Block.dirt.blockID);
		world.setBlock(x + 7, y + 0, z + 14, Block.dirt.blockID);
		world.setBlock(x + 7, y + 0, z + 15, Block.dirt.blockID);
		world.setBlock(x + 7, y + 0, z + 16, Block.dirt.blockID);
		world.setBlock(x + 7, y + 1, z + 0, Block.stoneBrick.blockID);
		world.setBlock(x + 7, y + 1, z + 4, Block.stoneBrick.blockID);
		world.setBlock(x + 7, y + 1, z + 5, Blocks.blockLimestone.blockID, 1, 3);
		world.setBlock(x + 7, y + 1, z + 6, Blocks.blockLimestone.blockID, 1, 3);
		world.setBlock(x + 7, y + 1, z + 10, Blocks.blockLimestone.blockID, 1, 3);
		world.setBlock(x + 7, y + 1, z + 11, Blocks.blockLimestone.blockID, 1, 3);
		world.setBlock(x + 7, y + 1, z + 12, Block.stoneBrick.blockID);
		world.setBlock(x + 7, y + 1, z + 16, Block.stoneBrick.blockID);
		world.setBlock(x + 7, y + 2, z + 0, Block.glass.blockID);
		world.setBlock(x + 7, y + 2, z + 16, Block.glass.blockID);
		world.setBlock(x + 7, y + 3, z + 0, Block.glass.blockID);
		world.setBlock(x + 7, y + 3, z + 16, Block.glass.blockID);
		world.setBlock(x + 7, y + 4, z + 1, Block.glass.blockID);
		world.setBlock(x + 7, y + 4, z + 15, Block.glass.blockID);
		world.setBlock(x + 7, y + 5, z + 2, Block.glass.blockID);
		world.setBlock(x + 7, y + 5, z + 14, Block.glass.blockID);
		world.setBlock(x + 7, y + 6, z + 3, Block.glass.blockID);
		world.setBlock(x + 7, y + 6, z + 4, Block.glass.blockID);
		world.setBlock(x + 7, y + 6, z + 12, Block.glass.blockID);
		world.setBlock(x + 7, y + 6, z + 13, Block.glass.blockID);
		world.setBlock(x + 7, y + 7, z + 5, Block.glass.blockID);
		world.setBlock(x + 7, y + 7, z + 6, Block.glass.blockID);
		world.setBlock(x + 7, y + 7, z + 7, Block.glass.blockID);
		world.setBlock(x + 7, y + 7, z + 8, Block.glass.blockID);
		world.setBlock(x + 7, y + 7, z + 9, Block.glass.blockID);
		world.setBlock(x + 7, y + 7, z + 10, Block.glass.blockID);
		world.setBlock(x + 7, y + 7, z + 11, Block.glass.blockID);
		world.setBlock(x + 8, y + 0, z + 0, Block.dirt.blockID);
		world.setBlock(x + 8, y + 0, z + 1, Block.dirt.blockID);
		world.setBlock(x + 8, y + 0, z + 2, Block.dirt.blockID);
		world.setBlock(x + 8, y + 0, z + 3, Block.dirt.blockID);
		world.setBlock(x + 8, y + 0, z + 4, Block.dirt.blockID);
		world.setBlock(x + 8, y + 0, z + 5, Block.dirt.blockID);
		world.setBlock(x + 8, y + 0, z + 6, Block.dirt.blockID);
		world.setBlock(x + 8, y + 0, z + 7, Block.stoneBrick.blockID);
		world.setBlock(x + 8, y + 0, z + 8, Block.dirt.blockID);
		world.setBlock(x + 8, y + 0, z + 9, Block.stoneBrick.blockID);
		world.setBlock(x + 8, y + 0, z + 10, Block.dirt.blockID);
		world.setBlock(x + 8, y + 0, z + 11, Block.dirt.blockID);
		world.setBlock(x + 8, y + 0, z + 12, Block.dirt.blockID);
		world.setBlock(x + 8, y + 0, z + 13, Block.dirt.blockID);
		world.setBlock(x + 8, y + 0, z + 14, Block.dirt.blockID);
		world.setBlock(x + 8, y + 0, z + 15, Block.dirt.blockID);
		world.setBlock(x + 8, y + 0, z + 16, Block.dirt.blockID);
		world.setBlock(x + 8, y + 1, z + 0, Block.stoneBrick.blockID);
		world.setBlock(x + 8, y + 1, z + 4, Block.stoneBrick.blockID);
		world.setBlock(x + 8, y + 1, z + 5, Blocks.blockLimestone.blockID, 1, 3);
		world.setBlock(x + 8, y + 1, z + 6, Blocks.blockLimestone.blockID, 1, 3);
		world.setBlock(x + 8, y + 1, z + 8, Blocks.blockLimestone.blockID, 1, 3);
		world.setBlock(x + 8, y + 1, z + 10, Blocks.blockLimestone.blockID, 1, 3);
		world.setBlock(x + 8, y + 1, z + 11, Blocks.blockLimestone.blockID, 1, 3);
		world.setBlock(x + 8, y + 1, z + 12, Block.stoneBrick.blockID);
		world.setBlock(x + 8, y + 1, z + 16, Block.stoneBrick.blockID);
		world.setBlock(x + 8, y + 2, z + 0, Block.glass.blockID);
		world.setBlock(x + 8, y + 2, z + 8, Blocks.blockLimestone.blockID, 1, 3);
		world.setBlock(x + 8, y + 2, z + 16, Block.glass.blockID);
		world.setBlock(x + 8, y + 3, z + 0, Block.glass.blockID);
		world.setBlock(x + 8, y + 3, z + 8, Blocks.blockLimestone.blockID, 1, 3);
		world.setBlock(x + 8, y + 3, z + 16, Block.glass.blockID);
		world.setBlock(x + 8, y + 4, z + 1, Block.glass.blockID);
		world.setBlock(x + 8, y + 4, z + 8, Blocks.blockChestSpawner.blockID);
		world.setBlockMetadataWithNotify(x + 8, y + 4, z + 8, 4, 3);
		world.setBlock(x + 8, y + 4, z + 15, Block.glass.blockID);
		world.setBlock(x + 8, y + 5, z + 2, Block.glass.blockID);
		world.setBlock(x + 8, y + 5, z + 14, Block.glass.blockID);
		world.setBlock(x + 8, y + 6, z + 3, Block.glass.blockID);
		world.setBlock(x + 8, y + 6, z + 4, Block.glass.blockID);
		world.setBlock(x + 8, y + 6, z + 12, Block.glass.blockID);
		world.setBlock(x + 8, y + 6, z + 13, Block.glass.blockID);
		world.setBlock(x + 8, y + 7, z + 5, Block.glass.blockID);
		world.setBlock(x + 8, y + 7, z + 6, Block.glass.blockID);
		world.setBlock(x + 8, y + 7, z + 7, Block.glass.blockID);
		world.setBlock(x + 8, y + 7, z + 8, Block.glass.blockID);
		world.setBlock(x + 8, y + 7, z + 9, Block.glass.blockID);
		world.setBlock(x + 8, y + 7, z + 10, Block.glass.blockID);
		world.setBlock(x + 8, y + 7, z + 11, Block.glass.blockID);
		world.setBlock(x + 9, y + 0, z + 0, Block.dirt.blockID);
		world.setBlock(x + 9, y + 0, z + 1, Block.dirt.blockID);
		world.setBlock(x + 9, y + 0, z + 2, Block.dirt.blockID);
		world.setBlock(x + 9, y + 0, z + 3, Block.dirt.blockID);
		world.setBlock(x + 9, y + 0, z + 4, Block.dirt.blockID);
		world.setBlock(x + 9, y + 0, z + 5, Block.dirt.blockID);
		world.setBlock(x + 9, y + 0, z + 6, Block.dirt.blockID);
		world.setBlock(x + 9, y + 0, z + 7, Block.stoneBrick.blockID);
		world.setBlock(x + 9, y + 0, z + 8, Block.stoneBrick.blockID);
		world.setBlock(x + 9, y + 0, z + 9, Block.stoneBrick.blockID);
		world.setBlock(x + 9, y + 0, z + 10, Block.dirt.blockID);
		world.setBlock(x + 9, y + 0, z + 11, Block.dirt.blockID);
		world.setBlock(x + 9, y + 0, z + 12, Block.dirt.blockID);
		world.setBlock(x + 9, y + 0, z + 13, Block.dirt.blockID);
		world.setBlock(x + 9, y + 0, z + 14, Block.dirt.blockID);
		world.setBlock(x + 9, y + 0, z + 15, Block.dirt.blockID);
		world.setBlock(x + 9, y + 0, z + 16, Block.dirt.blockID);
		world.setBlock(x + 9, y + 1, z + 0, Block.stoneBrick.blockID);
		world.setBlock(x + 9, y + 1, z + 4, Block.stoneBrick.blockID);
		world.setBlock(x + 9, y + 1, z + 5, Blocks.blockLimestone.blockID, 1, 3);
		world.setBlock(x + 9, y + 1, z + 6, Blocks.blockLimestone.blockID, 1, 3);
		world.setBlock(x + 9, y + 1, z + 10, Blocks.blockLimestone.blockID, 1, 3);
		world.setBlock(x + 9, y + 1, z + 11, Blocks.blockLimestone.blockID, 1, 3);
		world.setBlock(x + 9, y + 1, z + 12, Block.stoneBrick.blockID);
		world.setBlock(x + 9, y + 1, z + 16, Block.stoneBrick.blockID);
		world.setBlock(x + 9, y + 2, z + 0, Block.glass.blockID);
		world.setBlock(x + 9, y + 2, z + 16, Block.glass.blockID);
		world.setBlock(x + 9, y + 3, z + 0, Block.glass.blockID);
		world.setBlock(x + 9, y + 3, z + 16, Block.glass.blockID);
		world.setBlock(x + 9, y + 4, z + 1, Block.glass.blockID);
		world.setBlock(x + 9, y + 4, z + 15, Block.glass.blockID);
		world.setBlock(x + 9, y + 5, z + 2, Block.glass.blockID);
		world.setBlock(x + 9, y + 5, z + 14, Block.glass.blockID);
		world.setBlock(x + 9, y + 6, z + 3, Block.glass.blockID);
		world.setBlock(x + 9, y + 6, z + 4, Block.glass.blockID);
		world.setBlock(x + 9, y + 6, z + 12, Block.glass.blockID);
		world.setBlock(x + 9, y + 6, z + 13, Block.glass.blockID);
		world.setBlock(x + 9, y + 7, z + 5, Block.glass.blockID);
		world.setBlock(x + 9, y + 7, z + 6, Block.glass.blockID);
		world.setBlock(x + 9, y + 7, z + 7, Block.glass.blockID);
		world.setBlock(x + 9, y + 7, z + 8, Block.glass.blockID);
		world.setBlock(x + 9, y + 7, z + 9, Block.glass.blockID);
		world.setBlock(x + 9, y + 7, z + 10, Block.glass.blockID);
		world.setBlock(x + 9, y + 7, z + 11, Block.glass.blockID);
		world.setBlock(x + 10, y + 0, z + 0, Block.dirt.blockID);
		world.setBlock(x + 10, y + 0, z + 1, Block.dirt.blockID);
		world.setBlock(x + 10, y + 0, z + 2, Block.dirt.blockID);
		world.setBlock(x + 10, y + 0, z + 3, Block.dirt.blockID);
		world.setBlock(x + 10, y + 0, z + 4, Block.dirt.blockID);
		world.setBlock(x + 10, y + 0, z + 5, Block.dirt.blockID);
		world.setBlock(x + 10, y + 0, z + 6, Block.dirt.blockID);
		world.setBlock(x + 10, y + 0, z + 7, Block.dirt.blockID);
		world.setBlock(x + 10, y + 0, z + 8, Block.dirt.blockID);
		world.setBlock(x + 10, y + 0, z + 9, Block.dirt.blockID);
		world.setBlock(x + 10, y + 0, z + 10, Block.dirt.blockID);
		world.setBlock(x + 10, y + 0, z + 11, Block.dirt.blockID);
		world.setBlock(x + 10, y + 0, z + 12, Block.dirt.blockID);
		world.setBlock(x + 10, y + 0, z + 13, Block.dirt.blockID);
		world.setBlock(x + 10, y + 0, z + 14, Block.dirt.blockID);
		world.setBlock(x + 10, y + 0, z + 15, Block.dirt.blockID);
		world.setBlock(x + 10, y + 0, z + 16, Block.dirt.blockID);
		world.setBlock(x + 10, y + 1, z + 0, Block.stoneBrick.blockID);
		world.setBlock(x + 10, y + 1, z + 5, Block.stoneBrick.blockID);
		world.setBlock(x + 10, y + 1, z + 6, Blocks.blockLimestone.blockID, 1, 3);
		world.setBlock(x + 10, y + 1, z + 7, Blocks.blockLimestone.blockID, 1, 3);
		world.setBlock(x + 10, y + 1, z + 8, Blocks.blockLimestone.blockID, 1, 3);
		world.setBlock(x + 10, y + 1, z + 9, Blocks.blockLimestone.blockID, 1, 3);
		world.setBlock(x + 10, y + 1, z + 10, Blocks.blockLimestone.blockID, 1, 3);
		world.setBlock(x + 10, y + 1, z + 11, Block.stoneBrick.blockID);
		world.setBlock(x + 10, y + 1, z + 16, Block.stoneBrick.blockID);
		world.setBlock(x + 10, y + 2, z + 0, Block.glass.blockID);
		world.setBlock(x + 10, y + 2, z + 16, Block.glass.blockID);
		world.setBlock(x + 10, y + 3, z + 0, Block.glass.blockID);
		world.setBlock(x + 10, y + 3, z + 16, Block.glass.blockID);
		world.setBlock(x + 10, y + 4, z + 1, Block.glass.blockID);
		world.setBlock(x + 10, y + 4, z + 15, Block.glass.blockID);
		world.setBlock(x + 10, y + 5, z + 2, Block.glass.blockID);
		world.setBlock(x + 10, y + 5, z + 14, Block.glass.blockID);
		world.setBlock(x + 10, y + 6, z + 3, Block.glass.blockID);
		world.setBlock(x + 10, y + 6, z + 4, Block.glass.blockID);
		world.setBlock(x + 10, y + 6, z + 12, Block.glass.blockID);
		world.setBlock(x + 10, y + 6, z + 13, Block.glass.blockID);
		world.setBlock(x + 10, y + 7, z + 5, Block.glass.blockID);
		world.setBlock(x + 10, y + 7, z + 6, Block.glass.blockID);
		world.setBlock(x + 10, y + 7, z + 7, Block.glass.blockID);
		world.setBlock(x + 10, y + 7, z + 8, Block.glass.blockID);
		world.setBlock(x + 10, y + 7, z + 9, Block.glass.blockID);
		world.setBlock(x + 10, y + 7, z + 10, Block.glass.blockID);
		world.setBlock(x + 10, y + 7, z + 11, Block.glass.blockID);
		world.setBlock(x + 11, y + 0, z + 0, Block.dirt.blockID);
		world.setBlock(x + 11, y + 0, z + 1, Block.dirt.blockID);
		world.setBlock(x + 11, y + 0, z + 2, Block.dirt.blockID);
		world.setBlock(x + 11, y + 0, z + 3, Block.dirt.blockID);
		world.setBlock(x + 11, y + 0, z + 4, Block.dirt.blockID);
		world.setBlock(x + 11, y + 0, z + 5, Block.dirt.blockID);
		world.setBlock(x + 11, y + 0, z + 6, Block.dirt.blockID);
		world.setBlock(x + 11, y + 0, z + 7, Block.dirt.blockID);
		world.setBlock(x + 11, y + 0, z + 8, Block.dirt.blockID);
		world.setBlock(x + 11, y + 0, z + 9, Block.dirt.blockID);
		world.setBlock(x + 11, y + 0, z + 10, Block.dirt.blockID);
		world.setBlock(x + 11, y + 0, z + 11, Block.dirt.blockID);
		world.setBlock(x + 11, y + 0, z + 12, Block.dirt.blockID);
		world.setBlock(x + 11, y + 0, z + 13, Block.dirt.blockID);
		world.setBlock(x + 11, y + 0, z + 14, Block.dirt.blockID);
		world.setBlock(x + 11, y + 0, z + 15, Block.dirt.blockID);
		world.setBlock(x + 11, y + 0, z + 16, Block.dirt.blockID);
		world.setBlock(x + 11, y + 1, z + 1, Block.stoneBrick.blockID);
		world.setBlock(x + 11, y + 1, z + 6, Block.stoneBrick.blockID);
		world.setBlock(x + 11, y + 1, z + 7, Blocks.blockLimestone.blockID, 1, 3);
		world.setBlock(x + 11, y + 1, z + 8, Blocks.blockLimestone.blockID, 1, 3);
		world.setBlock(x + 11, y + 1, z + 9, Blocks.blockLimestone.blockID, 1, 3);
		world.setBlock(x + 11, y + 1, z + 10, Block.stoneBrick.blockID);
		world.setBlock(x + 11, y + 1, z + 15, Block.stoneBrick.blockID);
		world.setBlock(x + 11, y + 2, z + 1, Block.glass.blockID);
		world.setBlock(x + 11, y + 2, z + 15, Block.glass.blockID);
		world.setBlock(x + 11, y + 3, z + 1, Block.glass.blockID);
		world.setBlock(x + 11, y + 3, z + 15, Block.glass.blockID);
		world.setBlock(x + 11, y + 4, z + 2, Block.glass.blockID);
		world.setBlock(x + 11, y + 4, z + 14, Block.glass.blockID);
		world.setBlock(x + 11, y + 5, z + 3, Block.glass.blockID);
		world.setBlock(x + 11, y + 5, z + 13, Block.glass.blockID);
		world.setBlock(x + 11, y + 6, z + 4, Block.glass.blockID);
		world.setBlock(x + 11, y + 6, z + 5, Block.glass.blockID);
		world.setBlock(x + 11, y + 6, z + 11, Block.glass.blockID);
		world.setBlock(x + 11, y + 6, z + 12, Block.glass.blockID);
		world.setBlock(x + 11, y + 7, z + 6, Block.glass.blockID);
		world.setBlock(x + 11, y + 7, z + 7, Block.glass.blockID);
		world.setBlock(x + 11, y + 7, z + 8, Block.glass.blockID);
		world.setBlock(x + 11, y + 7, z + 9, Block.glass.blockID);
		world.setBlock(x + 11, y + 7, z + 10, Block.glass.blockID);
		world.setBlock(x + 12, y + 0, z + 0, Block.dirt.blockID);
		world.setBlock(x + 12, y + 0, z + 1, Block.dirt.blockID);
		world.setBlock(x + 12, y + 0, z + 2, Block.dirt.blockID);
		world.setBlock(x + 12, y + 0, z + 3, Block.dirt.blockID);
		world.setBlock(x + 12, y + 0, z + 4, Block.dirt.blockID);
		world.setBlock(x + 12, y + 0, z + 5, Block.dirt.blockID);
		world.setBlock(x + 12, y + 0, z + 6, Block.dirt.blockID);
		world.setBlock(x + 12, y + 0, z + 7, Block.dirt.blockID);
		world.setBlock(x + 12, y + 0, z + 8, Block.dirt.blockID);
		world.setBlock(x + 12, y + 0, z + 9, Block.dirt.blockID);
		world.setBlock(x + 12, y + 0, z + 10, Block.dirt.blockID);
		world.setBlock(x + 12, y + 0, z + 11, Block.dirt.blockID);
		world.setBlock(x + 12, y + 0, z + 12, Block.dirt.blockID);
		world.setBlock(x + 12, y + 0, z + 13, Block.dirt.blockID);
		world.setBlock(x + 12, y + 0, z + 14, Block.dirt.blockID);
		world.setBlock(x + 12, y + 0, z + 15, Block.dirt.blockID);
		world.setBlock(x + 12, y + 0, z + 16, Block.dirt.blockID);
		world.setBlock(x + 12, y + 1, z + 1, Block.stoneBrick.blockID);
		world.setBlock(x + 12, y + 1, z + 7, Block.stoneBrick.blockID);
		world.setBlock(x + 12, y + 1, z + 8, Block.stoneBrick.blockID);
		world.setBlock(x + 12, y + 1, z + 9, Block.stoneBrick.blockID);
		world.setBlock(x + 12, y + 1, z + 15, Block.stoneBrick.blockID);
		world.setBlock(x + 12, y + 2, z + 1, Block.glass.blockID);
		world.setBlock(x + 12, y + 2, z + 15, Block.glass.blockID);
		world.setBlock(x + 12, y + 3, z + 1, Block.glass.blockID);
		world.setBlock(x + 12, y + 3, z + 15, Block.glass.blockID);
		world.setBlock(x + 12, y + 4, z + 2, Block.glass.blockID);
		world.setBlock(x + 12, y + 4, z + 14, Block.glass.blockID);
		world.setBlock(x + 12, y + 5, z + 3, Block.glass.blockID);
		world.setBlock(x + 12, y + 5, z + 13, Block.glass.blockID);
		world.setBlock(x + 12, y + 6, z + 4, Block.glass.blockID);
		world.setBlock(x + 12, y + 6, z + 5, Block.glass.blockID);
		world.setBlock(x + 12, y + 6, z + 6, Block.glass.blockID);
		world.setBlock(x + 12, y + 6, z + 7, Block.glass.blockID);
		world.setBlock(x + 12, y + 6, z + 8, Block.glass.blockID);
		world.setBlock(x + 12, y + 6, z + 9, Block.glass.blockID);
		world.setBlock(x + 12, y + 6, z + 10, Block.glass.blockID);
		world.setBlock(x + 12, y + 6, z + 11, Block.glass.blockID);
		world.setBlock(x + 12, y + 6, z + 12, Block.glass.blockID);
		world.setBlock(x + 13, y + 0, z + 0, Block.dirt.blockID);
		world.setBlock(x + 13, y + 0, z + 1, Block.dirt.blockID);
		world.setBlock(x + 13, y + 0, z + 2, Block.dirt.blockID);
		world.setBlock(x + 13, y + 0, z + 3, Block.dirt.blockID);
		world.setBlock(x + 13, y + 0, z + 4, Block.dirt.blockID);
		world.setBlock(x + 13, y + 0, z + 5, Block.dirt.blockID);
		world.setBlock(x + 13, y + 0, z + 6, Block.dirt.blockID);
		world.setBlock(x + 13, y + 0, z + 7, Block.dirt.blockID);
		world.setBlock(x + 13, y + 0, z + 8, Block.dirt.blockID);
		world.setBlock(x + 13, y + 0, z + 9, Block.dirt.blockID);
		world.setBlock(x + 13, y + 0, z + 10, Block.dirt.blockID);
		world.setBlock(x + 13, y + 0, z + 11, Block.dirt.blockID);
		world.setBlock(x + 13, y + 0, z + 12, Block.dirt.blockID);
		world.setBlock(x + 13, y + 0, z + 13, Block.dirt.blockID);
		world.setBlock(x + 13, y + 0, z + 14, Block.dirt.blockID);
		world.setBlock(x + 13, y + 0, z + 15, Block.dirt.blockID);
		world.setBlock(x + 13, y + 0, z + 16, Block.dirt.blockID);
		world.setBlock(x + 13, y + 1, z + 2, Block.stoneBrick.blockID);
		world.setBlock(x + 13, y + 1, z + 14, Block.stoneBrick.blockID);
		world.setBlock(x + 13, y + 2, z + 2, Block.glass.blockID);
		world.setBlock(x + 13, y + 2, z + 14, Block.glass.blockID);
		world.setBlock(x + 13, y + 3, z + 2, Block.glass.blockID);
		world.setBlock(x + 13, y + 3, z + 14, Block.glass.blockID);
		world.setBlock(x + 13, y + 4, z + 3, Block.glass.blockID);
		world.setBlock(x + 13, y + 4, z + 13, Block.glass.blockID);
		world.setBlock(x + 13, y + 5, z + 4, Block.glass.blockID);
		world.setBlock(x + 13, y + 5, z + 5, Block.glass.blockID);
		world.setBlock(x + 13, y + 5, z + 11, Block.glass.blockID);
		world.setBlock(x + 13, y + 5, z + 12, Block.glass.blockID);
		world.setBlock(x + 13, y + 6, z + 6, Block.glass.blockID);
		world.setBlock(x + 13, y + 6, z + 7, Block.glass.blockID);
		world.setBlock(x + 13, y + 6, z + 8, Block.glass.blockID);
		world.setBlock(x + 13, y + 6, z + 9, Block.glass.blockID);
		world.setBlock(x + 13, y + 6, z + 10, Block.glass.blockID);
		world.setBlock(x + 14, y + 0, z + 0, Block.dirt.blockID);
		world.setBlock(x + 14, y + 0, z + 1, Block.dirt.blockID);
		world.setBlock(x + 14, y + 0, z + 2, Block.dirt.blockID);
		world.setBlock(x + 14, y + 0, z + 3, Block.dirt.blockID);
		world.setBlock(x + 14, y + 0, z + 4, Block.dirt.blockID);
		world.setBlock(x + 14, y + 0, z + 5, Block.dirt.blockID);
		world.setBlock(x + 14, y + 0, z + 6, Block.dirt.blockID);
		world.setBlock(x + 14, y + 0, z + 7, Block.dirt.blockID);
		world.setBlock(x + 14, y + 0, z + 8, Block.dirt.blockID);
		world.setBlock(x + 14, y + 0, z + 9, Block.dirt.blockID);
		world.setBlock(x + 14, y + 0, z + 10, Block.dirt.blockID);
		world.setBlock(x + 14, y + 0, z + 11, Block.dirt.blockID);
		world.setBlock(x + 14, y + 0, z + 12, Block.dirt.blockID);
		world.setBlock(x + 14, y + 0, z + 13, Block.dirt.blockID);
		world.setBlock(x + 14, y + 0, z + 14, Block.dirt.blockID);
		world.setBlock(x + 14, y + 0, z + 15, Block.dirt.blockID);
		world.setBlock(x + 14, y + 0, z + 16, Block.dirt.blockID);
		world.setBlock(x + 14, y + 1, z + 3, Block.stoneBrick.blockID);
		world.setBlock(x + 14, y + 1, z + 13, Block.stoneBrick.blockID);
		world.setBlock(x + 14, y + 2, z + 3, Block.glass.blockID);
		world.setBlock(x + 14, y + 2, z + 13, Block.glass.blockID);
		world.setBlock(x + 14, y + 3, z + 3, Block.glass.blockID);
		world.setBlock(x + 14, y + 3, z + 13, Block.glass.blockID);
		world.setBlock(x + 14, y + 4, z + 4, Block.glass.blockID);
		world.setBlock(x + 14, y + 4, z + 5, Block.glass.blockID);
		world.setBlock(x + 14, y + 4, z + 11, Block.glass.blockID);
		world.setBlock(x + 14, y + 4, z + 12, Block.glass.blockID);
		world.setBlock(x + 14, y + 5, z + 6, Block.glass.blockID);
		world.setBlock(x + 14, y + 5, z + 7, Block.glass.blockID);
		world.setBlock(x + 14, y + 5, z + 8, Block.glass.blockID);
		world.setBlock(x + 14, y + 5, z + 9, Block.glass.blockID);
		world.setBlock(x + 14, y + 5, z + 10, Block.glass.blockID);
		world.setBlock(x + 15, y + 0, z + 0, Block.dirt.blockID);
		world.setBlock(x + 15, y + 0, z + 1, Block.dirt.blockID);
		world.setBlock(x + 15, y + 0, z + 2, Block.dirt.blockID);
		world.setBlock(x + 15, y + 0, z + 3, Block.dirt.blockID);
		world.setBlock(x + 15, y + 0, z + 4, Block.dirt.blockID);
		world.setBlock(x + 15, y + 0, z + 5, Block.dirt.blockID);
		world.setBlock(x + 15, y + 0, z + 6, Block.dirt.blockID);
		world.setBlock(x + 15, y + 0, z + 7, Block.dirt.blockID);
		world.setBlock(x + 15, y + 0, z + 8, Block.dirt.blockID);
		world.setBlock(x + 15, y + 0, z + 9, Block.dirt.blockID);
		world.setBlock(x + 15, y + 0, z + 10, Block.dirt.blockID);
		world.setBlock(x + 15, y + 0, z + 11, Block.dirt.blockID);
		world.setBlock(x + 15, y + 0, z + 12, Block.dirt.blockID);
		world.setBlock(x + 15, y + 0, z + 13, Block.dirt.blockID);
		world.setBlock(x + 15, y + 0, z + 14, Block.dirt.blockID);
		world.setBlock(x + 15, y + 0, z + 15, Block.dirt.blockID);
		world.setBlock(x + 15, y + 0, z + 16, Block.dirt.blockID);
		world.setBlock(x + 15, y + 1, z + 4, Block.stoneBrick.blockID);
		world.setBlock(x + 15, y + 1, z + 5, Block.stoneBrick.blockID);
		world.setBlock(x + 15, y + 1, z + 11, Block.stoneBrick.blockID);
		world.setBlock(x + 15, y + 1, z + 12, Block.stoneBrick.blockID);
		world.setBlock(x + 15, y + 2, z + 4, Block.glass.blockID);
		world.setBlock(x + 15, y + 2, z + 5, Block.glass.blockID);
		world.setBlock(x + 15, y + 2, z + 11, Block.glass.blockID);
		world.setBlock(x + 15, y + 2, z + 12, Block.glass.blockID);
		world.setBlock(x + 15, y + 3, z + 4, Block.glass.blockID);
		world.setBlock(x + 15, y + 3, z + 5, Block.glass.blockID);
		world.setBlock(x + 15, y + 3, z + 11, Block.glass.blockID);
		world.setBlock(x + 15, y + 3, z + 12, Block.glass.blockID);
		world.setBlock(x + 15, y + 4, z + 6, Block.glass.blockID);
		world.setBlock(x + 15, y + 4, z + 7, Block.glass.blockID);
		world.setBlock(x + 15, y + 4, z + 8, Block.glass.blockID);
		world.setBlock(x + 15, y + 4, z + 9, Block.glass.blockID);
		world.setBlock(x + 15, y + 4, z + 10, Block.glass.blockID);
		world.setBlock(x + 16, y + 0, z + 0, Block.dirt.blockID);
		world.setBlock(x + 16, y + 0, z + 1, Block.dirt.blockID);
		world.setBlock(x + 16, y + 0, z + 2, Block.dirt.blockID);
		world.setBlock(x + 16, y + 0, z + 3, Block.dirt.blockID);
		world.setBlock(x + 16, y + 0, z + 4, Block.dirt.blockID);
		world.setBlock(x + 16, y + 0, z + 5, Block.dirt.blockID);
		world.setBlock(x + 16, y + 0, z + 6, Block.dirt.blockID);
		world.setBlock(x + 16, y + 0, z + 7, Block.dirt.blockID);
		world.setBlock(x + 16, y + 0, z + 8, Block.dirt.blockID);
		world.setBlock(x + 16, y + 0, z + 9, Block.dirt.blockID);
		world.setBlock(x + 16, y + 0, z + 10, Block.dirt.blockID);
		world.setBlock(x + 16, y + 0, z + 11, Block.dirt.blockID);
		world.setBlock(x + 16, y + 0, z + 12, Block.dirt.blockID);
		world.setBlock(x + 16, y + 0, z + 13, Block.dirt.blockID);
		world.setBlock(x + 16, y + 0, z + 14, Block.dirt.blockID);
		world.setBlock(x + 16, y + 0, z + 15, Block.dirt.blockID);
		world.setBlock(x + 16, y + 0, z + 16, Block.dirt.blockID);
		world.setBlock(x + 16, y + 1, z + 6, Block.stoneBrick.blockID);
		world.setBlock(x + 16, y + 1, z + 7, Block.stoneBrick.blockID);
		world.setBlock(x + 16, y + 1, z + 8, Block.stoneBrick.blockID);
		world.setBlock(x + 16, y + 1, z + 9, Block.stoneBrick.blockID);
		world.setBlock(x + 16, y + 1, z + 10, Block.stoneBrick.blockID);
		world.setBlock(x + 16, y + 2, z + 6, Block.glass.blockID);
		world.setBlock(x + 16, y + 2, z + 7, Block.glass.blockID);
		world.setBlock(x + 16, y + 2, z + 8, Block.glass.blockID);
		world.setBlock(x + 16, y + 2, z + 9, Block.glass.blockID);
		world.setBlock(x + 16, y + 2, z + 10, Block.glass.blockID);
		world.setBlock(x + 16, y + 3, z + 6, Block.glass.blockID);
		world.setBlock(x + 16, y + 3, z + 7, Block.glass.blockID);
		world.setBlock(x + 16, y + 3, z + 8, Block.glass.blockID);
		world.setBlock(x + 16, y + 3, z + 9, Block.glass.blockID);
		world.setBlock(x + 16, y + 3, z + 10, Block.glass.blockID);
		world.setBlock(x + 0, y + 1, z + 0, Block.sand.blockID, 0, 3);
		world.setBlock(x + 0, y + 1, z + 1, Block.sand.blockID, 0, 3);
		world.setBlock(x + 0, y + 1, z + 2, Block.sand.blockID, 0, 3);
		world.setBlock(x + 0, y + 1, z + 3, Block.sand.blockID, 0, 3);
		world.setBlock(x + 0, y + 1, z + 4, Block.sand.blockID, 0, 3);
		world.setBlock(x + 0, y + 1, z + 5, Block.sand.blockID, 0, 3);
		world.setBlock(x + 0, y + 1, z + 11, Block.sand.blockID, 0, 3);
		world.setBlock(x + 0, y + 1, z + 12, Block.sand.blockID, 0, 3);
		world.setBlock(x + 0, y + 1, z + 13, Block.sand.blockID, 0, 3);
		world.setBlock(x + 0, y + 1, z + 14, Block.sand.blockID, 0, 3);
		world.setBlock(x + 0, y + 1, z + 15, Block.sand.blockID, 0, 3);
		world.setBlock(x + 0, y + 1, z + 16, Block.sand.blockID, 0, 3);
		world.setBlock(x + 1, y + 1, z + 0, Block.sand.blockID, 0, 3);
		world.setBlock(x + 1, y + 1, z + 1, Block.sand.blockID, 0, 3);
		world.setBlock(x + 1, y + 1, z + 2, Block.sand.blockID, 0, 3);
		world.setBlock(x + 1, y + 1, z + 3, Block.sand.blockID, 0, 3);
		world.setBlock(x + 1, y + 1, z + 6, Block.sand.blockID, 0, 3);
		world.setBlock(x + 1, y + 1, z + 7, Block.sand.blockID, 0, 3);
		world.setBlock(x + 1, y + 1, z + 8, Block.sand.blockID, 0, 3);
		world.setBlock(x + 1, y + 1, z + 9, Block.sand.blockID, 0, 3);
		world.setBlock(x + 1, y + 1, z + 10, Block.sand.blockID, 0, 3);
		world.setBlock(x + 1, y + 1, z + 13, Block.sand.blockID, 0, 3);
		world.setBlock(x + 1, y + 1, z + 14, Block.sand.blockID, 0, 3);
		world.setBlock(x + 1, y + 1, z + 15, Block.sand.blockID, 0, 3);
		world.setBlock(x + 1, y + 1, z + 16, Block.sand.blockID, 0, 3);
		world.setBlock(x + 2, y + 1, z + 0, Block.sand.blockID, 0, 3);
		world.setBlock(x + 2, y + 1, z + 1, Block.sand.blockID, 0, 3);
		world.setBlock(x + 2, y + 1, z + 2, Block.sand.blockID, 0, 3);
		world.setBlock(x + 2, y + 1, z + 4, Block.sand.blockID, 0, 3);
		world.setBlock(x + 2, y + 1, z + 5, Block.sand.blockID, 0, 3);
		world.setBlock(x + 2, y + 1, z + 6, Block.sand.blockID, 0, 3);
		world.setBlock(x + 2, y + 1, z + 7, Block.sand.blockID, 0, 3);
		world.setBlock(x + 2, y + 1, z + 8, Block.sand.blockID, 0, 3);
		world.setBlock(x + 2, y + 1, z + 9, Block.sand.blockID, 0, 3);
		world.setBlock(x + 2, y + 1, z + 10, Block.sand.blockID, 0, 3);
		world.setBlock(x + 2, y + 1, z + 11, Block.sand.blockID, 0, 3);
		world.setBlock(x + 2, y + 1, z + 12, Block.sand.blockID, 0, 3);
		world.setBlock(x + 2, y + 1, z + 14, Block.sand.blockID, 0, 3);
		world.setBlock(x + 2, y + 1, z + 15, Block.sand.blockID, 0, 3);
		world.setBlock(x + 2, y + 1, z + 16, Block.sand.blockID, 0, 3);
		world.setBlock(x + 3, y + 1, z + 0, Block.sand.blockID, 0, 3);
		world.setBlock(x + 3, y + 1, z + 1, Block.sand.blockID, 0, 3);
		world.setBlock(x + 3, y + 1, z + 3, Block.sand.blockID, 0, 3);
		world.setBlock(x + 3, y + 1, z + 4, Block.sand.blockID, 0, 3);
		world.setBlock(x + 3, y + 1, z + 5, Block.sand.blockID, 0, 3);
		world.setBlock(x + 3, y + 1, z + 6, Block.sand.blockID, 0, 3);
		world.setBlock(x + 3, y + 1, z + 7, Block.sand.blockID, 0, 3);
		world.setBlock(x + 3, y + 1, z + 9, Block.sand.blockID, 0, 3);
		world.setBlock(x + 3, y + 1, z + 10, Block.sand.blockID, 0, 3);
		world.setBlock(x + 3, y + 1, z + 11, Block.sand.blockID, 0, 3);
		world.setBlock(x + 3, y + 1, z + 12, Block.sand.blockID, 0, 3);
		world.setBlock(x + 3, y + 1, z + 13, Block.sand.blockID, 0, 3);
		world.setBlock(x + 3, y + 1, z + 15, Block.sand.blockID, 0, 3);
		world.setBlock(x + 3, y + 1, z + 16, Block.sand.blockID, 0, 3);
		world.setBlock(x + 4, y + 1, z + 0, Block.sand.blockID, 0, 3);
		world.setBlock(x + 4, y + 1, z + 2, Block.sand.blockID, 0, 3);
		world.setBlock(x + 4, y + 1, z + 3, Block.sand.blockID, 0, 3);
		world.setBlock(x + 4, y + 1, z + 4, Block.sand.blockID, 0, 3);
		world.setBlock(x + 4, y + 1, z + 5, Block.sand.blockID, 0, 3);
		world.setBlock(x + 4, y + 1, z + 6, Block.sand.blockID, 0, 3);
		world.setBlock(x + 4, y + 1, z + 10, Block.sand.blockID, 0, 3);
		world.setBlock(x + 4, y + 1, z + 11, Block.sand.blockID, 0, 3);
		world.setBlock(x + 4, y + 1, z + 12, Block.sand.blockID, 0, 3);
		world.setBlock(x + 4, y + 1, z + 13, Block.sand.blockID, 0, 3);
		world.setBlock(x + 4, y + 1, z + 14, Block.sand.blockID, 0, 3);
		world.setBlock(x + 4, y + 1, z + 16, Block.sand.blockID, 0, 3);
		world.setBlock(x + 5, y + 1, z + 0, Block.sand.blockID, 0, 3);
		world.setBlock(x + 5, y + 1, z + 2, Block.sand.blockID, 0, 3);
		world.setBlock(x + 5, y + 1, z + 3, Block.sand.blockID, 0, 3);
		world.setBlock(x + 5, y + 1, z + 4, Block.sand.blockID, 0, 3);
		world.setBlock(x + 5, y + 1, z + 5, Block.sand.blockID, 0, 3);
		world.setBlock(x + 5, y + 1, z + 11, Block.sand.blockID, 0, 3);
		world.setBlock(x + 5, y + 1, z + 12, Block.sand.blockID, 0, 3);
		world.setBlock(x + 5, y + 1, z + 13, Block.sand.blockID, 0, 3);
		world.setBlock(x + 5, y + 1, z + 14, Block.sand.blockID, 0, 3);
		world.setBlock(x + 5, y + 1, z + 16, Block.sand.blockID, 0, 3);
		world.setBlock(x + 6, y + 1, z + 1, Block.sand.blockID, 0, 3);
		world.setBlock(x + 6, y + 1, z + 2, Block.sand.blockID, 0, 3);
		world.setBlock(x + 6, y + 1, z + 3, Block.sand.blockID, 0, 3);
		world.setBlock(x + 6, y + 1, z + 4, Block.sand.blockID, 0, 3);
		world.setBlock(x + 6, y + 1, z + 12, Block.sand.blockID, 0, 3);
		world.setBlock(x + 6, y + 1, z + 13, Block.sand.blockID, 0, 3);
		world.setBlock(x + 6, y + 1, z + 14, Block.sand.blockID, 0, 3);
		world.setBlock(x + 6, y + 1, z + 15, Block.sand.blockID, 0, 3);
		world.setBlock(x + 7, y + 1, z + 1, Block.sand.blockID, 0, 3);
		world.setBlock(x + 7, y + 1, z + 2, Block.sand.blockID, 0, 3);
		world.setBlock(x + 7, y + 1, z + 3, Block.sand.blockID, 0, 3);
		world.setBlock(x + 7, y + 1, z + 13, Block.sand.blockID, 0, 3);
		world.setBlock(x + 7, y + 1, z + 14, Block.sand.blockID, 0, 3);
		world.setBlock(x + 7, y + 1, z + 15, Block.sand.blockID, 0, 3);
		world.setBlock(x + 8, y + 1, z + 1, Block.sand.blockID, 0, 3);
		world.setBlock(x + 8, y + 1, z + 2, Block.sand.blockID, 0, 3);
		world.setBlock(x + 8, y + 1, z + 3, Block.sand.blockID, 0, 3);
		world.setBlock(x + 8, y + 2, z + 7, Blocks.blockLimestone.blockID, 0, 3);
		world.setBlock(x + 10, y + 2, z + 7, Blocks.blockLimestone.blockID, 0, 3);
		world.setBlock(x + 8, y + 2, z + 9, Blocks.blockLimestone.blockID, 0, 3);
		world.setBlock(x + 10, y + 2, z + 9, Blocks.blockLimestone.blockID, 0, 3);
		world.setBlock(x + 9, y + 2, z + 7, Block.glowStone.blockID);
		world.setBlock(x + 7, y + 2, z + 7, Block.glowStone.blockID);
		world.setBlock(x + 7, y + 2, z + 9, Block.glowStone.blockID);
		world.setBlock(x + 9, y + 2, z + 9, Block.glowStone.blockID);
		world.setBlock(x + 8, y + 1, z + 13, Block.sand.blockID, 0, 3);
		world.setBlock(x + 8, y + 1, z + 14, Block.sand.blockID, 0, 3);
		world.setBlock(x + 8, y + 1, z + 15, Block.sand.blockID, 0, 3);
		world.setBlock(x + 9, y + 1, z + 1, Block.sand.blockID, 0, 3);
		world.setBlock(x + 9, y + 1, z + 2, Block.sand.blockID, 0, 3);
		world.setBlock(x + 9, y + 1, z + 3, Block.sand.blockID, 0, 3);
		world.setBlock(x + 9, y + 1, z + 13, Block.sand.blockID, 0, 3);
		world.setBlock(x + 9, y + 1, z + 14, Block.sand.blockID, 0, 3);
		world.setBlock(x + 9, y + 1, z + 15, Block.sand.blockID, 0, 3);
		world.setBlock(x + 10, y + 1, z + 1, Block.sand.blockID, 0, 3);
		world.setBlock(x + 10, y + 1, z + 2, Block.sand.blockID, 0, 3);
		world.setBlock(x + 10, y + 1, z + 3, Block.sand.blockID, 0, 3);
		world.setBlock(x + 10, y + 1, z + 4, Block.sand.blockID, 0, 3);
		world.setBlock(x + 10, y + 1, z + 12, Block.sand.blockID, 0, 3);
		world.setBlock(x + 10, y + 1, z + 13, Block.sand.blockID, 0, 3);
		world.setBlock(x + 10, y + 1, z + 14, Block.sand.blockID, 0, 3);
		world.setBlock(x + 10, y + 1, z + 15, Block.sand.blockID, 0, 3);
		world.setBlock(x + 11, y + 1, z + 0, Block.sand.blockID, 0, 3);
		world.setBlock(x + 11, y + 1, z + 2, Block.sand.blockID, 0, 3);
		world.setBlock(x + 11, y + 1, z + 3, Block.sand.blockID, 0, 3);
		world.setBlock(x + 11, y + 1, z + 4, Block.sand.blockID, 0, 3);
		world.setBlock(x + 11, y + 1, z + 5, Block.sand.blockID, 0, 3);
		world.setBlock(x + 11, y + 1, z + 11, Block.sand.blockID, 0, 3);
		world.setBlock(x + 11, y + 1, z + 12, Block.sand.blockID, 0, 3);
		world.setBlock(x + 11, y + 1, z + 13, Block.sand.blockID, 0, 3);
		world.setBlock(x + 11, y + 1, z + 14, Block.sand.blockID, 0, 3);
		world.setBlock(x + 11, y + 1, z + 16, Block.sand.blockID, 0, 3);
		world.setBlock(x + 12, y + 1, z + 0, Block.sand.blockID, 0, 3);
		world.setBlock(x + 12, y + 1, z + 2, Block.sand.blockID, 0, 3);
		world.setBlock(x + 12, y + 1, z + 3, Block.sand.blockID, 0, 3);
		world.setBlock(x + 12, y + 1, z + 4, Block.sand.blockID, 0, 3);
		world.setBlock(x + 12, y + 1, z + 5, Block.sand.blockID, 0, 3);
		world.setBlock(x + 12, y + 1, z + 6, Block.sand.blockID, 0, 3);
		world.setBlock(x + 12, y + 1, z + 10, Block.sand.blockID, 0, 3);
		world.setBlock(x + 12, y + 1, z + 11, Block.sand.blockID, 0, 3);
		world.setBlock(x + 12, y + 1, z + 12, Block.sand.blockID, 0, 3);
		world.setBlock(x + 12, y + 1, z + 13, Block.sand.blockID, 0, 3);
		world.setBlock(x + 12, y + 1, z + 14, Block.sand.blockID, 0, 3);
		world.setBlock(x + 12, y + 1, z + 16, Block.sand.blockID, 0, 3);
		world.setBlock(x + 13, y + 1, z + 0, Block.sand.blockID, 0, 3);
		world.setBlock(x + 13, y + 1, z + 1, Block.sand.blockID, 0, 3);
		world.setBlock(x + 13, y + 1, z + 3, Block.sand.blockID, 0, 3);
		world.setBlock(x + 13, y + 1, z + 4, Block.sand.blockID, 0, 3);
		world.setBlock(x + 13, y + 1, z + 5, Block.sand.blockID, 0, 3);
		world.setBlock(x + 13, y + 1, z + 6, Block.sand.blockID, 0, 3);
		world.setBlock(x + 13, y + 1, z + 7, Block.sand.blockID, 0, 3);
		world.setBlock(x + 13, y + 1, z + 8, Block.sand.blockID, 0, 3);
		world.setBlock(x + 13, y + 1, z + 9, Block.sand.blockID, 0, 3);
		world.setBlock(x + 13, y + 1, z + 10, Block.sand.blockID, 0, 3);
		world.setBlock(x + 13, y + 1, z + 11, Block.sand.blockID, 0, 3);
		world.setBlock(x + 13, y + 1, z + 12, Block.sand.blockID, 0, 3);
		world.setBlock(x + 13, y + 1, z + 13, Block.sand.blockID, 0, 3);
		world.setBlock(x + 13, y + 1, z + 15, Block.sand.blockID, 0, 3);
		world.setBlock(x + 13, y + 1, z + 16, Block.sand.blockID, 0, 3);
		world.setBlock(x + 14, y + 1, z + 0, Block.sand.blockID, 0, 3);
		world.setBlock(x + 14, y + 1, z + 1, Block.sand.blockID, 0, 3);
		world.setBlock(x + 14, y + 1, z + 2, Block.sand.blockID, 0, 3);
		world.setBlock(x + 14, y + 1, z + 4, Block.sand.blockID, 0, 3);
		world.setBlock(x + 14, y + 1, z + 5, Block.sand.blockID, 0, 3);
		world.setBlock(x + 14, y + 1, z + 6, Block.sand.blockID, 0, 3);
		world.setBlock(x + 14, y + 1, z + 7, Block.sand.blockID, 0, 3);
		world.setBlock(x + 14, y + 1, z + 8, Block.sand.blockID, 0, 3);
		world.setBlock(x + 14, y + 1, z + 9, Block.sand.blockID, 0, 3);
		world.setBlock(x + 14, y + 1, z + 10, Block.sand.blockID, 0, 3);
		world.setBlock(x + 14, y + 1, z + 11, Block.sand.blockID, 0, 3);
		world.setBlock(x + 14, y + 1, z + 12, Block.sand.blockID, 0, 3);
		world.setBlock(x + 14, y + 1, z + 14, Block.sand.blockID, 0, 3);
		world.setBlock(x + 14, y + 1, z + 15, Block.sand.blockID, 0, 3);
		world.setBlock(x + 14, y + 1, z + 16, Block.sand.blockID, 0, 3);
		world.setBlock(x + 15, y + 1, z + 0, Block.sand.blockID, 0, 3);
		world.setBlock(x + 15, y + 1, z + 1, Block.sand.blockID, 0, 3);
		world.setBlock(x + 15, y + 1, z + 2, Block.sand.blockID, 0, 3);
		world.setBlock(x + 15, y + 1, z + 3, Block.sand.blockID, 0, 3);
		world.setBlock(x + 15, y + 1, z + 6, Block.sand.blockID, 0, 3);
		world.setBlock(x + 15, y + 1, z + 7, Block.sand.blockID, 0, 3);
		world.setBlock(x + 15, y + 1, z + 8, Block.sand.blockID, 0, 3);
		world.setBlock(x + 15, y + 1, z + 9, Block.sand.blockID, 0, 3);
		world.setBlock(x + 15, y + 1, z + 10, Block.sand.blockID, 0, 3);
		world.setBlock(x + 15, y + 1, z + 13, Block.sand.blockID, 0, 3);
		world.setBlock(x + 15, y + 1, z + 14, Block.sand.blockID, 0, 3);
		world.setBlock(x + 15, y + 1, z + 15, Block.sand.blockID, 0, 3);
		world.setBlock(x + 15, y + 1, z + 16, Block.sand.blockID, 0, 3);
		world.setBlock(x + 16, y + 1, z + 0, Block.sand.blockID, 0, 3);
		world.setBlock(x + 16, y + 1, z + 1, Block.sand.blockID, 0, 3);
		world.setBlock(x + 16, y + 1, z + 2, Block.sand.blockID, 0, 3);
		world.setBlock(x + 16, y + 1, z + 3, Block.sand.blockID, 0, 3);
		world.setBlock(x + 16, y + 1, z + 4, Block.sand.blockID, 0, 3);
		world.setBlock(x + 16, y + 1, z + 5, Block.sand.blockID, 0, 3);
		world.setBlock(x + 16, y + 1, z + 11, Block.sand.blockID, 0, 3);
		world.setBlock(x + 16, y + 1, z + 12, Block.sand.blockID, 0, 3);
		world.setBlock(x + 16, y + 1, z + 13, Block.sand.blockID, 0, 3);
		world.setBlock(x + 16, y + 1, z + 14, Block.sand.blockID, 0, 3);
		world.setBlock(x + 16, y + 1, z + 15, Block.sand.blockID, 0, 3);
		world.setBlock(x + 16, y + 1, z + 16, Block.sand.blockID, 0, 3);
		
		y++;
		
		// Air
		//world.setBlock(x + 0, y + 1, z + 7, 0);
		//world.setBlock(x + 0, y + 1, z + 8, 0);
		//world.setBlock(x + 0, y + 1, z + 9, 0);
		world.setBlock(x + 0, y + 1, z + 17, 0);
		//world.setBlock(x + 0, y + 2, z + 7, 0);
		//world.setBlock(x + 0, y + 2, z + 8, 0);
		//world.setBlock(x + 0, y + 2, z + 9, 0);
		world.setBlock(x + 0, y + 2, z + 17, 0);
		world.setBlock(x + 0, y + 3, z + 17, 0);
		world.setBlock(x + 0, y + 4, z + 17, 0);
		world.setBlock(x + 0, y + 5, z + 17, 0);
		world.setBlock(x + 0, y + 6, z + 17, 0);
		world.setBlock(x + 1, y + 1, z + 6, 0);
		world.setBlock(x + 1, y + 1, z + 7, 0);
		world.setBlock(x + 1, y + 1, z + 8, 0);
		world.setBlock(x + 1, y + 1, z + 9, 0);
		world.setBlock(x + 1, y + 1, z + 10, 0);
		world.setBlock(x + 1, y + 1, z + 17, 0);
		world.setBlock(x + 1, y + 2, z + 6, 0);
		world.setBlock(x + 1, y + 2, z + 7, 0);
		world.setBlock(x + 1, y + 2, z + 8, 0);
		world.setBlock(x + 1, y + 2, z + 9, 0);
		world.setBlock(x + 1, y + 2, z + 10, 0);
		;
		world.setBlock(x + 1, y + 2, z + 17, 0);
		world.setBlock(x + 1, y + 3, z + 7, 0);
		world.setBlock(x + 1, y + 3, z + 8, 0);
		world.setBlock(x + 1, y + 3, z + 9, 0);
		world.setBlock(x + 1, y + 3, z + 17, 0);
		world.setBlock(x + 1, y + 4, z + 17, 0);
		world.setBlock(x + 1, y + 5, z + 17, 0);
		world.setBlock(x + 1, y + 6, z + 17, 0);
		world.setBlock(x + 2, y + 1, z + 4, 0);
		world.setBlock(x + 2, y + 1, z + 5, 0);
		world.setBlock(x + 2, y + 1, z + 6, 0);
		world.setBlock(x + 2, y + 1, z + 7, 0);
		world.setBlock(x + 2, y + 1, z + 8, 0);
		world.setBlock(x + 2, y + 1, z + 9, 0);
		world.setBlock(x + 2, y + 1, z + 10, 0);
		world.setBlock(x + 2, y + 1, z + 11, 0);
		world.setBlock(x + 2, y + 1, z + 12, 0);
		world.setBlock(x + 2, y + 1, z + 17, 0);
		world.setBlock(x + 2, y + 2, z + 4, 0);
		world.setBlock(x + 2, y + 2, z + 5, 0);
		world.setBlock(x + 2, y + 2, z + 6, 0);
		world.setBlock(x + 2, y + 2, z + 7, 0);
		world.setBlock(x + 2, y + 2, z + 8, 0);
		world.setBlock(x + 2, y + 2, z + 9, 0);
		world.setBlock(x + 2, y + 2, z + 10, 0);
		world.setBlock(x + 2, y + 2, z + 11, 0);
		world.setBlock(x + 2, y + 2, z + 12, 0);
		world.setBlock(x + 2, y + 2, z + 17, 0);
		world.setBlock(x + 2, y + 3, z + 6, 0);
		world.setBlock(x + 2, y + 3, z + 7, 0);
		world.setBlock(x + 2, y + 3, z + 8, 0);
		world.setBlock(x + 2, y + 3, z + 9, 0);
		world.setBlock(x + 2, y + 3, z + 10, 0);
		world.setBlock(x + 2, y + 3, z + 17, 0);
		world.setBlock(x + 2, y + 4, z + 17, 0);
		world.setBlock(x + 2, y + 5, z + 17, 0);
		world.setBlock(x + 2, y + 6, z + 17, 0);
		world.setBlock(x + 3, y + 1, z + 3, 0);
		world.setBlock(x + 3, y + 1, z + 4, 0);
		world.setBlock(x + 3, y + 1, z + 5, 0);
		world.setBlock(x + 3, y + 1, z + 6, 0);
		world.setBlock(x + 3, y + 1, z + 7, 0);
		world.setBlock(x + 3, y + 1, z + 8, 0);
		world.setBlock(x + 3, y + 1, z + 9, 0);
		world.setBlock(x + 3, y + 1, z + 10, 0);
		world.setBlock(x + 3, y + 1, z + 11, 0);
		world.setBlock(x + 3, y + 1, z + 12, 0);
		world.setBlock(x + 3, y + 1, z + 13, 0);
		world.setBlock(x + 3, y + 1, z + 17, 0);
		world.setBlock(x + 3, y + 2, z + 3, 0);
		world.setBlock(x + 3, y + 2, z + 4, 0);
		world.setBlock(x + 3, y + 2, z + 5, 0);
		world.setBlock(x + 3, y + 2, z + 6, 0);
		world.setBlock(x + 3, y + 2, z + 7, 0);
		world.setBlock(x + 3, y + 2, z + 8, 0);
		world.setBlock(x + 3, y + 2, z + 9, 0);
		world.setBlock(x + 3, y + 2, z + 10, 0);
		world.setBlock(x + 3, y + 2, z + 11, 0);
		world.setBlock(x + 3, y + 2, z + 12, 0);
		world.setBlock(x + 3, y + 2, z + 13, 0);
		world.setBlock(x + 3, y + 2, z + 17, 0);
		world.setBlock(x + 3, y + 3, z + 4, 0);
		world.setBlock(x + 3, y + 3, z + 5, 0);
		world.setBlock(x + 3, y + 3, z + 6, 0);
		world.setBlock(x + 3, y + 3, z + 7, 0);
		world.setBlock(x + 3, y + 3, z + 8, 0);
		world.setBlock(x + 3, y + 3, z + 9, 0);
		world.setBlock(x + 3, y + 3, z + 10, 0);
		world.setBlock(x + 3, y + 3, z + 11, 0);
		world.setBlock(x + 3, y + 3, z + 12, 0);
		world.setBlock(x + 3, y + 3, z + 17, 0);
		world.setBlock(x + 3, y + 4, z + 6, 0);
		world.setBlock(x + 3, y + 4, z + 7, 0);
		world.setBlock(x + 3, y + 4, z + 8, 0);
		world.setBlock(x + 3, y + 4, z + 9, 0);
		world.setBlock(x + 3, y + 4, z + 10, 0);
		world.setBlock(x + 3, y + 4, z + 17, 0);
		world.setBlock(x + 3, y + 5, z + 17, 0);
		world.setBlock(x + 3, y + 6, z + 17, 0);
		world.setBlock(x + 4, y + 1, z + 2, 0);
		world.setBlock(x + 4, y + 1, z + 3, 0);
		world.setBlock(x + 4, y + 1, z + 4, 0);
		world.setBlock(x + 4, y + 1, z + 5, 0);
		world.setBlock(x + 4, y + 1, z + 6, 0);
		world.setBlock(x + 4, y + 1, z + 7, 0);
		world.setBlock(x + 4, y + 1, z + 8, 0);
		world.setBlock(x + 4, y + 1, z + 9, 0);
		world.setBlock(x + 4, y + 1, z + 10, 0);
		world.setBlock(x + 4, y + 1, z + 11, 0);
		world.setBlock(x + 4, y + 1, z + 12, 0);
		world.setBlock(x + 4, y + 1, z + 13, 0);
		world.setBlock(x + 4, y + 1, z + 14, 0);
		world.setBlock(x + 4, y + 1, z + 17, 0);
		world.setBlock(x + 4, y + 2, z + 2, 0);
		world.setBlock(x + 4, y + 2, z + 3, 0);
		world.setBlock(x + 4, y + 2, z + 4, 0);
		world.setBlock(x + 4, y + 2, z + 5, 0);
		world.setBlock(x + 4, y + 2, z + 6, 0);
		world.setBlock(x + 4, y + 2, z + 7, 0);
		world.setBlock(x + 4, y + 2, z + 8, 0);
		world.setBlock(x + 4, y + 2, z + 9, 0);
		world.setBlock(x + 4, y + 2, z + 10, 0);
		world.setBlock(x + 4, y + 2, z + 11, 0);
		world.setBlock(x + 4, y + 2, z + 12, 0);
		world.setBlock(x + 4, y + 2, z + 13, 0);
		world.setBlock(x + 4, y + 2, z + 14, 0);
		world.setBlock(x + 4, y + 2, z + 17, 0);
		world.setBlock(x + 4, y + 3, z + 3, 0);
		world.setBlock(x + 4, y + 3, z + 4, 0);
		world.setBlock(x + 4, y + 3, z + 5, 0);
		world.setBlock(x + 4, y + 3, z + 6, 0);
		world.setBlock(x + 4, y + 3, z + 7, 0);
		world.setBlock(x + 4, y + 3, z + 8, 0);
		world.setBlock(x + 4, y + 3, z + 9, 0);
		world.setBlock(x + 4, y + 3, z + 10, 0);
		world.setBlock(x + 4, y + 3, z + 11, 0);
		world.setBlock(x + 4, y + 3, z + 12, 0);
		world.setBlock(x + 4, y + 3, z + 13, 0);
		world.setBlock(x + 4, y + 3, z + 17, 0);
		world.setBlock(x + 4, y + 4, z + 4, 0);
		world.setBlock(x + 4, y + 4, z + 5, 0);
		world.setBlock(x + 4, y + 4, z + 6, 0);
		world.setBlock(x + 4, y + 4, z + 7, 0);
		world.setBlock(x + 4, y + 4, z + 8, 0);
		world.setBlock(x + 4, y + 4, z + 9, 0);
		world.setBlock(x + 4, y + 4, z + 10, 0);
		world.setBlock(x + 4, y + 4, z + 11, 0);
		world.setBlock(x + 4, y + 4, z + 12, 0);
		world.setBlock(x + 4, y + 4, z + 17, 0);
		world.setBlock(x + 4, y + 5, z + 17, 0);
		world.setBlock(x + 4, y + 6, z + 17, 0);
		world.setBlock(x + 5, y + 1, z + 2, 0);
		world.setBlock(x + 5, y + 1, z + 3, 0);
		world.setBlock(x + 5, y + 1, z + 4, 0);
		world.setBlock(x + 5, y + 1, z + 5, 0);
		world.setBlock(x + 5, y + 1, z + 6, 0);
		world.setBlock(x + 5, y + 1, z + 7, 0);
		world.setBlock(x + 5, y + 1, z + 8, 0);
		world.setBlock(x + 5, y + 1, z + 9, 0);
		world.setBlock(x + 5, y + 1, z + 10, 0);
		world.setBlock(x + 5, y + 1, z + 11, 0);
		world.setBlock(x + 5, y + 1, z + 12, 0);
		world.setBlock(x + 5, y + 1, z + 13, 0);
		world.setBlock(x + 5, y + 1, z + 14, 0);
		world.setBlock(x + 5, y + 1, z + 17, 0);
		world.setBlock(x + 5, y + 2, z + 2, 0);
		world.setBlock(x + 5, y + 2, z + 3, 0);
		world.setBlock(x + 5, y + 2, z + 4, 0);
		world.setBlock(x + 5, y + 2, z + 5, 0);
		world.setBlock(x + 5, y + 2, z + 6, 0);
		world.setBlock(x + 5, y + 2, z + 7, 0);
		world.setBlock(x + 5, y + 2, z + 8, 0);
		world.setBlock(x + 5, y + 2, z + 9, 0);
		world.setBlock(x + 5, y + 2, z + 10, 0);
		world.setBlock(x + 5, y + 2, z + 11, 0);
		world.setBlock(x + 5, y + 2, z + 12, 0);
		world.setBlock(x + 5, y + 2, z + 13, 0);
		world.setBlock(x + 5, y + 2, z + 14, 0);
		world.setBlock(x + 5, y + 2, z + 17, 0);
		world.setBlock(x + 5, y + 3, z + 3, 0);
		world.setBlock(x + 5, y + 3, z + 4, 0);
		world.setBlock(x + 5, y + 3, z + 5, 0);
		world.setBlock(x + 5, y + 3, z + 6, 0);
		world.setBlock(x + 5, y + 3, z + 7, 0);
		world.setBlock(x + 5, y + 3, z + 8, 0);
		world.setBlock(x + 5, y + 3, z + 9, 0);
		world.setBlock(x + 5, y + 3, z + 10, 0);
		world.setBlock(x + 5, y + 3, z + 11, 0);
		world.setBlock(x + 5, y + 3, z + 12, 0);
		world.setBlock(x + 5, y + 3, z + 13, 0);
		world.setBlock(x + 5, y + 3, z + 17, 0);
		world.setBlock(x + 5, y + 4, z + 4, 0);
		world.setBlock(x + 5, y + 4, z + 5, 0);
		world.setBlock(x + 5, y + 4, z + 6, 0);
		world.setBlock(x + 5, y + 4, z + 7, 0);
		world.setBlock(x + 5, y + 4, z + 8, 0);
		world.setBlock(x + 5, y + 4, z + 9, 0);
		world.setBlock(x + 5, y + 4, z + 10, 0);
		world.setBlock(x + 5, y + 4, z + 11, 0);
		world.setBlock(x + 5, y + 4, z + 12, 0);
		world.setBlock(x + 5, y + 4, z + 17, 0);
		world.setBlock(x + 5, y + 5, z + 6, 0);
		world.setBlock(x + 5, y + 5, z + 7, 0);
		world.setBlock(x + 5, y + 5, z + 8, 0);
		world.setBlock(x + 5, y + 5, z + 9, 0);
		world.setBlock(x + 5, y + 5, z + 10, 0);
		world.setBlock(x + 5, y + 5, z + 17, 0);
		world.setBlock(x + 5, y + 6, z + 17, 0);
		world.setBlock(x + 6, y + 1, z + 1, 0);
		world.setBlock(x + 6, y + 1, z + 2, 0);
		world.setBlock(x + 6, y + 1, z + 3, 0);
		world.setBlock(x + 6, y + 1, z + 4, 0);
		world.setBlock(x + 6, y + 1, z + 5, 0);
		world.setBlock(x + 6, y + 1, z + 6, 0);
		world.setBlock(x + 6, y + 1, z + 7, 0);
		world.setBlock(x + 6, y + 1, z + 8, 0);
		world.setBlock(x + 6, y + 1, z + 9, 0);
		world.setBlock(x + 6, y + 1, z + 10, 0);
		world.setBlock(x + 6, y + 1, z + 11, 0);
		world.setBlock(x + 6, y + 1, z + 12, 0);
		world.setBlock(x + 6, y + 1, z + 13, 0);
		world.setBlock(x + 6, y + 1, z + 14, 0);
		world.setBlock(x + 6, y + 1, z + 15, 0);
		world.setBlock(x + 6, y + 1, z + 17, 0);
		world.setBlock(x + 6, y + 2, z + 1, 0);
		world.setBlock(x + 6, y + 2, z + 2, 0);
		world.setBlock(x + 6, y + 2, z + 3, 0);
		world.setBlock(x + 6, y + 2, z + 4, 0);
		world.setBlock(x + 6, y + 2, z + 5, 0);
		world.setBlock(x + 6, y + 2, z + 6, 0);
		world.setBlock(x + 6, y + 2, z + 7, 0);
		world.setBlock(x + 6, y + 2, z + 8, 0);
		world.setBlock(x + 6, y + 2, z + 9, 0);
		world.setBlock(x + 6, y + 2, z + 10, 0);
		world.setBlock(x + 6, y + 2, z + 11, 0);
		world.setBlock(x + 6, y + 2, z + 12, 0);
		world.setBlock(x + 6, y + 2, z + 13, 0);
		world.setBlock(x + 6, y + 2, z + 14, 0);
		world.setBlock(x + 6, y + 2, z + 15, 0);
		world.setBlock(x + 6, y + 2, z + 17, 0);
		world.setBlock(x + 6, y + 3, z + 2, 0);
		world.setBlock(x + 6, y + 3, z + 3, 0);
		world.setBlock(x + 6, y + 3, z + 4, 0);
		world.setBlock(x + 6, y + 3, z + 5, 0);
		world.setBlock(x + 6, y + 3, z + 6, 0);
		world.setBlock(x + 6, y + 3, z + 7, 0);
		world.setBlock(x + 6, y + 3, z + 8, 0);
		world.setBlock(x + 6, y + 3, z + 9, 0);
		world.setBlock(x + 6, y + 3, z + 10, 0);
		world.setBlock(x + 6, y + 3, z + 11, 0);
		world.setBlock(x + 6, y + 3, z + 12, 0);
		world.setBlock(x + 6, y + 3, z + 13, 0);
		world.setBlock(x + 6, y + 3, z + 14, 0);
		world.setBlock(x + 6, y + 3, z + 17, 0);
		world.setBlock(x + 6, y + 4, z + 3, 0);
		world.setBlock(x + 6, y + 4, z + 4, 0);
		world.setBlock(x + 6, y + 4, z + 5, 0);
		world.setBlock(x + 6, y + 4, z + 6, 0);
		world.setBlock(x + 6, y + 4, z + 7, 0);
		world.setBlock(x + 6, y + 4, z + 8, 0);
		world.setBlock(x + 6, y + 4, z + 9, 0);
		world.setBlock(x + 6, y + 4, z + 10, 0);
		world.setBlock(x + 6, y + 4, z + 11, 0);
		world.setBlock(x + 6, y + 4, z + 12, 0);
		world.setBlock(x + 6, y + 4, z + 13, 0);
		world.setBlock(x + 6, y + 4, z + 17, 0);
		world.setBlock(x + 6, y + 5, z + 5, 0);
		world.setBlock(x + 6, y + 5, z + 6, 0);
		world.setBlock(x + 6, y + 5, z + 7, 0);
		world.setBlock(x + 6, y + 5, z + 8, 0);
		world.setBlock(x + 6, y + 5, z + 9, 0);
		world.setBlock(x + 6, y + 5, z + 10, 0);
		world.setBlock(x + 6, y + 5, z + 11, 0);
		world.setBlock(x + 6, y + 5, z + 17, 0);
		world.setBlock(x + 6, y + 6, z + 17, 0);
		world.setBlock(x + 7, y + 1, z + 1, 0);
		world.setBlock(x + 7, y + 1, z + 2, 0);
		world.setBlock(x + 7, y + 1, z + 3, 0);
		world.setBlock(x + 7, y + 1, z + 4, 0);
		world.setBlock(x + 7, y + 1, z + 5, 0);
		world.setBlock(x + 7, y + 1, z + 6, 0);
		world.setBlock(x + 7, y + 1, z + 10, 0);
		world.setBlock(x + 7, y + 1, z + 11, 0);
		world.setBlock(x + 7, y + 1, z + 12, 0);
		world.setBlock(x + 7, y + 1, z + 13, 0);
		world.setBlock(x + 7, y + 1, z + 14, 0);
		world.setBlock(x + 7, y + 1, z + 15, 0);
		world.setBlock(x + 7, y + 1, z + 17, 0);
		world.setBlock(x + 7, y + 2, z + 1, 0);
		world.setBlock(x + 7, y + 2, z + 2, 0);
		world.setBlock(x + 7, y + 2, z + 3, 0);
		world.setBlock(x + 7, y + 2, z + 4, 0);
		world.setBlock(x + 7, y + 2, z + 5, 0);
		world.setBlock(x + 7, y + 2, z + 6, 0);
		world.setBlock(x + 7, y + 2, z + 7, 0);
		world.setBlock(x + 7, y + 2, z + 8, 0);
		world.setBlock(x + 7, y + 2, z + 9, 0);
		world.setBlock(x + 7, y + 2, z + 10, 0);
		world.setBlock(x + 7, y + 2, z + 11, 0);
		world.setBlock(x + 7, y + 2, z + 12, 0);
		world.setBlock(x + 7, y + 2, z + 13, 0);
		world.setBlock(x + 7, y + 2, z + 14, 0);
		world.setBlock(x + 7, y + 2, z + 15, 0);
		world.setBlock(x + 7, y + 2, z + 17, 0);
		world.setBlock(x + 7, y + 3, z + 2, 0);
		world.setBlock(x + 7, y + 3, z + 3, 0);
		world.setBlock(x + 7, y + 3, z + 4, 0);
		world.setBlock(x + 7, y + 3, z + 5, 0);
		world.setBlock(x + 7, y + 3, z + 6, 0);
		world.setBlock(x + 7, y + 3, z + 7, 0);
		world.setBlock(x + 7, y + 3, z + 8, 0);
		world.setBlock(x + 7, y + 3, z + 9, 0);
		world.setBlock(x + 7, y + 3, z + 10, 0);
		world.setBlock(x + 7, y + 3, z + 11, 0);
		world.setBlock(x + 7, y + 3, z + 12, 0);
		world.setBlock(x + 7, y + 3, z + 13, 0);
		world.setBlock(x + 7, y + 3, z + 14, 0);
		world.setBlock(x + 7, y + 3, z + 17, 0);
		world.setBlock(x + 7, y + 4, z + 3, 0);
		world.setBlock(x + 7, y + 4, z + 4, 0);
		world.setBlock(x + 7, y + 4, z + 5, 0);
		world.setBlock(x + 7, y + 4, z + 6, 0);
		world.setBlock(x + 7, y + 4, z + 7, 0);
		world.setBlock(x + 7, y + 4, z + 8, 0);
		world.setBlock(x + 7, y + 4, z + 9, 0);
		world.setBlock(x + 7, y + 4, z + 10, 0);
		world.setBlock(x + 7, y + 4, z + 11, 0);
		world.setBlock(x + 7, y + 4, z + 12, 0);
		world.setBlock(x + 7, y + 4, z + 13, 0);
		world.setBlock(x + 7, y + 4, z + 17, 0);
		world.setBlock(x + 7, y + 5, z + 5, 0);
		world.setBlock(x + 7, y + 5, z + 6, 0);
		world.setBlock(x + 7, y + 5, z + 7, 0);
		world.setBlock(x + 7, y + 5, z + 8, 0);
		world.setBlock(x + 7, y + 5, z + 9, 0);
		world.setBlock(x + 7, y + 5, z + 10, 0);
		world.setBlock(x + 7, y + 5, z + 11, 0);
		world.setBlock(x + 7, y + 5, z + 17, 0);
		world.setBlock(x + 7, y + 6, z + 17, 0);
		world.setBlock(x + 8, y + 1, z + 1, 0);
		world.setBlock(x + 8, y + 1, z + 2, 0);
		world.setBlock(x + 8, y + 1, z + 3, 0);
		world.setBlock(x + 8, y + 1, z + 4, 0);
		world.setBlock(x + 8, y + 1, z + 5, 0);
		world.setBlock(x + 8, y + 1, z + 6, 0);
		world.setBlock(x + 8, y + 1, z + 10, 0);
		world.setBlock(x + 8, y + 1, z + 11, 0);
		world.setBlock(x + 8, y + 1, z + 12, 0);
		world.setBlock(x + 8, y + 1, z + 13, 0);
		world.setBlock(x + 8, y + 1, z + 14, 0);
		world.setBlock(x + 8, y + 1, z + 15, 0);
		world.setBlock(x + 8, y + 1, z + 17, 0);
		world.setBlock(x + 8, y + 2, z + 1, 0);
		world.setBlock(x + 8, y + 2, z + 2, 0);
		world.setBlock(x + 8, y + 2, z + 3, 0);
		world.setBlock(x + 8, y + 2, z + 4, 0);
		world.setBlock(x + 8, y + 2, z + 5, 0);
		world.setBlock(x + 8, y + 2, z + 6, 0);
		world.setBlock(x + 8, y + 2, z + 7, 0);
		world.setBlock(x + 8, y + 2, z + 9, 0);
		world.setBlock(x + 8, y + 2, z + 10, 0);
		world.setBlock(x + 8, y + 2, z + 11, 0);
		world.setBlock(x + 8, y + 2, z + 12, 0);
		world.setBlock(x + 8, y + 2, z + 13, 0);
		world.setBlock(x + 8, y + 2, z + 14, 0);
		world.setBlock(x + 8, y + 2, z + 15, 0);
		world.setBlock(x + 8, y + 2, z + 17, 0);
		world.setBlock(x + 8, y + 3, z + 2, 0);
		world.setBlock(x + 8, y + 3, z + 3, 0);
		world.setBlock(x + 8, y + 3, z + 4, 0);
		world.setBlock(x + 8, y + 3, z + 5, 0);
		world.setBlock(x + 8, y + 3, z + 6, 0);
		world.setBlock(x + 8, y + 3, z + 7, 0);
		world.setBlock(x + 8, y + 3, z + 9, 0);
		world.setBlock(x + 8, y + 3, z + 10, 0);
		world.setBlock(x + 8, y + 3, z + 11, 0);
		world.setBlock(x + 8, y + 3, z + 12, 0);
		world.setBlock(x + 8, y + 3, z + 13, 0);
		world.setBlock(x + 8, y + 3, z + 14, 0);
		world.setBlock(x + 8, y + 3, z + 17, 0);
		world.setBlock(x + 8, y + 4, z + 3, 0);
		world.setBlock(x + 8, y + 4, z + 4, 0);
		world.setBlock(x + 8, y + 4, z + 5, 0);
		world.setBlock(x + 8, y + 4, z + 6, 0);
		world.setBlock(x + 8, y + 4, z + 7, 0);
		world.setBlock(x + 8, y + 4, z + 8, 0);
		world.setBlock(x + 8, y + 4, z + 9, 0);
		world.setBlock(x + 8, y + 4, z + 10, 0);
		world.setBlock(x + 8, y + 4, z + 11, 0);
		world.setBlock(x + 8, y + 4, z + 12, 0);
		world.setBlock(x + 8, y + 4, z + 13, 0);
		world.setBlock(x + 8, y + 4, z + 17, 0);
		world.setBlock(x + 8, y + 5, z + 5, 0);
		world.setBlock(x + 8, y + 5, z + 6, 0);
		world.setBlock(x + 8, y + 5, z + 7, 0);
		world.setBlock(x + 8, y + 5, z + 8, 0);
		world.setBlock(x + 8, y + 5, z + 9, 0);
		world.setBlock(x + 8, y + 5, z + 10, 0);
		world.setBlock(x + 8, y + 5, z + 11, 0);
		world.setBlock(x + 8, y + 5, z + 17, 0);
		world.setBlock(x + 8, y + 6, z + 17, 0);
		world.setBlock(x + 9, y + 1, z + 1, 0);
		world.setBlock(x + 9, y + 1, z + 2, 0);
		world.setBlock(x + 9, y + 1, z + 3, 0);
		world.setBlock(x + 9, y + 1, z + 4, 0);
		world.setBlock(x + 9, y + 1, z + 5, 0);
		world.setBlock(x + 9, y + 1, z + 6, 0);
		world.setBlock(x + 9, y + 1, z + 10, 0);
		world.setBlock(x + 9, y + 1, z + 11, 0);
		world.setBlock(x + 9, y + 1, z + 12, 0);
		world.setBlock(x + 9, y + 1, z + 13, 0);
		world.setBlock(x + 9, y + 1, z + 14, 0);
		world.setBlock(x + 9, y + 1, z + 15, 0);
		world.setBlock(x + 9, y + 1, z + 17, 0);
		world.setBlock(x + 9, y + 2, z + 1, 0);
		world.setBlock(x + 9, y + 2, z + 2, 0);
		world.setBlock(x + 9, y + 2, z + 3, 0);
		world.setBlock(x + 9, y + 2, z + 4, 0);
		world.setBlock(x + 9, y + 2, z + 5, 0);
		world.setBlock(x + 9, y + 2, z + 6, 0);
		world.setBlock(x + 9, y + 2, z + 7, 0);
		world.setBlock(x + 9, y + 2, z + 8, 0);
		world.setBlock(x + 9, y + 2, z + 9, 0);
		world.setBlock(x + 9, y + 2, z + 10, 0);
		world.setBlock(x + 9, y + 2, z + 11, 0);
		world.setBlock(x + 9, y + 2, z + 12, 0);
		world.setBlock(x + 9, y + 2, z + 13, 0);
		world.setBlock(x + 9, y + 2, z + 14, 0);
		world.setBlock(x + 9, y + 2, z + 15, 0);
		world.setBlock(x + 9, y + 2, z + 17, 0);
		world.setBlock(x + 9, y + 3, z + 2, 0);
		world.setBlock(x + 9, y + 3, z + 3, 0);
		world.setBlock(x + 9, y + 3, z + 4, 0);
		world.setBlock(x + 9, y + 3, z + 5, 0);
		world.setBlock(x + 9, y + 3, z + 6, 0);
		world.setBlock(x + 9, y + 3, z + 7, 0);
		world.setBlock(x + 9, y + 3, z + 8, 0);
		world.setBlock(x + 9, y + 3, z + 9, 0);
		world.setBlock(x + 9, y + 3, z + 10, 0);
		world.setBlock(x + 9, y + 3, z + 11, 0);
		world.setBlock(x + 9, y + 3, z + 12, 0);
		world.setBlock(x + 9, y + 3, z + 13, 0);
		world.setBlock(x + 9, y + 3, z + 14, 0);
		world.setBlock(x + 9, y + 3, z + 17, 0);
		world.setBlock(x + 9, y + 4, z + 3, 0);
		world.setBlock(x + 9, y + 4, z + 4, 0);
		world.setBlock(x + 9, y + 4, z + 5, 0);
		world.setBlock(x + 9, y + 4, z + 6, 0);
		world.setBlock(x + 9, y + 4, z + 7, 0);
		world.setBlock(x + 9, y + 4, z + 8, 0);
		world.setBlock(x + 9, y + 4, z + 9, 0);
		world.setBlock(x + 9, y + 4, z + 10, 0);
		world.setBlock(x + 9, y + 4, z + 11, 0);
		world.setBlock(x + 9, y + 4, z + 12, 0);
		world.setBlock(x + 9, y + 4, z + 13, 0);
		world.setBlock(x + 9, y + 4, z + 17, 0);
		world.setBlock(x + 9, y + 5, z + 5, 0);
		world.setBlock(x + 9, y + 5, z + 6, 0);
		world.setBlock(x + 9, y + 5, z + 7, 0);
		world.setBlock(x + 9, y + 5, z + 8, 0);
		world.setBlock(x + 9, y + 5, z + 9, 0);
		world.setBlock(x + 9, y + 5, z + 10, 0);
		world.setBlock(x + 9, y + 5, z + 11, 0);
		world.setBlock(x + 9, y + 5, z + 17, 0);
		world.setBlock(x + 9, y + 6, z + 17, 0);
		world.setBlock(x + 10, y + 1, z + 1, 0);
		world.setBlock(x + 10, y + 1, z + 2, 0);
		world.setBlock(x + 10, y + 1, z + 3, 0);
		world.setBlock(x + 10, y + 1, z + 4, 0);
		world.setBlock(x + 10, y + 1, z + 5, 0);
		world.setBlock(x + 10, y + 1, z + 6, 0);
		// world.setBlock(x + 10, y + 1, z + 7, 0);
		world.setBlock(x + 10, y + 1, z + 8, 0);
		// world.setBlock(x + 10, y + 1, z + 9, 0);
		world.setBlock(x + 10, y + 1, z + 10, 0);
		world.setBlock(x + 10, y + 1, z + 11, 0);
		world.setBlock(x + 10, y + 1, z + 12, 0);
		world.setBlock(x + 10, y + 1, z + 13, 0);
		world.setBlock(x + 10, y + 1, z + 14, 0);
		world.setBlock(x + 10, y + 1, z + 15, 0);
		world.setBlock(x + 10, y + 1, z + 17, 0);
		world.setBlock(x + 10, y + 2, z + 1, 0);
		world.setBlock(x + 10, y + 2, z + 2, 0);
		world.setBlock(x + 10, y + 2, z + 3, 0);
		world.setBlock(x + 10, y + 2, z + 4, 0);
		world.setBlock(x + 10, y + 2, z + 5, 0);
		world.setBlock(x + 10, y + 2, z + 6, 0);
		world.setBlock(x + 10, y + 2, z + 7, 0);
		world.setBlock(x + 10, y + 2, z + 8, 0);
		world.setBlock(x + 10, y + 2, z + 9, 0);
		world.setBlock(x + 10, y + 2, z + 10, 0);
		world.setBlock(x + 10, y + 2, z + 11, 0);
		world.setBlock(x + 10, y + 2, z + 12, 0);
		world.setBlock(x + 10, y + 2, z + 13, 0);
		world.setBlock(x + 10, y + 2, z + 14, 0);
		world.setBlock(x + 10, y + 2, z + 15, 0);
		world.setBlock(x + 10, y + 2, z + 17, 0);
		world.setBlock(x + 10, y + 3, z + 2, 0);
		world.setBlock(x + 10, y + 3, z + 3, 0);
		world.setBlock(x + 10, y + 3, z + 4, 0);
		world.setBlock(x + 10, y + 3, z + 5, 0);
		world.setBlock(x + 10, y + 3, z + 6, 0);
		world.setBlock(x + 10, y + 3, z + 7, 0);
		world.setBlock(x + 10, y + 3, z + 8, 0);
		world.setBlock(x + 10, y + 3, z + 9, 0);
		world.setBlock(x + 10, y + 3, z + 10, 0);
		world.setBlock(x + 10, y + 3, z + 11, 0);
		world.setBlock(x + 10, y + 3, z + 12, 0);
		world.setBlock(x + 10, y + 3, z + 13, 0);
		world.setBlock(x + 10, y + 3, z + 14, 0);
		world.setBlock(x + 10, y + 3, z + 17, 0);
		world.setBlock(x + 10, y + 4, z + 3, 0);
		world.setBlock(x + 10, y + 4, z + 4, 0);
		world.setBlock(x + 10, y + 4, z + 5, 0);
		world.setBlock(x + 10, y + 4, z + 6, 0);
		world.setBlock(x + 10, y + 4, z + 7, 0);
		world.setBlock(x + 10, y + 4, z + 8, 0);
		world.setBlock(x + 10, y + 4, z + 9, 0);
		world.setBlock(x + 10, y + 4, z + 10, 0);
		world.setBlock(x + 10, y + 4, z + 11, 0);
		world.setBlock(x + 10, y + 4, z + 12, 0);
		world.setBlock(x + 10, y + 4, z + 13, 0);
		world.setBlock(x + 10, y + 4, z + 17, 0);
		world.setBlock(x + 10, y + 5, z + 5, 0);
		world.setBlock(x + 10, y + 5, z + 6, 0);
		world.setBlock(x + 10, y + 5, z + 7, 0);
		world.setBlock(x + 10, y + 5, z + 8, 0);
		world.setBlock(x + 10, y + 5, z + 9, 0);
		world.setBlock(x + 10, y + 5, z + 10, 0);
		world.setBlock(x + 10, y + 5, z + 11, 0);
		world.setBlock(x + 10, y + 5, z + 17, 0);
		world.setBlock(x + 10, y + 6, z + 17, 0);
		world.setBlock(x + 11, y + 1, z + 2, 0);
		world.setBlock(x + 11, y + 1, z + 3, 0);
		world.setBlock(x + 11, y + 1, z + 4, 0);
		world.setBlock(x + 11, y + 1, z + 5, 0);
		world.setBlock(x + 11, y + 1, z + 6, 0);
		world.setBlock(x + 11, y + 1, z + 7, 0);
		world.setBlock(x + 11, y + 1, z + 8, 0);
		world.setBlock(x + 11, y + 1, z + 9, 0);
		world.setBlock(x + 11, y + 1, z + 10, 0);
		world.setBlock(x + 11, y + 1, z + 11, 0);
		world.setBlock(x + 11, y + 1, z + 12, 0);
		world.setBlock(x + 11, y + 1, z + 13, 0);
		world.setBlock(x + 11, y + 1, z + 14, 0);
		world.setBlock(x + 11, y + 1, z + 17, 0);
		world.setBlock(x + 11, y + 2, z + 2, 0);
		world.setBlock(x + 11, y + 2, z + 3, 0);
		world.setBlock(x + 11, y + 2, z + 4, 0);
		world.setBlock(x + 11, y + 2, z + 5, 0);
		world.setBlock(x + 11, y + 2, z + 6, 0);
		world.setBlock(x + 11, y + 2, z + 7, 0);
		world.setBlock(x + 11, y + 2, z + 8, 0);
		world.setBlock(x + 11, y + 2, z + 9, 0);
		world.setBlock(x + 11, y + 2, z + 10, 0);
		world.setBlock(x + 11, y + 2, z + 11, 0);
		world.setBlock(x + 11, y + 2, z + 12, 0);
		world.setBlock(x + 11, y + 2, z + 13, 0);
		world.setBlock(x + 11, y + 2, z + 14, 0);
		world.setBlock(x + 11, y + 2, z + 17, 0);
		world.setBlock(x + 11, y + 3, z + 3, 0);
		world.setBlock(x + 11, y + 3, z + 4, 0);
		world.setBlock(x + 11, y + 3, z + 5, 0);
		world.setBlock(x + 11, y + 3, z + 6, 0);
		world.setBlock(x + 11, y + 3, z + 7, 0);
		world.setBlock(x + 11, y + 3, z + 8, 0);
		world.setBlock(x + 11, y + 3, z + 9, 0);
		world.setBlock(x + 11, y + 3, z + 10, 0);
		world.setBlock(x + 11, y + 3, z + 11, 0);
		world.setBlock(x + 11, y + 3, z + 12, 0);
		world.setBlock(x + 11, y + 3, z + 13, 0);
		world.setBlock(x + 11, y + 3, z + 17, 0);
		world.setBlock(x + 11, y + 4, z + 4, 0);
		world.setBlock(x + 11, y + 4, z + 5, 0);
		world.setBlock(x + 11, y + 4, z + 6, 0);
		world.setBlock(x + 11, y + 4, z + 7, 0);
		world.setBlock(x + 11, y + 4, z + 8, 0);
		world.setBlock(x + 11, y + 4, z + 9, 0);
		world.setBlock(x + 11, y + 4, z + 10, 0);
		world.setBlock(x + 11, y + 4, z + 11, 0);
		world.setBlock(x + 11, y + 4, z + 12, 0);
		world.setBlock(x + 11, y + 4, z + 17, 0);
		world.setBlock(x + 11, y + 5, z + 6, 0);
		world.setBlock(x + 11, y + 5, z + 7, 0);
		world.setBlock(x + 11, y + 5, z + 8, 0);
		world.setBlock(x + 11, y + 5, z + 9, 0);
		world.setBlock(x + 11, y + 5, z + 10, 0);
		world.setBlock(x + 11, y + 5, z + 17, 0);
		world.setBlock(x + 11, y + 6, z + 17, 0);
		world.setBlock(x + 12, y + 1, z + 2, 0);
		world.setBlock(x + 12, y + 1, z + 3, 0);
		world.setBlock(x + 12, y + 1, z + 4, 0);
		world.setBlock(x + 12, y + 1, z + 5, 0);
		world.setBlock(x + 12, y + 1, z + 6, 0);
		world.setBlock(x + 12, y + 1, z + 7, 0);
		world.setBlock(x + 12, y + 1, z + 8, 0);
		world.setBlock(x + 12, y + 1, z + 9, 0);
		world.setBlock(x + 12, y + 1, z + 10, 0);
		world.setBlock(x + 12, y + 1, z + 11, 0);
		world.setBlock(x + 12, y + 1, z + 12, 0);
		world.setBlock(x + 12, y + 1, z + 13, 0);
		world.setBlock(x + 12, y + 1, z + 14, 0);
		world.setBlock(x + 12, y + 1, z + 17, 0);
		world.setBlock(x + 12, y + 2, z + 2, 0);
		world.setBlock(x + 12, y + 2, z + 3, 0);
		world.setBlock(x + 12, y + 2, z + 4, 0);
		world.setBlock(x + 12, y + 2, z + 5, 0);
		world.setBlock(x + 12, y + 2, z + 6, 0);
		world.setBlock(x + 12, y + 2, z + 7, 0);
		world.setBlock(x + 12, y + 2, z + 8, 0);
		world.setBlock(x + 12, y + 2, z + 9, 0);
		world.setBlock(x + 12, y + 2, z + 10, 0);
		world.setBlock(x + 12, y + 2, z + 11, 0);
		world.setBlock(x + 12, y + 2, z + 12, 0);
		world.setBlock(x + 12, y + 2, z + 13, 0);
		world.setBlock(x + 12, y + 2, z + 14, 0);
		world.setBlock(x + 12, y + 2, z + 17, 0);
		world.setBlock(x + 12, y + 3, z + 3, 0);
		world.setBlock(x + 12, y + 3, z + 4, 0);
		world.setBlock(x + 12, y + 3, z + 5, 0);
		world.setBlock(x + 12, y + 3, z + 6, 0);
		world.setBlock(x + 12, y + 3, z + 7, 0);
		world.setBlock(x + 12, y + 3, z + 8, 0);
		world.setBlock(x + 12, y + 3, z + 9, 0);
		world.setBlock(x + 12, y + 3, z + 10, 0);
		world.setBlock(x + 12, y + 3, z + 11, 0);
		world.setBlock(x + 12, y + 3, z + 12, 0);
		world.setBlock(x + 12, y + 3, z + 13, 0);
		world.setBlock(x + 12, y + 3, z + 17, 0);
		world.setBlock(x + 12, y + 4, z + 4, 0);
		world.setBlock(x + 12, y + 4, z + 5, 0);
		world.setBlock(x + 12, y + 4, z + 6, 0);
		world.setBlock(x + 12, y + 4, z + 7, 0);
		world.setBlock(x + 12, y + 4, z + 8, 0);
		world.setBlock(x + 12, y + 4, z + 9, 0);
		world.setBlock(x + 12, y + 4, z + 10, 0);
		world.setBlock(x + 12, y + 4, z + 11, 0);
		world.setBlock(x + 12, y + 4, z + 12, 0);
		world.setBlock(x + 12, y + 4, z + 17, 0);
		world.setBlock(x + 12, y + 5, z + 17, 0);
		world.setBlock(x + 12, y + 6, z + 17, 0);
		world.setBlock(x + 13, y + 1, z + 3, 0);
		world.setBlock(x + 13, y + 1, z + 4, 0);
		world.setBlock(x + 13, y + 1, z + 5, 0);
		world.setBlock(x + 13, y + 1, z + 6, 0);
		world.setBlock(x + 13, y + 1, z + 7, 0);
		world.setBlock(x + 13, y + 1, z + 8, 0);
		world.setBlock(x + 13, y + 1, z + 9, 0);
		world.setBlock(x + 13, y + 1, z + 10, 0);
		world.setBlock(x + 13, y + 1, z + 11, 0);
		world.setBlock(x + 13, y + 1, z + 12, 0);
		world.setBlock(x + 13, y + 1, z + 13, 0);
		world.setBlock(x + 13, y + 1, z + 17, 0);
		world.setBlock(x + 13, y + 2, z + 3, 0);
		world.setBlock(x + 13, y + 2, z + 4, 0);
		world.setBlock(x + 13, y + 2, z + 5, 0);
		world.setBlock(x + 13, y + 2, z + 6, 0);
		world.setBlock(x + 13, y + 2, z + 7, 0);
		world.setBlock(x + 13, y + 2, z + 8, 0);
		world.setBlock(x + 13, y + 2, z + 9, 0);
		world.setBlock(x + 13, y + 2, z + 10, 0);
		world.setBlock(x + 13, y + 2, z + 11, 0);
		world.setBlock(x + 13, y + 2, z + 12, 0);
		world.setBlock(x + 13, y + 2, z + 13, 0);
		world.setBlock(x + 13, y + 2, z + 17, 0);
		world.setBlock(x + 13, y + 3, z + 4, 0);
		world.setBlock(x + 13, y + 3, z + 5, 0);
		world.setBlock(x + 13, y + 3, z + 6, 0);
		world.setBlock(x + 13, y + 3, z + 7, 0);
		world.setBlock(x + 13, y + 3, z + 8, 0);
		world.setBlock(x + 13, y + 3, z + 9, 0);
		world.setBlock(x + 13, y + 3, z + 10, 0);
		world.setBlock(x + 13, y + 3, z + 11, 0);
		world.setBlock(x + 13, y + 3, z + 12, 0);
		world.setBlock(x + 13, y + 3, z + 17, 0);
		world.setBlock(x + 13, y + 4, z + 6, 0);
		world.setBlock(x + 13, y + 4, z + 7, 0);
		world.setBlock(x + 13, y + 4, z + 8, 0);
		world.setBlock(x + 13, y + 4, z + 9, 0);
		world.setBlock(x + 13, y + 4, z + 10, 0);
		world.setBlock(x + 13, y + 4, z + 17, 0);
		world.setBlock(x + 13, y + 5, z + 17, 0);
		world.setBlock(x + 13, y + 6, z + 17, 0);
		world.setBlock(x + 14, y + 1, z + 4, 0);
		world.setBlock(x + 14, y + 1, z + 5, 0);
		world.setBlock(x + 14, y + 1, z + 6, 0);
		world.setBlock(x + 14, y + 1, z + 7, 0);
		world.setBlock(x + 14, y + 1, z + 8, 0);
		world.setBlock(x + 14, y + 1, z + 9, 0);
		world.setBlock(x + 14, y + 1, z + 10, 0);
		world.setBlock(x + 14, y + 1, z + 11, 0);
		world.setBlock(x + 14, y + 1, z + 12, 0);
		world.setBlock(x + 14, y + 1, z + 17, 0);
		world.setBlock(x + 14, y + 2, z + 4, 0);
		world.setBlock(x + 14, y + 2, z + 5, 0);
		world.setBlock(x + 14, y + 2, z + 6, 0);
		world.setBlock(x + 14, y + 2, z + 7, 0);
		world.setBlock(x + 14, y + 2, z + 8, 0);
		world.setBlock(x + 14, y + 2, z + 9, 0);
		world.setBlock(x + 14, y + 2, z + 10, 0);
		world.setBlock(x + 14, y + 2, z + 11, 0);
		world.setBlock(x + 14, y + 2, z + 12, 0);
		world.setBlock(x + 14, y + 2, z + 17, 0);
		world.setBlock(x + 14, y + 3, z + 6, 0);
		world.setBlock(x + 14, y + 3, z + 7, 0);
		world.setBlock(x + 14, y + 3, z + 8, 0);
		world.setBlock(x + 14, y + 3, z + 9, 0);
		world.setBlock(x + 14, y + 3, z + 10, 0);
		world.setBlock(x + 14, y + 3, z + 17, 0);
		world.setBlock(x + 14, y + 4, z + 17, 0);
		world.setBlock(x + 14, y + 5, z + 17, 0);
		world.setBlock(x + 14, y + 6, z + 17, 0);
		world.setBlock(x + 15, y + 1, z + 6, 0);
		world.setBlock(x + 15, y + 1, z + 7, 0);
		world.setBlock(x + 15, y + 1, z + 8, 0);
		world.setBlock(x + 15, y + 1, z + 9, 0);
		world.setBlock(x + 15, y + 1, z + 10, 0);
		world.setBlock(x + 15, y + 1, z + 17, 0);
		world.setBlock(x + 15, y + 2, z + 6, 0);
		world.setBlock(x + 15, y + 2, z + 7, 0);
		world.setBlock(x + 15, y + 2, z + 8, 0);
		world.setBlock(x + 15, y + 2, z + 9, 0);
		world.setBlock(x + 15, y + 2, z + 10, 0);
		world.setBlock(x + 15, y + 2, z + 17, 0);
		world.setBlock(x + 15, y + 3, z + 17, 0);
		world.setBlock(x + 15, y + 4, z + 17, 0);
		world.setBlock(x + 15, y + 5, z + 17, 0);
		world.setBlock(x + 15, y + 6, z + 17, 0);
		world.setBlock(x + 16, y + 1, z + 17, 0);
		world.setBlock(x + 16, y + 2, z + 17, 0);
		world.setBlock(x + 16, y + 3, z + 17, 0);
		world.setBlock(x + 16, y + 4, z + 17, 0);
		world.setBlock(x + 16, y + 5, z + 17, 0);
		world.setBlock(x + 16, y + 6, z + 17, 0);
		world.setBlock(x + 17, y + 1, z + 0, 0);
		world.setBlock(x + 17, y + 1, z + 1, 0);
		world.setBlock(x + 17, y + 1, z + 2, 0);
		world.setBlock(x + 17, y + 1, z + 3, 0);
		world.setBlock(x + 17, y + 1, z + 4, 0);
		world.setBlock(x + 17, y + 1, z + 5, 0);
		world.setBlock(x + 17, y + 1, z + 6, 0);
		world.setBlock(x + 17, y + 1, z + 7, 0);
		world.setBlock(x + 17, y + 1, z + 8, 0);
		world.setBlock(x + 17, y + 1, z + 9, 0);
		world.setBlock(x + 17, y + 1, z + 10, 0);
		world.setBlock(x + 17, y + 1, z + 11, 0);
		world.setBlock(x + 17, y + 1, z + 12, 0);
		world.setBlock(x + 17, y + 1, z + 13, 0);
		world.setBlock(x + 17, y + 1, z + 14, 0);
		world.setBlock(x + 17, y + 1, z + 15, 0);
		world.setBlock(x + 17, y + 1, z + 16, 0);
		world.setBlock(x + 17, y + 1, z + 17, 0);
		world.setBlock(x + 17, y + 2, z + 0, 0);
		world.setBlock(x + 17, y + 2, z + 1, 0);
		world.setBlock(x + 17, y + 2, z + 2, 0);
		world.setBlock(x + 17, y + 2, z + 3, 0);
		world.setBlock(x + 17, y + 2, z + 4, 0);
		world.setBlock(x + 17, y + 2, z + 5, 0);
		world.setBlock(x + 17, y + 2, z + 6, 0);
		world.setBlock(x + 17, y + 2, z + 7, 0);
		world.setBlock(x + 17, y + 2, z + 8, 0);
		world.setBlock(x + 17, y + 2, z + 9, 0);
		world.setBlock(x + 17, y + 2, z + 10, 0);
		world.setBlock(x + 17, y + 2, z + 11, 0);
		world.setBlock(x + 17, y + 2, z + 12, 0);
		world.setBlock(x + 17, y + 2, z + 13, 0);
		world.setBlock(x + 17, y + 2, z + 14, 0);
		world.setBlock(x + 17, y + 2, z + 15, 0);
		world.setBlock(x + 17, y + 2, z + 16, 0);
		world.setBlock(x + 17, y + 2, z + 17, 0);
		world.setBlock(x + 17, y + 3, z + 0, 0);
		world.setBlock(x + 17, y + 3, z + 1, 0);
		world.setBlock(x + 17, y + 3, z + 2, 0);
		world.setBlock(x + 17, y + 3, z + 3, 0);
		world.setBlock(x + 17, y + 3, z + 4, 0);
		world.setBlock(x + 17, y + 3, z + 5, 0);
		world.setBlock(x + 17, y + 3, z + 6, 0);
		world.setBlock(x + 17, y + 3, z + 7, 0);
		world.setBlock(x + 17, y + 3, z + 8, 0);
		world.setBlock(x + 17, y + 3, z + 9, 0);
		world.setBlock(x + 17, y + 3, z + 10, 0);
		world.setBlock(x + 17, y + 3, z + 11, 0);
		world.setBlock(x + 17, y + 3, z + 12, 0);
		world.setBlock(x + 17, y + 3, z + 13, 0);
		world.setBlock(x + 17, y + 3, z + 14, 0);
		world.setBlock(x + 17, y + 3, z + 15, 0);
		world.setBlock(x + 17, y + 3, z + 16, 0);
		world.setBlock(x + 17, y + 3, z + 17, 0);
		world.setBlock(x + 17, y + 4, z + 0, 0);
		world.setBlock(x + 17, y + 4, z + 1, 0);
		world.setBlock(x + 17, y + 4, z + 2, 0);
		world.setBlock(x + 17, y + 4, z + 3, 0);
		world.setBlock(x + 17, y + 4, z + 4, 0);
		world.setBlock(x + 17, y + 4, z + 5, 0);
		world.setBlock(x + 17, y + 4, z + 6, 0);
		world.setBlock(x + 17, y + 4, z + 7, 0);
		world.setBlock(x + 17, y + 4, z + 8, 0);
		world.setBlock(x + 17, y + 4, z + 9, 0);
		world.setBlock(x + 17, y + 4, z + 10, 0);
		world.setBlock(x + 17, y + 4, z + 11, 0);
		world.setBlock(x + 17, y + 4, z + 12, 0);
		world.setBlock(x + 17, y + 4, z + 13, 0);
		world.setBlock(x + 17, y + 4, z + 14, 0);
		world.setBlock(x + 17, y + 4, z + 15, 0);
		world.setBlock(x + 17, y + 4, z + 16, 0);
		world.setBlock(x + 17, y + 4, z + 17, 0);
		world.setBlock(x + 17, y + 5, z + 0, 0);
		world.setBlock(x + 17, y + 5, z + 1, 0);
		world.setBlock(x + 17, y + 5, z + 2, 0);
		world.setBlock(x + 17, y + 5, z + 3, 0);
		world.setBlock(x + 17, y + 5, z + 4, 0);
		world.setBlock(x + 17, y + 5, z + 5, 0);
		world.setBlock(x + 17, y + 5, z + 6, 0);
		world.setBlock(x + 17, y + 5, z + 7, 0);
		world.setBlock(x + 17, y + 5, z + 8, 0);
		world.setBlock(x + 17, y + 5, z + 9, 0);
		world.setBlock(x + 17, y + 5, z + 10, 0);
		world.setBlock(x + 17, y + 5, z + 11, 0);
		world.setBlock(x + 17, y + 5, z + 12, 0);
		world.setBlock(x + 17, y + 5, z + 13, 0);
		world.setBlock(x + 17, y + 5, z + 14, 0);
		world.setBlock(x + 17, y + 5, z + 15, 0);
		world.setBlock(x + 17, y + 5, z + 16, 0);
		world.setBlock(x + 17, y + 5, z + 17, 0);
		world.setBlock(x + 17, y + 6, z + 0, 0);
		world.setBlock(x + 17, y + 6, z + 1, 0);
		world.setBlock(x + 17, y + 6, z + 2, 0);
		world.setBlock(x + 17, y + 6, z + 3, 0);
		world.setBlock(x + 17, y + 6, z + 4, 0);
		world.setBlock(x + 17, y + 6, z + 5, 0);
		world.setBlock(x + 17, y + 6, z + 6, 0);
		world.setBlock(x + 17, y + 6, z + 7, 0);
		world.setBlock(x + 17, y + 6, z + 8, 0);
		world.setBlock(x + 17, y + 6, z + 9, 0);
		world.setBlock(x + 17, y + 6, z + 10, 0);
		world.setBlock(x + 17, y + 6, z + 11, 0);
		world.setBlock(x + 17, y + 6, z + 12, 0);
		world.setBlock(x + 17, y + 6, z + 13, 0);
		world.setBlock(x + 17, y + 6, z + 14, 0);
		world.setBlock(x + 17, y + 6, z + 15, 0);
		world.setBlock(x + 17, y + 6, z + 16, 0);
		world.setBlock(x + 17, y + 6, z + 17, 0);
	}
	
}