/*
*** MADE BY MITHION'S .SCHEMATIC TO JAVA CONVERTING TOOL v1.6 ***
*/

package oceania.gen;
import java.util.ArrayList;
import java.util.List;
import java.util.Random;

import oceania.blocks.Blocks;

import cpw.mods.fml.common.IWorldGenerator;

import net.minecraft.block.Block;
import net.minecraft.world.World;
import net.minecraft.world.biome.BiomeGenBase;
import net.minecraft.world.chunk.IChunkProvider;

public class WorldGenUnderwaterVillage implements IWorldGenerator
{
	
	public boolean LocationIsValidSpawn(World world, int x, int y, int z)
	{
		List<Integer> validDirt = new ArrayList<Integer>();
		List<Integer> validWater = new ArrayList<Integer>();
		validWater.add(world.getBlockId(x + 8, y + 7, z + 8));
		validWater.add(world.getBlockId(x, y + 7, z));
		validWater.add(world.getBlockId(x + 16, y + 7, z + 8));
		validWater.add(world.getBlockId(x + 8, y + 7, z + 16));
		validWater.add(world.getBlockId(x + 16, y + 7, z + 16));
		
		validDirt.add(world.getBlockId(x + 8, y + 1, z + 8));
		validDirt.add(world.getBlockId(x, y + 1, z));
		validDirt.add(world.getBlockId(x + 16, y + 1, z + 8));
		validDirt.add(world.getBlockId(x + 8, y + 1, z + 16));
		validDirt.add(world.getBlockId(x + 16, y + 1, z + 16));
		
		if(world.rand.nextInt(10) != 1)
			return false;
		
		for(int validID : validWater)
		{
			if(!(validID == Block.waterStill.blockID || validID == Block.waterMoving.blockID))
				return false;
		}
		
		for(int validID : validDirt)
		{
			if(!(validID == Block.dirt.blockID || validID == Block.blockClay.blockID || validID == Block.sand.blockID))
				return false;
		}
		
		return true;
	}

	@Override
	public void generate(Random random, int chunkX, int chunkZ, World world, IChunkProvider chunkGenerator, IChunkProvider chunkProvider) 
	{
	    int i = (chunkX * 16) + random.nextInt(16); // x
	    int j = 0; // y
	    int k = (chunkZ * 16) + random.nextInt(16); // z
	    
	    for(int count = 40; count <= 60; count++) {
	    	int blockID = world.getBlockId(i, count + 1, k);
	    	int blockAboveID = world.getBlockId(i, count + 2, k);
	    	if((blockID == Block.sand.blockID || blockID == Block.dirt.blockID) && (blockAboveID == Block.waterStill.blockID || blockAboveID == Block.waterMoving.blockID))
	    	{
	    		j = count - 1;
	    		break;
	    	}
	    }

	    if(world.getBiomeGenForCoords(i, k) != BiomeGenBase.ocean || !LocationIsValidSpawn(world, i, j, k) || j == 0)
	    {
			return;
	    }

        System.out.println("New Underwater Village at "+i+" "+j+" "+k+" ");
		world.setBlock(i + 0, j + 0, k + 0, Block.dirt.blockID);
		world.setBlock(i + 0, j + 0, k + 1, Block.dirt.blockID);
		world.setBlock(i + 0, j + 0, k + 2, Block.dirt.blockID);
		world.setBlock(i + 0, j + 0, k + 3, Block.dirt.blockID);
		world.setBlock(i + 0, j + 0, k + 4, Block.dirt.blockID);
		world.setBlock(i + 0, j + 0, k + 5, Block.dirt.blockID);
		world.setBlock(i + 0, j + 0, k + 6, Block.dirt.blockID);
		world.setBlock(i + 0, j + 0, k + 7, Block.dirt.blockID);
		world.setBlock(i + 0, j + 0, k + 8, Block.dirt.blockID);
		world.setBlock(i + 0, j + 0, k + 9, Block.dirt.blockID);
		world.setBlock(i + 0, j + 0, k + 10, Block.dirt.blockID);
		world.setBlock(i + 0, j + 0, k + 11, Block.dirt.blockID);
		world.setBlock(i + 0, j + 0, k + 12, Block.dirt.blockID);
		world.setBlock(i + 0, j + 0, k + 13, Block.dirt.blockID);
		world.setBlock(i + 0, j + 0, k + 14, Block.dirt.blockID);
		world.setBlock(i + 0, j + 0, k + 15, Block.dirt.blockID);
		world.setBlock(i + 0, j + 0, k + 16, Block.dirt.blockID);
		world.setBlock(i + 0, j + 1, k + 6, Block.stoneBrick.blockID);
		world.setBlock(i + 0, j + 1, k + 7, Block.stoneBrick.blockID);
		world.setBlock(i + 0, j + 1, k + 8, Block.stoneBrick.blockID);
		world.setBlock(i + 0, j + 1, k + 9, Block.stoneBrick.blockID);
		world.setBlock(i + 0, j + 1, k + 10, Block.stoneBrick.blockID);
		//world.setBlock(i + 0, j + 2, k + 7, -123);
		//world.setBlock(i + 0, j + 2, k + 8, -123);
		//world.setBlock(i + 0, j + 2, k + 9, -123);
		//world.setBlock(i + 0, j + 2, k + 10, -101, 2, 3);
		//world.setBlock(i + 0, j + 3, k + 6, -101, 2, 3);
		//world.setBlock(i + 0, j + 3, k + 10, -101, 2, 3);
		//world.setBlock(i + 0, j + 3, k + 7, -123);
		//world.setBlock(i + 0, j + 3, k + 8, -123);
		//world.setBlock(i + 0, j + 3, k + 9, -123);
		//world.setBlock(i + 0, j + 4, k + 8, -123);
		//world.setBlockAndMetadata(i + 0, j + 4, k + 6, -101, 2);
		//world.setBlockAndMetadata(i + 0, j + 4, k + 7, -100, 7);
		//world.setBlockAndMetadata(i + 0, j + 4, k + 9, -100, 6);
		//world.setBlockAndMetadata(i + 0, j + 4, k + 10, -101, 2);
		world.setBlock(i + 0, j + 5, k + 6, Block.stoneBrick.blockID);
		world.setBlock(i + 0, j + 5, k + 7, Blocks.blockLimestone.blockID, 1, 3);
		world.setBlock(i + 0, j + 5, k + 8, Blocks.blockLimestone.blockID, 1, 3);
		world.setBlock(i + 0, j + 5, k + 9, Blocks.blockLimestone.blockID, 1, 3);
		world.setBlock(i + 0, j + 5, k + 10, Block.stoneBrick.blockID);
		world.setBlock(i + 1, j + 0, k + 0, Block.dirt.blockID);
		world.setBlock(i + 1, j + 0, k + 1, Block.dirt.blockID);
		world.setBlock(i + 1, j + 0, k + 2, Block.dirt.blockID);
		world.setBlock(i + 1, j + 0, k + 3, Block.dirt.blockID);
		world.setBlock(i + 1, j + 0, k + 4, Block.dirt.blockID);
		world.setBlock(i + 1, j + 0, k + 5, Block.dirt.blockID);
		world.setBlock(i + 1, j + 0, k + 6, Block.dirt.blockID);
		world.setBlock(i + 1, j + 0, k + 7, Block.dirt.blockID);
		world.setBlock(i + 1, j + 0, k + 8, Block.dirt.blockID);
		world.setBlock(i + 1, j + 0, k + 9, Block.dirt.blockID);
		world.setBlock(i + 1, j + 0, k + 10, Block.dirt.blockID);
		world.setBlock(i + 1, j + 0, k + 11, Block.dirt.blockID);
		world.setBlock(i + 1, j + 0, k + 12, Block.dirt.blockID);
		world.setBlock(i + 1, j + 0, k + 13, Block.dirt.blockID);
		world.setBlock(i + 1, j + 0, k + 14, Block.dirt.blockID);
		world.setBlock(i + 1, j + 0, k + 15, Block.dirt.blockID);
		world.setBlock(i + 1, j + 0, k + 16, Block.dirt.blockID);
		world.setBlock(i + 1, j + 1, k + 4, Block.stoneBrick.blockID);
		world.setBlock(i + 1, j + 1, k + 5, Block.stoneBrick.blockID);
		world.setBlock(i + 1, j + 1, k + 11, Block.stoneBrick.blockID);
		world.setBlock(i + 1, j + 1, k + 12, Block.stoneBrick.blockID);
		world.setBlock(i + 1, j + 2, k + 4, Block.glass.blockID);
		world.setBlock(i + 1, j + 2, k + 5, Block.glass.blockID);
		world.setBlock(i + 1, j + 2, k + 11, Block.glass.blockID);
		world.setBlock(i + 1, j + 2, k + 12, Block.glass.blockID);
		world.setBlock(i + 1, j + 3, k + 4, Block.glass.blockID);
		world.setBlock(i + 1, j + 3, k + 5, Block.glass.blockID);
		world.setBlock(i + 1, j + 3, k + 11, Block.glass.blockID);
		world.setBlock(i + 1, j + 3, k + 12, Block.glass.blockID);
		world.setBlock(i + 1, j + 4, k + 6, Block.glass.blockID);
		world.setBlock(i + 1, j + 4, k + 10, Block.glass.blockID);
		world.setBlock(i + 1, j + 5, k + 7, Block.glass.blockID);
		world.setBlock(i + 1, j + 5, k + 8, Block.glass.blockID);
		world.setBlock(i + 1, j + 5, k + 9, Block.glass.blockID);
		world.setBlock(i + 2, j + 0, k + 0, Block.dirt.blockID);
		world.setBlock(i + 2, j + 0, k + 1, Block.dirt.blockID);
		world.setBlock(i + 2, j + 0, k + 2, Block.dirt.blockID);
		world.setBlock(i + 2, j + 0, k + 3, Block.dirt.blockID);
		world.setBlock(i + 2, j + 0, k + 4, Block.dirt.blockID);
		world.setBlock(i + 2, j + 0, k + 5, Block.dirt.blockID);
		world.setBlock(i + 2, j + 0, k + 6, Block.dirt.blockID);
		world.setBlock(i + 2, j + 0, k + 7, Block.dirt.blockID);
		world.setBlock(i + 2, j + 0, k + 8, Block.dirt.blockID);
		world.setBlock(i + 2, j + 0, k + 9, Block.dirt.blockID);
		world.setBlock(i + 2, j + 0, k + 10, Block.dirt.blockID);
		world.setBlock(i + 2, j + 0, k + 11, Block.dirt.blockID);
		world.setBlock(i + 2, j + 0, k + 12, Block.dirt.blockID);
		world.setBlock(i + 2, j + 0, k + 13, Block.dirt.blockID);
		world.setBlock(i + 2, j + 0, k + 14, Block.dirt.blockID);
		world.setBlock(i + 2, j + 0, k + 15, Block.dirt.blockID);
		world.setBlock(i + 2, j + 0, k + 16, Block.dirt.blockID);
		world.setBlock(i + 2, j + 1, k + 3, Block.stoneBrick.blockID);
		world.setBlock(i + 2, j + 1, k + 13, Block.stoneBrick.blockID);
		world.setBlock(i + 2, j + 2, k + 3, Block.glass.blockID);
		world.setBlock(i + 2, j + 2, k + 13, Block.glass.blockID);
		world.setBlock(i + 2, j + 3, k + 3, Block.glass.blockID);
		world.setBlock(i + 2, j + 3, k + 13, Block.glass.blockID);
		world.setBlock(i + 2, j + 4, k + 4, Block.glass.blockID);
		world.setBlock(i + 2, j + 4, k + 5, Block.glass.blockID);
		world.setBlock(i + 2, j + 4, k + 11, Block.glass.blockID);
		world.setBlock(i + 2, j + 4, k + 12, Block.glass.blockID);
		world.setBlock(i + 2, j + 5, k + 6, Block.glass.blockID);
		world.setBlock(i + 2, j + 5, k + 7, Block.glass.blockID);
		world.setBlock(i + 2, j + 5, k + 8, Block.glass.blockID);
		world.setBlock(i + 2, j + 5, k + 9, Block.glass.blockID);
		world.setBlock(i + 2, j + 5, k + 10, Block.glass.blockID);
		world.setBlock(i + 3, j + 0, k + 0, Block.dirt.blockID);
		world.setBlock(i + 3, j + 0, k + 1, Block.dirt.blockID);
		world.setBlock(i + 3, j + 0, k + 2, Block.dirt.blockID);
		world.setBlock(i + 3, j + 0, k + 3, Block.dirt.blockID);
		world.setBlock(i + 3, j + 0, k + 4, Block.dirt.blockID);
		world.setBlock(i + 3, j + 0, k + 5, Block.dirt.blockID);
		world.setBlock(i + 3, j + 0, k + 6, Block.dirt.blockID);
		world.setBlock(i + 3, j + 0, k + 7, Block.dirt.blockID);
		world.setBlock(i + 3, j + 0, k + 8, Block.dirt.blockID);
		world.setBlock(i + 3, j + 0, k + 9, Block.dirt.blockID);
		world.setBlock(i + 3, j + 0, k + 10, Block.dirt.blockID);
		world.setBlock(i + 3, j + 0, k + 11, Block.dirt.blockID);
		world.setBlock(i + 3, j + 0, k + 12, Block.dirt.blockID);
		world.setBlock(i + 3, j + 0, k + 13, Block.dirt.blockID);
		world.setBlock(i + 3, j + 0, k + 14, Block.dirt.blockID);
		world.setBlock(i + 3, j + 0, k + 15, Block.dirt.blockID);
		world.setBlock(i + 3, j + 0, k + 16, Block.dirt.blockID);
		world.setBlock(i + 3, j + 1, k + 2, Block.stoneBrick.blockID);
		world.setBlock(i + 3, j + 1, k + 8, Blocks.blockDepulsor.blockID);
		world.setBlock(i + 3, j + 1, k + 14, Block.stoneBrick.blockID);
		world.setBlock(i + 3, j + 2, k + 2, Block.glass.blockID);
		world.setBlock(i + 3, j + 2, k + 14, Block.glass.blockID);
		world.setBlock(i + 3, j + 3, k + 2, Block.glass.blockID);
		world.setBlock(i + 3, j + 3, k + 14, Block.glass.blockID);
		world.setBlock(i + 3, j + 4, k + 3, Block.glass.blockID);
		world.setBlock(i + 3, j + 4, k + 13, Block.glass.blockID);
		world.setBlock(i + 3, j + 5, k + 4, Block.glass.blockID);
		world.setBlock(i + 3, j + 5, k + 5, Block.glass.blockID);
		world.setBlock(i + 3, j + 5, k + 11, Block.glass.blockID);
		world.setBlock(i + 3, j + 5, k + 12, Block.glass.blockID);
		world.setBlock(i + 3, j + 6, k + 6, Block.glass.blockID);
		world.setBlock(i + 3, j + 6, k + 7, Block.glass.blockID);
		world.setBlock(i + 3, j + 6, k + 8, Block.glass.blockID);
		world.setBlock(i + 3, j + 6, k + 9, Block.glass.blockID);
		world.setBlock(i + 3, j + 6, k + 10, Block.glass.blockID);
		world.setBlock(i + 4, j + 0, k + 0, Block.dirt.blockID);
		world.setBlock(i + 4, j + 0, k + 1, Block.dirt.blockID);
		world.setBlock(i + 4, j + 0, k + 2, Block.dirt.blockID);
		world.setBlock(i + 4, j + 0, k + 3, Block.dirt.blockID);
		world.setBlock(i + 4, j + 0, k + 4, Block.dirt.blockID);
		world.setBlock(i + 4, j + 0, k + 5, Block.dirt.blockID);
		world.setBlock(i + 4, j + 0, k + 6, Block.dirt.blockID);
		world.setBlock(i + 4, j + 0, k + 7, Block.dirt.blockID);
		world.setBlock(i + 4, j + 0, k + 8, Block.dirt.blockID);
		world.setBlock(i + 4, j + 0, k + 9, Block.dirt.blockID);
		world.setBlock(i + 4, j + 0, k + 10, Block.dirt.blockID);
		world.setBlock(i + 4, j + 0, k + 11, Block.dirt.blockID);
		world.setBlock(i + 4, j + 0, k + 12, Block.dirt.blockID);
		world.setBlock(i + 4, j + 0, k + 13, Block.dirt.blockID);
		world.setBlock(i + 4, j + 0, k + 14, Block.dirt.blockID);
		world.setBlock(i + 4, j + 0, k + 15, Block.dirt.blockID);
		world.setBlock(i + 4, j + 0, k + 16, Block.dirt.blockID);
		world.setBlock(i + 4, j + 1, k + 1, Block.stoneBrick.blockID);
		world.setBlock(i + 4, j + 1, k + 7, Block.stoneBrick.blockID);
		world.setBlock(i + 4, j + 1, k + 8, Block.stoneBrick.blockID);
		world.setBlock(i + 4, j + 1, k + 9, Block.stoneBrick.blockID);
		world.setBlock(i + 4, j + 1, k + 15, Block.stoneBrick.blockID);
		world.setBlock(i + 4, j + 2, k + 1, Block.glass.blockID);
		world.setBlock(i + 4, j + 2, k + 15, Block.glass.blockID);
		world.setBlock(i + 4, j + 3, k + 1, Block.glass.blockID);
		world.setBlock(i + 4, j + 3, k + 15, Block.glass.blockID);
		world.setBlock(i + 4, j + 4, k + 2, Block.glass.blockID);
		world.setBlock(i + 4, j + 4, k + 14, Block.glass.blockID);
		world.setBlock(i + 4, j + 5, k + 3, Block.glass.blockID);
		world.setBlock(i + 4, j + 5, k + 13, Block.glass.blockID);
		world.setBlock(i + 4, j + 6, k + 4, Block.glass.blockID);
		world.setBlock(i + 4, j + 6, k + 5, Block.glass.blockID);
		world.setBlock(i + 4, j + 6, k + 6, Block.glass.blockID);
		world.setBlock(i + 4, j + 6, k + 7, Block.glass.blockID);
		world.setBlock(i + 4, j + 6, k + 8, Block.glass.blockID);
		world.setBlock(i + 4, j + 6, k + 9, Block.glass.blockID);
		world.setBlock(i + 4, j + 6, k + 10, Block.glass.blockID);
		world.setBlock(i + 4, j + 6, k + 11, Block.glass.blockID);
		world.setBlock(i + 4, j + 6, k + 12, Block.glass.blockID);
		world.setBlock(i + 5, j + 0, k + 0, Block.dirt.blockID);
		world.setBlock(i + 5, j + 0, k + 1, Block.dirt.blockID);
		world.setBlock(i + 5, j + 0, k + 2, Block.dirt.blockID);
		world.setBlock(i + 5, j + 0, k + 3, Block.dirt.blockID);
		world.setBlock(i + 5, j + 0, k + 4, Block.dirt.blockID);
		world.setBlock(i + 5, j + 0, k + 5, Block.dirt.blockID);
		world.setBlock(i + 5, j + 0, k + 6, Block.dirt.blockID);
		world.setBlock(i + 5, j + 0, k + 7, Block.dirt.blockID);
		world.setBlock(i + 5, j + 0, k + 8, Block.dirt.blockID);
		world.setBlock(i + 5, j + 0, k + 9, Block.dirt.blockID);
		world.setBlock(i + 5, j + 0, k + 10, Block.dirt.blockID);
		world.setBlock(i + 5, j + 0, k + 11, Block.dirt.blockID);
		world.setBlock(i + 5, j + 0, k + 12, Block.dirt.blockID);
		world.setBlock(i + 5, j + 0, k + 13, Block.dirt.blockID);
		world.setBlock(i + 5, j + 0, k + 14, Block.dirt.blockID);
		world.setBlock(i + 5, j + 0, k + 15, Block.dirt.blockID);
		world.setBlock(i + 5, j + 0, k + 16, Block.dirt.blockID);
		world.setBlock(i + 5, j + 1, k + 1, Block.stoneBrick.blockID);
		world.setBlock(i + 5, j + 1, k + 6, Block.stoneBrick.blockID);
		world.setBlock(i + 5, j + 1, k + 7, Blocks.blockLimestone.blockID, 1, 3);
		world.setBlock(i + 5, j + 1, k + 8, Blocks.blockLimestone.blockID, 1, 3);
		world.setBlock(i + 5, j + 1, k + 9, Blocks.blockLimestone.blockID, 1, 3);
		world.setBlock(i + 5, j + 1, k + 10, Block.stoneBrick.blockID);
		world.setBlock(i + 5, j + 1, k + 15, Block.stoneBrick.blockID);
		world.setBlock(i + 5, j + 2, k + 1, Block.glass.blockID);
		world.setBlock(i + 5, j + 2, k + 15, Block.glass.blockID);
		world.setBlock(i + 5, j + 3, k + 1, Block.glass.blockID);
		world.setBlock(i + 5, j + 3, k + 15, Block.glass.blockID);
		world.setBlock(i + 5, j + 4, k + 2, Block.glass.blockID);
		world.setBlock(i + 5, j + 4, k + 14, Block.glass.blockID);
		world.setBlock(i + 5, j + 5, k + 3, Block.glass.blockID);
		world.setBlock(i + 5, j + 5, k + 13, Block.glass.blockID);
		world.setBlock(i + 5, j + 6, k + 4, Block.glass.blockID);
		world.setBlock(i + 5, j + 6, k + 5, Block.glass.blockID);
		world.setBlock(i + 5, j + 6, k + 11, Block.glass.blockID);
		world.setBlock(i + 5, j + 6, k + 12, Block.glass.blockID);
		world.setBlock(i + 5, j + 7, k + 6, Block.glass.blockID);
		world.setBlock(i + 5, j + 7, k + 7, Block.glass.blockID);
		world.setBlock(i + 5, j + 7, k + 8, Block.glass.blockID);
		world.setBlock(i + 5, j + 7, k + 9, Block.glass.blockID);
		world.setBlock(i + 5, j + 7, k + 10, Block.glass.blockID);
		world.setBlock(i + 6, j + 0, k + 0, Block.dirt.blockID);
		world.setBlock(i + 6, j + 0, k + 1, Block.dirt.blockID);
		world.setBlock(i + 6, j + 0, k + 2, Block.dirt.blockID);
		world.setBlock(i + 6, j + 0, k + 3, Block.dirt.blockID);
		world.setBlock(i + 6, j + 0, k + 4, Block.dirt.blockID);
		world.setBlock(i + 6, j + 0, k + 5, Block.dirt.blockID);
		world.setBlock(i + 6, j + 0, k + 6, Block.dirt.blockID);
		world.setBlock(i + 6, j + 0, k + 7, Block.dirt.blockID);
		world.setBlock(i + 6, j + 0, k + 8, Block.dirt.blockID);
		world.setBlock(i + 6, j + 0, k + 9, Block.dirt.blockID);
		world.setBlock(i + 6, j + 0, k + 10, Block.dirt.blockID);
		world.setBlock(i + 6, j + 0, k + 11, Block.dirt.blockID);
		world.setBlock(i + 6, j + 0, k + 12, Block.dirt.blockID);
		world.setBlock(i + 6, j + 0, k + 13, Block.dirt.blockID);
		world.setBlock(i + 6, j + 0, k + 14, Block.dirt.blockID);
		world.setBlock(i + 6, j + 0, k + 15, Block.dirt.blockID);
		world.setBlock(i + 6, j + 0, k + 16, Block.dirt.blockID);
		world.setBlock(i + 6, j + 1, k + 0, Block.stoneBrick.blockID);
		world.setBlock(i + 6, j + 1, k + 5, Block.stoneBrick.blockID);
		world.setBlock(i + 6, j + 1, k + 6, Blocks.blockLimestone.blockID, 1, 3);
		world.setBlock(i + 6, j + 1, k + 7, Blocks.blockLimestone.blockID, 1, 3);
		world.setBlock(i + 6, j + 1, k + 8, Blocks.blockLimestone.blockID, 1, 3);
		world.setBlock(i + 6, j + 1, k + 9, Blocks.blockLimestone.blockID, 1, 3);
		world.setBlock(i + 6, j + 1, k + 10, Blocks.blockLimestone.blockID, 1, 3);
		world.setBlock(i + 6, j + 1, k + 11, Block.stoneBrick.blockID);
		world.setBlock(i + 6, j + 1, k + 16, Block.stoneBrick.blockID);
		world.setBlock(i + 6, j + 2, k + 0, Block.glass.blockID);
		world.setBlock(i + 6, j + 2, k + 16, Block.glass.blockID);
		world.setBlock(i + 6, j + 3, k + 0, Block.glass.blockID);
		world.setBlock(i + 6, j + 3, k + 16, Block.glass.blockID);
		world.setBlock(i + 6, j + 4, k + 1, Block.glass.blockID);
		world.setBlock(i + 6, j + 4, k + 15, Block.glass.blockID);
		world.setBlock(i + 6, j + 5, k + 2, Block.glass.blockID);
		world.setBlock(i + 6, j + 5, k + 14, Block.glass.blockID);
		world.setBlock(i + 6, j + 6, k + 3, Block.glass.blockID);
		world.setBlock(i + 6, j + 6, k + 4, Block.glass.blockID);
		world.setBlock(i + 6, j + 6, k + 12, Block.glass.blockID);
		world.setBlock(i + 6, j + 6, k + 13, Block.glass.blockID);
		world.setBlock(i + 6, j + 7, k + 5, Block.glass.blockID);
		world.setBlock(i + 6, j + 7, k + 6, Block.glass.blockID);
		world.setBlock(i + 6, j + 7, k + 7, Block.glass.blockID);
		world.setBlock(i + 6, j + 7, k + 8, Block.glass.blockID);
		world.setBlock(i + 6, j + 7, k + 9, Block.glass.blockID);
		world.setBlock(i + 6, j + 7, k + 10, Block.glass.blockID);
		world.setBlock(i + 6, j + 7, k + 11, Block.glass.blockID);
		world.setBlock(i + 7, j + 0, k + 0, Block.dirt.blockID);
		world.setBlock(i + 7, j + 0, k + 1, Block.dirt.blockID);
		world.setBlock(i + 7, j + 0, k + 2, Block.dirt.blockID);
		world.setBlock(i + 7, j + 0, k + 3, Block.dirt.blockID);
		world.setBlock(i + 7, j + 0, k + 4, Block.dirt.blockID);
		world.setBlock(i + 7, j + 0, k + 5, Block.dirt.blockID);
		world.setBlock(i + 7, j + 0, k + 6, Block.dirt.blockID);
		world.setBlock(i + 7, j + 0, k + 7, Block.stoneBrick.blockID);
		world.setBlock(i + 7, j + 0, k + 8, Block.stoneBrick.blockID);
		world.setBlock(i + 7, j + 0, k + 9, Block.stoneBrick.blockID);
		world.setBlock(i + 7, j + 0, k + 10, Blocks.blockLimestone.blockID, 1, 3);
		world.setBlock(i + 7, j + 0, k + 11, Block.dirt.blockID);
		world.setBlock(i + 7, j + 0, k + 12, Block.dirt.blockID);
		world.setBlock(i + 7, j + 0, k + 13, Block.dirt.blockID);
		world.setBlock(i + 7, j + 0, k + 14, Block.dirt.blockID);
		world.setBlock(i + 7, j + 0, k + 15, Block.dirt.blockID);
		world.setBlock(i + 7, j + 0, k + 16, Block.dirt.blockID);
		world.setBlock(i + 7, j + 1, k + 0, Block.stoneBrick.blockID);
		world.setBlock(i + 7, j + 1, k + 4, Block.stoneBrick.blockID);
		world.setBlock(i + 7, j + 1, k + 5, Blocks.blockLimestone.blockID, 1, 3);
		world.setBlock(i + 7, j + 1, k + 6, Blocks.blockLimestone.blockID, 1, 3);
		world.setBlock(i + 7, j + 1, k + 10, Blocks.blockLimestone.blockID, 1, 3);
		world.setBlock(i + 7, j + 1, k + 11, Blocks.blockLimestone.blockID, 1, 3);
		world.setBlock(i + 7, j + 1, k + 12, Block.stoneBrick.blockID);
		world.setBlock(i + 7, j + 1, k + 16, Block.stoneBrick.blockID);
		world.setBlock(i + 7, j + 2, k + 0, Block.glass.blockID);
		world.setBlock(i + 7, j + 2, k + 16, Block.glass.blockID);
		world.setBlock(i + 7, j + 3, k + 0, Block.glass.blockID);
		world.setBlock(i + 7, j + 3, k + 16, Block.glass.blockID);
		world.setBlock(i + 7, j + 4, k + 1, Block.glass.blockID);
		world.setBlock(i + 7, j + 4, k + 15, Block.glass.blockID);
		world.setBlock(i + 7, j + 5, k + 2, Block.glass.blockID);
		world.setBlock(i + 7, j + 5, k + 14, Block.glass.blockID);
		world.setBlock(i + 7, j + 6, k + 3, Block.glass.blockID);
		world.setBlock(i + 7, j + 6, k + 4, Block.glass.blockID);
		world.setBlock(i + 7, j + 6, k + 12, Block.glass.blockID);
		world.setBlock(i + 7, j + 6, k + 13, Block.glass.blockID);
		world.setBlock(i + 7, j + 7, k + 5, Block.glass.blockID);
		world.setBlock(i + 7, j + 7, k + 6, Block.glass.blockID);
		world.setBlock(i + 7, j + 7, k + 7, Block.glass.blockID);
		world.setBlock(i + 7, j + 7, k + 8, Block.glass.blockID);
		world.setBlock(i + 7, j + 7, k + 9, Block.glass.blockID);
		world.setBlock(i + 7, j + 7, k + 10, Block.glass.blockID);
		world.setBlock(i + 7, j + 7, k + 11, Block.glass.blockID);
		world.setBlock(i + 8, j + 0, k + 0, Block.dirt.blockID);
		world.setBlock(i + 8, j + 0, k + 1, Block.dirt.blockID);
		world.setBlock(i + 8, j + 0, k + 2, Block.dirt.blockID);
		world.setBlock(i + 8, j + 0, k + 3, Block.dirt.blockID);
		world.setBlock(i + 8, j + 0, k + 4, Block.dirt.blockID);
		world.setBlock(i + 8, j + 0, k + 5, Block.dirt.blockID);
		world.setBlock(i + 8, j + 0, k + 6, Block.dirt.blockID);
		world.setBlock(i + 8, j + 0, k + 7, Block.stoneBrick.blockID);
		world.setBlock(i + 8, j + 0, k + 8, Block.dirt.blockID);
		world.setBlock(i + 8, j + 0, k + 9, Block.stoneBrick.blockID);
		world.setBlock(i + 8, j + 0, k + 10, Block.dirt.blockID);
		world.setBlock(i + 8, j + 0, k + 11, Block.dirt.blockID);
		world.setBlock(i + 8, j + 0, k + 12, Block.dirt.blockID);
		world.setBlock(i + 8, j + 0, k + 13, Block.dirt.blockID);
		world.setBlock(i + 8, j + 0, k + 14, Block.dirt.blockID);
		world.setBlock(i + 8, j + 0, k + 15, Block.dirt.blockID);
		world.setBlock(i + 8, j + 0, k + 16, Block.dirt.blockID);
		world.setBlock(i + 8, j + 1, k + 0, Block.stoneBrick.blockID);
		world.setBlock(i + 8, j + 1, k + 4, Block.stoneBrick.blockID);
		world.setBlock(i + 8, j + 1, k + 5, Blocks.blockLimestone.blockID, 1, 3);
		world.setBlock(i + 8, j + 1, k + 6, Blocks.blockLimestone.blockID, 1, 3);
		world.setBlock(i + 8, j + 1, k + 8, Blocks.blockLimestone.blockID, 1, 3);
		world.setBlock(i + 8, j + 1, k + 10, Blocks.blockLimestone.blockID, 1, 3);
		world.setBlock(i + 8, j + 1, k + 11, Blocks.blockLimestone.blockID, 1, 3);
		world.setBlock(i + 8, j + 1, k + 12, Block.stoneBrick.blockID);
		world.setBlock(i + 8, j + 1, k + 16, Block.stoneBrick.blockID);
		world.setBlock(i + 8, j + 2, k + 0, Block.glass.blockID);
		world.setBlock(i + 8, j + 2, k + 8, Blocks.blockLimestone.blockID, 1, 3);
		world.setBlock(i + 8, j + 2, k + 16, Block.glass.blockID);
		world.setBlock(i + 8, j + 3, k + 0, Block.glass.blockID);
		world.setBlock(i + 8, j + 3, k + 8, Blocks.blockLimestone.blockID, 1, 3);
		world.setBlock(i + 8, j + 3, k + 16, Block.glass.blockID);
		world.setBlock(i + 8, j + 4, k + 1, Block.glass.blockID);
		world.setBlock(i + 8, j + 4, k + 8, Blocks.blockChestSpawner.blockID);
		world.setBlockMetadataWithNotify(i + 8, j + 4, k + 8, 4, 3);
		world.setBlock(i + 8, j + 4, k + 15, Block.glass.blockID);
		world.setBlock(i + 8, j + 5, k + 2, Block.glass.blockID);
		world.setBlock(i + 8, j + 5, k + 14, Block.glass.blockID);
		world.setBlock(i + 8, j + 6, k + 3, Block.glass.blockID);
		world.setBlock(i + 8, j + 6, k + 4, Block.glass.blockID);
		world.setBlock(i + 8, j + 6, k + 12, Block.glass.blockID);
		world.setBlock(i + 8, j + 6, k + 13, Block.glass.blockID);
		world.setBlock(i + 8, j + 7, k + 5, Block.glass.blockID);
		world.setBlock(i + 8, j + 7, k + 6, Block.glass.blockID);
		world.setBlock(i + 8, j + 7, k + 7, Block.glass.blockID);
		world.setBlock(i + 8, j + 7, k + 8, Block.glass.blockID);
		world.setBlock(i + 8, j + 7, k + 9, Block.glass.blockID);
		world.setBlock(i + 8, j + 7, k + 10, Block.glass.blockID);
		world.setBlock(i + 8, j + 7, k + 11, Block.glass.blockID);
		world.setBlock(i + 9, j + 0, k + 0, Block.dirt.blockID);
		world.setBlock(i + 9, j + 0, k + 1, Block.dirt.blockID);
		world.setBlock(i + 9, j + 0, k + 2, Block.dirt.blockID);
		world.setBlock(i + 9, j + 0, k + 3, Block.dirt.blockID);
		world.setBlock(i + 9, j + 0, k + 4, Block.dirt.blockID);
		world.setBlock(i + 9, j + 0, k + 5, Block.dirt.blockID);
		world.setBlock(i + 9, j + 0, k + 6, Block.dirt.blockID);
		world.setBlock(i + 9, j + 0, k + 7, Block.stoneBrick.blockID);
		world.setBlock(i + 9, j + 0, k + 8, Block.stoneBrick.blockID);
		world.setBlock(i + 9, j + 0, k + 9, Block.stoneBrick.blockID);
		world.setBlock(i + 9, j + 0, k + 10, Block.dirt.blockID);
		world.setBlock(i + 9, j + 0, k + 11, Block.dirt.blockID);
		world.setBlock(i + 9, j + 0, k + 12, Block.dirt.blockID);
		world.setBlock(i + 9, j + 0, k + 13, Block.dirt.blockID);
		world.setBlock(i + 9, j + 0, k + 14, Block.dirt.blockID);
		world.setBlock(i + 9, j + 0, k + 15, Block.dirt.blockID);
		world.setBlock(i + 9, j + 0, k + 16, Block.dirt.blockID);
		world.setBlock(i + 9, j + 1, k + 0, Block.stoneBrick.blockID);
		world.setBlock(i + 9, j + 1, k + 4, Block.stoneBrick.blockID);
		world.setBlock(i + 9, j + 1, k + 5, Blocks.blockLimestone.blockID, 1, 3);
		world.setBlock(i + 9, j + 1, k + 6, Blocks.blockLimestone.blockID, 1, 3);
		world.setBlock(i + 9, j + 1, k + 10, Blocks.blockLimestone.blockID, 1, 3);
		world.setBlock(i + 9, j + 1, k + 11, Blocks.blockLimestone.blockID, 1, 3);
		world.setBlock(i + 9, j + 1, k + 12, Block.stoneBrick.blockID);
		world.setBlock(i + 9, j + 1, k + 16, Block.stoneBrick.blockID);
		world.setBlock(i + 9, j + 2, k + 0, Block.glass.blockID);
		world.setBlock(i + 9, j + 2, k + 16, Block.glass.blockID);
		world.setBlock(i + 9, j + 3, k + 0, Block.glass.blockID);
		world.setBlock(i + 9, j + 3, k + 16, Block.glass.blockID);
		world.setBlock(i + 9, j + 4, k + 1, Block.glass.blockID);
		world.setBlock(i + 9, j + 4, k + 15, Block.glass.blockID);
		world.setBlock(i + 9, j + 5, k + 2, Block.glass.blockID);
		world.setBlock(i + 9, j + 5, k + 14, Block.glass.blockID);
		world.setBlock(i + 9, j + 6, k + 3, Block.glass.blockID);
		world.setBlock(i + 9, j + 6, k + 4, Block.glass.blockID);
		world.setBlock(i + 9, j + 6, k + 12, Block.glass.blockID);
		world.setBlock(i + 9, j + 6, k + 13, Block.glass.blockID);
		world.setBlock(i + 9, j + 7, k + 5, Block.glass.blockID);
		world.setBlock(i + 9, j + 7, k + 6, Block.glass.blockID);
		world.setBlock(i + 9, j + 7, k + 7, Block.glass.blockID);
		world.setBlock(i + 9, j + 7, k + 8, Block.glass.blockID);
		world.setBlock(i + 9, j + 7, k + 9, Block.glass.blockID);
		world.setBlock(i + 9, j + 7, k + 10, Block.glass.blockID);
		world.setBlock(i + 9, j + 7, k + 11, Block.glass.blockID);
		world.setBlock(i + 10, j + 0, k + 0, Block.dirt.blockID);
		world.setBlock(i + 10, j + 0, k + 1, Block.dirt.blockID);
		world.setBlock(i + 10, j + 0, k + 2, Block.dirt.blockID);
		world.setBlock(i + 10, j + 0, k + 3, Block.dirt.blockID);
		world.setBlock(i + 10, j + 0, k + 4, Block.dirt.blockID);
		world.setBlock(i + 10, j + 0, k + 5, Block.dirt.blockID);
		world.setBlock(i + 10, j + 0, k + 6, Block.dirt.blockID);
		world.setBlock(i + 10, j + 0, k + 7, Block.dirt.blockID);
		world.setBlock(i + 10, j + 0, k + 8, Block.dirt.blockID);
		world.setBlock(i + 10, j + 0, k + 9, Block.dirt.blockID);
		world.setBlock(i + 10, j + 0, k + 10, Block.dirt.blockID);
		world.setBlock(i + 10, j + 0, k + 11, Block.dirt.blockID);
		world.setBlock(i + 10, j + 0, k + 12, Block.dirt.blockID);
		world.setBlock(i + 10, j + 0, k + 13, Block.dirt.blockID);
		world.setBlock(i + 10, j + 0, k + 14, Block.dirt.blockID);
		world.setBlock(i + 10, j + 0, k + 15, Block.dirt.blockID);
		world.setBlock(i + 10, j + 0, k + 16, Block.dirt.blockID);
		world.setBlock(i + 10, j + 1, k + 0, Block.stoneBrick.blockID);
		world.setBlock(i + 10, j + 1, k + 5, Block.stoneBrick.blockID);
		world.setBlock(i + 10, j + 1, k + 6, Blocks.blockLimestone.blockID, 1, 3);
		world.setBlock(i + 10, j + 1, k + 7, Blocks.blockLimestone.blockID, 1, 3);
		world.setBlock(i + 10, j + 1, k + 8, Blocks.blockLimestone.blockID, 1, 3);
		world.setBlock(i + 10, j + 1, k + 9, Blocks.blockLimestone.blockID, 1, 3);
		world.setBlock(i + 10, j + 1, k + 10, Blocks.blockLimestone.blockID, 1, 3);
		world.setBlock(i + 10, j + 1, k + 11, Block.stoneBrick.blockID);
		world.setBlock(i + 10, j + 1, k + 16, Block.stoneBrick.blockID);
		world.setBlock(i + 10, j + 2, k + 0, Block.glass.blockID);
		world.setBlock(i + 10, j + 2, k + 16, Block.glass.blockID);
		world.setBlock(i + 10, j + 3, k + 0, Block.glass.blockID);
		world.setBlock(i + 10, j + 3, k + 16, Block.glass.blockID);
		world.setBlock(i + 10, j + 4, k + 1, Block.glass.blockID);
		world.setBlock(i + 10, j + 4, k + 15, Block.glass.blockID);
		world.setBlock(i + 10, j + 5, k + 2, Block.glass.blockID);
		world.setBlock(i + 10, j + 5, k + 14, Block.glass.blockID);
		world.setBlock(i + 10, j + 6, k + 3, Block.glass.blockID);
		world.setBlock(i + 10, j + 6, k + 4, Block.glass.blockID);
		world.setBlock(i + 10, j + 6, k + 12, Block.glass.blockID);
		world.setBlock(i + 10, j + 6, k + 13, Block.glass.blockID);
		world.setBlock(i + 10, j + 7, k + 5, Block.glass.blockID);
		world.setBlock(i + 10, j + 7, k + 6, Block.glass.blockID);
		world.setBlock(i + 10, j + 7, k + 7, Block.glass.blockID);
		world.setBlock(i + 10, j + 7, k + 8, Block.glass.blockID);
		world.setBlock(i + 10, j + 7, k + 9, Block.glass.blockID);
		world.setBlock(i + 10, j + 7, k + 10, Block.glass.blockID);
		world.setBlock(i + 10, j + 7, k + 11, Block.glass.blockID);
		world.setBlock(i + 11, j + 0, k + 0, Block.dirt.blockID);
		world.setBlock(i + 11, j + 0, k + 1, Block.dirt.blockID);
		world.setBlock(i + 11, j + 0, k + 2, Block.dirt.blockID);
		world.setBlock(i + 11, j + 0, k + 3, Block.dirt.blockID);
		world.setBlock(i + 11, j + 0, k + 4, Block.dirt.blockID);
		world.setBlock(i + 11, j + 0, k + 5, Block.dirt.blockID);
		world.setBlock(i + 11, j + 0, k + 6, Block.dirt.blockID);
		world.setBlock(i + 11, j + 0, k + 7, Block.dirt.blockID);
		world.setBlock(i + 11, j + 0, k + 8, Block.dirt.blockID);
		world.setBlock(i + 11, j + 0, k + 9, Block.dirt.blockID);
		world.setBlock(i + 11, j + 0, k + 10, Block.dirt.blockID);
		world.setBlock(i + 11, j + 0, k + 11, Block.dirt.blockID);
		world.setBlock(i + 11, j + 0, k + 12, Block.dirt.blockID);
		world.setBlock(i + 11, j + 0, k + 13, Block.dirt.blockID);
		world.setBlock(i + 11, j + 0, k + 14, Block.dirt.blockID);
		world.setBlock(i + 11, j + 0, k + 15, Block.dirt.blockID);
		world.setBlock(i + 11, j + 0, k + 16, Block.dirt.blockID);
		world.setBlock(i + 11, j + 1, k + 1, Block.stoneBrick.blockID);
		world.setBlock(i + 11, j + 1, k + 6, Block.stoneBrick.blockID);
		world.setBlock(i + 11, j + 1, k + 7, Blocks.blockLimestone.blockID, 1, 3);
		world.setBlock(i + 11, j + 1, k + 8, Blocks.blockLimestone.blockID, 1, 3);
		world.setBlock(i + 11, j + 1, k + 9, Blocks.blockLimestone.blockID, 1, 3);
		world.setBlock(i + 11, j + 1, k + 10, Block.stoneBrick.blockID);
		world.setBlock(i + 11, j + 1, k + 15, Block.stoneBrick.blockID);
		world.setBlock(i + 11, j + 2, k + 1, Block.glass.blockID);
		world.setBlock(i + 11, j + 2, k + 15, Block.glass.blockID);
		world.setBlock(i + 11, j + 3, k + 1, Block.glass.blockID);
		world.setBlock(i + 11, j + 3, k + 15, Block.glass.blockID);
		world.setBlock(i + 11, j + 4, k + 2, Block.glass.blockID);
		world.setBlock(i + 11, j + 4, k + 14, Block.glass.blockID);
		world.setBlock(i + 11, j + 5, k + 3, Block.glass.blockID);
		world.setBlock(i + 11, j + 5, k + 13, Block.glass.blockID);
		world.setBlock(i + 11, j + 6, k + 4, Block.glass.blockID);
		world.setBlock(i + 11, j + 6, k + 5, Block.glass.blockID);
		world.setBlock(i + 11, j + 6, k + 11, Block.glass.blockID);
		world.setBlock(i + 11, j + 6, k + 12, Block.glass.blockID);
		world.setBlock(i + 11, j + 7, k + 6, Block.glass.blockID);
		world.setBlock(i + 11, j + 7, k + 7, Block.glass.blockID);
		world.setBlock(i + 11, j + 7, k + 8, Block.glass.blockID);
		world.setBlock(i + 11, j + 7, k + 9, Block.glass.blockID);
		world.setBlock(i + 11, j + 7, k + 10, Block.glass.blockID);
		world.setBlock(i + 12, j + 0, k + 0, Block.dirt.blockID);
		world.setBlock(i + 12, j + 0, k + 1, Block.dirt.blockID);
		world.setBlock(i + 12, j + 0, k + 2, Block.dirt.blockID);
		world.setBlock(i + 12, j + 0, k + 3, Block.dirt.blockID);
		world.setBlock(i + 12, j + 0, k + 4, Block.dirt.blockID);
		world.setBlock(i + 12, j + 0, k + 5, Block.dirt.blockID);
		world.setBlock(i + 12, j + 0, k + 6, Block.dirt.blockID);
		world.setBlock(i + 12, j + 0, k + 7, Block.dirt.blockID);
		world.setBlock(i + 12, j + 0, k + 8, Block.dirt.blockID);
		world.setBlock(i + 12, j + 0, k + 9, Block.dirt.blockID);
		world.setBlock(i + 12, j + 0, k + 10, Block.dirt.blockID);
		world.setBlock(i + 12, j + 0, k + 11, Block.dirt.blockID);
		world.setBlock(i + 12, j + 0, k + 12, Block.dirt.blockID);
		world.setBlock(i + 12, j + 0, k + 13, Block.dirt.blockID);
		world.setBlock(i + 12, j + 0, k + 14, Block.dirt.blockID);
		world.setBlock(i + 12, j + 0, k + 15, Block.dirt.blockID);
		world.setBlock(i + 12, j + 0, k + 16, Block.dirt.blockID);
		world.setBlock(i + 12, j + 1, k + 1, Block.stoneBrick.blockID);
		world.setBlock(i + 12, j + 1, k + 7, Block.stoneBrick.blockID);
		world.setBlock(i + 12, j + 1, k + 8, Block.stoneBrick.blockID);
		world.setBlock(i + 12, j + 1, k + 9, Block.stoneBrick.blockID);
		world.setBlock(i + 12, j + 1, k + 15, Block.stoneBrick.blockID);
		world.setBlock(i + 12, j + 2, k + 1, Block.glass.blockID);
		world.setBlock(i + 12, j + 2, k + 15, Block.glass.blockID);
		world.setBlock(i + 12, j + 3, k + 1, Block.glass.blockID);
		world.setBlock(i + 12, j + 3, k + 15, Block.glass.blockID);
		world.setBlock(i + 12, j + 4, k + 2, Block.glass.blockID);
		world.setBlock(i + 12, j + 4, k + 14, Block.glass.blockID);
		world.setBlock(i + 12, j + 5, k + 3, Block.glass.blockID);
		world.setBlock(i + 12, j + 5, k + 13, Block.glass.blockID);
		world.setBlock(i + 12, j + 6, k + 4, Block.glass.blockID);
		world.setBlock(i + 12, j + 6, k + 5, Block.glass.blockID);
		world.setBlock(i + 12, j + 6, k + 6, Block.glass.blockID);
		world.setBlock(i + 12, j + 6, k + 7, Block.glass.blockID);
		world.setBlock(i + 12, j + 6, k + 8, Block.glass.blockID);
		world.setBlock(i + 12, j + 6, k + 9, Block.glass.blockID);
		world.setBlock(i + 12, j + 6, k + 10, Block.glass.blockID);
		world.setBlock(i + 12, j + 6, k + 11, Block.glass.blockID);
		world.setBlock(i + 12, j + 6, k + 12, Block.glass.blockID);
		world.setBlock(i + 13, j + 0, k + 0, Block.dirt.blockID);
		world.setBlock(i + 13, j + 0, k + 1, Block.dirt.blockID);
		world.setBlock(i + 13, j + 0, k + 2, Block.dirt.blockID);
		world.setBlock(i + 13, j + 0, k + 3, Block.dirt.blockID);
		world.setBlock(i + 13, j + 0, k + 4, Block.dirt.blockID);
		world.setBlock(i + 13, j + 0, k + 5, Block.dirt.blockID);
		world.setBlock(i + 13, j + 0, k + 6, Block.dirt.blockID);
		world.setBlock(i + 13, j + 0, k + 7, Block.dirt.blockID);
		world.setBlock(i + 13, j + 0, k + 8, Block.dirt.blockID);
		world.setBlock(i + 13, j + 0, k + 9, Block.dirt.blockID);
		world.setBlock(i + 13, j + 0, k + 10, Block.dirt.blockID);
		world.setBlock(i + 13, j + 0, k + 11, Block.dirt.blockID);
		world.setBlock(i + 13, j + 0, k + 12, Block.dirt.blockID);
		world.setBlock(i + 13, j + 0, k + 13, Block.dirt.blockID);
		world.setBlock(i + 13, j + 0, k + 14, Block.dirt.blockID);
		world.setBlock(i + 13, j + 0, k + 15, Block.dirt.blockID);
		world.setBlock(i + 13, j + 0, k + 16, Block.dirt.blockID);
		world.setBlock(i + 13, j + 1, k + 2, Block.stoneBrick.blockID);
		world.setBlock(i + 13, j + 1, k + 14, Block.stoneBrick.blockID);
		world.setBlock(i + 13, j + 2, k + 2, Block.glass.blockID);
		world.setBlock(i + 13, j + 2, k + 14, Block.glass.blockID);
		world.setBlock(i + 13, j + 3, k + 2, Block.glass.blockID);
		world.setBlock(i + 13, j + 3, k + 14, Block.glass.blockID);
		world.setBlock(i + 13, j + 4, k + 3, Block.glass.blockID);
		world.setBlock(i + 13, j + 4, k + 13, Block.glass.blockID);
		world.setBlock(i + 13, j + 5, k + 4, Block.glass.blockID);
		world.setBlock(i + 13, j + 5, k + 5, Block.glass.blockID);
		world.setBlock(i + 13, j + 5, k + 11, Block.glass.blockID);
		world.setBlock(i + 13, j + 5, k + 12, Block.glass.blockID);
		world.setBlock(i + 13, j + 6, k + 6, Block.glass.blockID);
		world.setBlock(i + 13, j + 6, k + 7, Block.glass.blockID);
		world.setBlock(i + 13, j + 6, k + 8, Block.glass.blockID);
		world.setBlock(i + 13, j + 6, k + 9, Block.glass.blockID);
		world.setBlock(i + 13, j + 6, k + 10, Block.glass.blockID);
		world.setBlock(i + 14, j + 0, k + 0, Block.dirt.blockID);
		world.setBlock(i + 14, j + 0, k + 1, Block.dirt.blockID);
		world.setBlock(i + 14, j + 0, k + 2, Block.dirt.blockID);
		world.setBlock(i + 14, j + 0, k + 3, Block.dirt.blockID);
		world.setBlock(i + 14, j + 0, k + 4, Block.dirt.blockID);
		world.setBlock(i + 14, j + 0, k + 5, Block.dirt.blockID);
		world.setBlock(i + 14, j + 0, k + 6, Block.dirt.blockID);
		world.setBlock(i + 14, j + 0, k + 7, Block.dirt.blockID);
		world.setBlock(i + 14, j + 0, k + 8, Block.dirt.blockID);
		world.setBlock(i + 14, j + 0, k + 9, Block.dirt.blockID);
		world.setBlock(i + 14, j + 0, k + 10, Block.dirt.blockID);
		world.setBlock(i + 14, j + 0, k + 11, Block.dirt.blockID);
		world.setBlock(i + 14, j + 0, k + 12, Block.dirt.blockID);
		world.setBlock(i + 14, j + 0, k + 13, Block.dirt.blockID);
		world.setBlock(i + 14, j + 0, k + 14, Block.dirt.blockID);
		world.setBlock(i + 14, j + 0, k + 15, Block.dirt.blockID);
		world.setBlock(i + 14, j + 0, k + 16, Block.dirt.blockID);
		world.setBlock(i + 14, j + 1, k + 3, Block.stoneBrick.blockID);
		world.setBlock(i + 14, j + 1, k + 13, Block.stoneBrick.blockID);
		world.setBlock(i + 14, j + 2, k + 3, Block.glass.blockID);
		world.setBlock(i + 14, j + 2, k + 13, Block.glass.blockID);
		world.setBlock(i + 14, j + 3, k + 3, Block.glass.blockID);
		world.setBlock(i + 14, j + 3, k + 13, Block.glass.blockID);
		world.setBlock(i + 14, j + 4, k + 4, Block.glass.blockID);
		world.setBlock(i + 14, j + 4, k + 5, Block.glass.blockID);
		world.setBlock(i + 14, j + 4, k + 11, Block.glass.blockID);
		world.setBlock(i + 14, j + 4, k + 12, Block.glass.blockID);
		world.setBlock(i + 14, j + 5, k + 6, Block.glass.blockID);
		world.setBlock(i + 14, j + 5, k + 7, Block.glass.blockID);
		world.setBlock(i + 14, j + 5, k + 8, Block.glass.blockID);
		world.setBlock(i + 14, j + 5, k + 9, Block.glass.blockID);
		world.setBlock(i + 14, j + 5, k + 10, Block.glass.blockID);
		world.setBlock(i + 15, j + 0, k + 0, Block.dirt.blockID);
		world.setBlock(i + 15, j + 0, k + 1, Block.dirt.blockID);
		world.setBlock(i + 15, j + 0, k + 2, Block.dirt.blockID);
		world.setBlock(i + 15, j + 0, k + 3, Block.dirt.blockID);
		world.setBlock(i + 15, j + 0, k + 4, Block.dirt.blockID);
		world.setBlock(i + 15, j + 0, k + 5, Block.dirt.blockID);
		world.setBlock(i + 15, j + 0, k + 6, Block.dirt.blockID);
		world.setBlock(i + 15, j + 0, k + 7, Block.dirt.blockID);
		world.setBlock(i + 15, j + 0, k + 8, Block.dirt.blockID);
		world.setBlock(i + 15, j + 0, k + 9, Block.dirt.blockID);
		world.setBlock(i + 15, j + 0, k + 10, Block.dirt.blockID);
		world.setBlock(i + 15, j + 0, k + 11, Block.dirt.blockID);
		world.setBlock(i + 15, j + 0, k + 12, Block.dirt.blockID);
		world.setBlock(i + 15, j + 0, k + 13, Block.dirt.blockID);
		world.setBlock(i + 15, j + 0, k + 14, Block.dirt.blockID);
		world.setBlock(i + 15, j + 0, k + 15, Block.dirt.blockID);
		world.setBlock(i + 15, j + 0, k + 16, Block.dirt.blockID);
		world.setBlock(i + 15, j + 1, k + 4, Block.stoneBrick.blockID);
		world.setBlock(i + 15, j + 1, k + 5, Block.stoneBrick.blockID);
		world.setBlock(i + 15, j + 1, k + 11, Block.stoneBrick.blockID);
		world.setBlock(i + 15, j + 1, k + 12, Block.stoneBrick.blockID);
		world.setBlock(i + 15, j + 2, k + 4, Block.glass.blockID);
		world.setBlock(i + 15, j + 2, k + 5, Block.glass.blockID);
		world.setBlock(i + 15, j + 2, k + 11, Block.glass.blockID);
		world.setBlock(i + 15, j + 2, k + 12, Block.glass.blockID);
		world.setBlock(i + 15, j + 3, k + 4, Block.glass.blockID);
		world.setBlock(i + 15, j + 3, k + 5, Block.glass.blockID);
		world.setBlock(i + 15, j + 3, k + 11, Block.glass.blockID);
		world.setBlock(i + 15, j + 3, k + 12, Block.glass.blockID);
		world.setBlock(i + 15, j + 4, k + 6, Block.glass.blockID);
		world.setBlock(i + 15, j + 4, k + 7, Block.glass.blockID);
		world.setBlock(i + 15, j + 4, k + 8, Block.glass.blockID);
		world.setBlock(i + 15, j + 4, k + 9, Block.glass.blockID);
		world.setBlock(i + 15, j + 4, k + 10, Block.glass.blockID);
		world.setBlock(i + 16, j + 0, k + 0, Block.dirt.blockID);
		world.setBlock(i + 16, j + 0, k + 1, Block.dirt.blockID);
		world.setBlock(i + 16, j + 0, k + 2, Block.dirt.blockID);
		world.setBlock(i + 16, j + 0, k + 3, Block.dirt.blockID);
		world.setBlock(i + 16, j + 0, k + 4, Block.dirt.blockID);
		world.setBlock(i + 16, j + 0, k + 5, Block.dirt.blockID);
		world.setBlock(i + 16, j + 0, k + 6, Block.dirt.blockID);
		world.setBlock(i + 16, j + 0, k + 7, Block.dirt.blockID);
		world.setBlock(i + 16, j + 0, k + 8, Block.dirt.blockID);
		world.setBlock(i + 16, j + 0, k + 9, Block.dirt.blockID);
		world.setBlock(i + 16, j + 0, k + 10, Block.dirt.blockID);
		world.setBlock(i + 16, j + 0, k + 11, Block.dirt.blockID);
		world.setBlock(i + 16, j + 0, k + 12, Block.dirt.blockID);
		world.setBlock(i + 16, j + 0, k + 13, Block.dirt.blockID);
		world.setBlock(i + 16, j + 0, k + 14, Block.dirt.blockID);
		world.setBlock(i + 16, j + 0, k + 15, Block.dirt.blockID);
		world.setBlock(i + 16, j + 0, k + 16, Block.dirt.blockID);
		world.setBlock(i + 16, j + 1, k + 6, Block.stoneBrick.blockID);
		world.setBlock(i + 16, j + 1, k + 7, Block.stoneBrick.blockID);
		world.setBlock(i + 16, j + 1, k + 8, Block.stoneBrick.blockID);
		world.setBlock(i + 16, j + 1, k + 9, Block.stoneBrick.blockID);
		world.setBlock(i + 16, j + 1, k + 10, Block.stoneBrick.blockID);
		world.setBlock(i + 16, j + 2, k + 6, Block.glass.blockID);
		world.setBlock(i + 16, j + 2, k + 7, Block.glass.blockID);
		world.setBlock(i + 16, j + 2, k + 8, Block.glass.blockID);
		world.setBlock(i + 16, j + 2, k + 9, Block.glass.blockID);
		world.setBlock(i + 16, j + 2, k + 10, Block.glass.blockID);
		world.setBlock(i + 16, j + 3, k + 6, Block.glass.blockID);
		world.setBlock(i + 16, j + 3, k + 7, Block.glass.blockID);
		world.setBlock(i + 16, j + 3, k + 8, Block.glass.blockID);
		world.setBlock(i + 16, j + 3, k + 9, Block.glass.blockID);
		world.setBlock(i + 16, j + 3, k + 10, Block.glass.blockID); 
		world.setBlock(i + 0, j + 1, k + 0, Block.sand.blockID, 0, 3);
		world.setBlock(i + 0, j + 1, k + 1, Block.sand.blockID, 0, 3);
		world.setBlock(i + 0, j + 1, k + 2, Block.sand.blockID, 0, 3);
		world.setBlock(i + 0, j + 1, k + 3, Block.sand.blockID, 0, 3);
		world.setBlock(i + 0, j + 1, k + 4, Block.sand.blockID, 0, 3);
		world.setBlock(i + 0, j + 1, k + 5, Block.sand.blockID, 0, 3);
		world.setBlock(i + 0, j + 1, k + 11, Block.sand.blockID, 0, 3);
		world.setBlock(i + 0, j + 1, k + 12, Block.sand.blockID, 0, 3);
		world.setBlock(i + 0, j + 1, k + 13, Block.sand.blockID, 0, 3);
		world.setBlock(i + 0, j + 1, k + 14, Block.sand.blockID, 0, 3);
		world.setBlock(i + 0, j + 1, k + 15, Block.sand.blockID, 0, 3);
		world.setBlock(i + 0, j + 1, k + 16, Block.sand.blockID, 0, 3);
		world.setBlock(i + 1, j + 1, k + 0, Block.sand.blockID, 0, 3);
		world.setBlock(i + 1, j + 1, k + 1, Block.sand.blockID, 0, 3);
		world.setBlock(i + 1, j + 1, k + 2, Block.sand.blockID, 0, 3);
		world.setBlock(i + 1, j + 1, k + 3, Block.sand.blockID, 0, 3);
		world.setBlock(i + 1, j + 1, k + 6, Block.sand.blockID, 0, 3);
		world.setBlock(i + 1, j + 1, k + 7, Block.sand.blockID, 0, 3);
		world.setBlock(i + 1, j + 1, k + 8, Block.sand.blockID, 0, 3);
		world.setBlock(i + 1, j + 1, k + 9, Block.sand.blockID, 0, 3);
		world.setBlock(i + 1, j + 1, k + 10, Block.sand.blockID, 0, 3);
		world.setBlock(i + 1, j + 1, k + 13, Block.sand.blockID, 0, 3);
		world.setBlock(i + 1, j + 1, k + 14, Block.sand.blockID, 0, 3);
		world.setBlock(i + 1, j + 1, k + 15, Block.sand.blockID, 0, 3);
		world.setBlock(i + 1, j + 1, k + 16, Block.sand.blockID, 0, 3);
		world.setBlock(i + 2, j + 1, k + 0, Block.sand.blockID, 0, 3);
		world.setBlock(i + 2, j + 1, k + 1, Block.sand.blockID, 0, 3);
		world.setBlock(i + 2, j + 1, k + 2, Block.sand.blockID, 0, 3);
		world.setBlock(i + 2, j + 1, k + 4, Block.sand.blockID, 0, 3);
		world.setBlock(i + 2, j + 1, k + 5, Block.sand.blockID, 0, 3);
		world.setBlock(i + 2, j + 1, k + 6, Block.sand.blockID, 0, 3);
		world.setBlock(i + 2, j + 1, k + 7, Block.sand.blockID, 0, 3);
		world.setBlock(i + 2, j + 1, k + 8, Block.sand.blockID, 0, 3);
		world.setBlock(i + 2, j + 1, k + 9, Block.sand.blockID, 0, 3);
		world.setBlock(i + 2, j + 1, k + 10, Block.sand.blockID, 0, 3);
		world.setBlock(i + 2, j + 1, k + 11, Block.sand.blockID, 0, 3);
		world.setBlock(i + 2, j + 1, k + 12, Block.sand.blockID, 0, 3);
		world.setBlock(i + 2, j + 1, k + 14, Block.sand.blockID, 0, 3);
		world.setBlock(i + 2, j + 1, k + 15, Block.sand.blockID, 0, 3);
		world.setBlock(i + 2, j + 1, k + 16, Block.sand.blockID, 0, 3);
		world.setBlock(i + 3, j + 1, k + 0, Block.sand.blockID, 0, 3);
		world.setBlock(i + 3, j + 1, k + 1, Block.sand.blockID, 0, 3);
		world.setBlock(i + 3, j + 1, k + 3, Block.sand.blockID, 0, 3);
		world.setBlock(i + 3, j + 1, k + 4, Block.sand.blockID, 0, 3);
		world.setBlock(i + 3, j + 1, k + 5, Block.sand.blockID, 0, 3);
		world.setBlock(i + 3, j + 1, k + 6, Block.sand.blockID, 0, 3);
		world.setBlock(i + 3, j + 1, k + 7, Block.sand.blockID, 0, 3);
		world.setBlock(i + 3, j + 1, k + 9, Block.sand.blockID, 0, 3);
		world.setBlock(i + 3, j + 1, k + 10, Block.sand.blockID, 0, 3);
		world.setBlock(i + 3, j + 1, k + 11, Block.sand.blockID, 0, 3);
		world.setBlock(i + 3, j + 1, k + 12, Block.sand.blockID, 0, 3);
		world.setBlock(i + 3, j + 1, k + 13, Block.sand.blockID, 0, 3);
		world.setBlock(i + 3, j + 1, k + 15, Block.sand.blockID, 0, 3);
		world.setBlock(i + 3, j + 1, k + 16, Block.sand.blockID, 0, 3);
		world.setBlock(i + 4, j + 1, k + 0, Block.sand.blockID, 0, 3);
		world.setBlock(i + 4, j + 1, k + 2, Block.sand.blockID, 0, 3);
		world.setBlock(i + 4, j + 1, k + 3, Block.sand.blockID, 0, 3);
		world.setBlock(i + 4, j + 1, k + 4, Block.sand.blockID, 0, 3);
		world.setBlock(i + 4, j + 1, k + 5, Block.sand.blockID, 0, 3);
		world.setBlock(i + 4, j + 1, k + 6, Block.sand.blockID, 0, 3);
		world.setBlock(i + 4, j + 1, k + 10, Block.sand.blockID, 0, 3);
		world.setBlock(i + 4, j + 1, k + 11, Block.sand.blockID, 0, 3);
		world.setBlock(i + 4, j + 1, k + 12, Block.sand.blockID, 0, 3);
		world.setBlock(i + 4, j + 1, k + 13, Block.sand.blockID, 0, 3);
		world.setBlock(i + 4, j + 1, k + 14, Block.sand.blockID, 0, 3);
		world.setBlock(i + 4, j + 1, k + 16, Block.sand.blockID, 0, 3);
		world.setBlock(i + 5, j + 1, k + 0, Block.sand.blockID, 0, 3);
		world.setBlock(i + 5, j + 1, k + 2, Block.sand.blockID, 0, 3);
		world.setBlock(i + 5, j + 1, k + 3, Block.sand.blockID, 0, 3);
		world.setBlock(i + 5, j + 1, k + 4, Block.sand.blockID, 0, 3);
		world.setBlock(i + 5, j + 1, k + 5, Block.sand.blockID, 0, 3);
		world.setBlock(i + 5, j + 1, k + 11, Block.sand.blockID, 0, 3);
		world.setBlock(i + 5, j + 1, k + 12, Block.sand.blockID, 0, 3);
		world.setBlock(i + 5, j + 1, k + 13, Block.sand.blockID, 0, 3);
		world.setBlock(i + 5, j + 1, k + 14, Block.sand.blockID, 0, 3);
		world.setBlock(i + 5, j + 1, k + 16, Block.sand.blockID, 0, 3);
		world.setBlock(i + 6, j + 1, k + 1, Block.sand.blockID, 0, 3);
		world.setBlock(i + 6, j + 1, k + 2, Block.sand.blockID, 0, 3);
		world.setBlock(i + 6, j + 1, k + 3, Block.sand.blockID, 0, 3);
		world.setBlock(i + 6, j + 1, k + 4, Block.sand.blockID, 0, 3);
		world.setBlock(i + 6, j + 1, k + 12, Block.sand.blockID, 0, 3);
		world.setBlock(i + 6, j + 1, k + 13, Block.sand.blockID, 0, 3);
		world.setBlock(i + 6, j + 1, k + 14, Block.sand.blockID, 0, 3);
		world.setBlock(i + 6, j + 1, k + 15, Block.sand.blockID, 0, 3);
		world.setBlock(i + 7, j + 1, k + 1, Block.sand.blockID, 0, 3);
		world.setBlock(i + 7, j + 1, k + 2, Block.sand.blockID, 0, 3);
		world.setBlock(i + 7, j + 1, k + 3, Block.sand.blockID, 0, 3);
		world.setBlockMetadataWithNotify(i + 7, j + 1, k + 7, Block.waterStill.blockID, 9);
		world.setBlockMetadataWithNotify(i + 7, j + 1, k + 8, Block.waterStill.blockID, 8);
		world.setBlockMetadataWithNotify(i + 7, j + 1, k + 9, Block.waterStill.blockID, 9);
		world.setBlock(i + 7, j + 1, k + 13, Block.sand.blockID, 0, 3);
		world.setBlock(i + 7, j + 1, k + 14, Block.sand.blockID, 0, 3);
		world.setBlock(i + 7, j + 1, k + 15, Block.sand.blockID, 0, 3);
		world.setBlockMetadataWithNotify(i + 7, j + 2, k + 7, Block.waterStill.blockID, 3);
		world.setBlock(i + 7, j + 2, k + 8, Block.waterStill.blockID);
		world.setBlockMetadataWithNotify(i + 7, j + 2, k + 9, Block.waterStill.blockID, 3);
		world.setBlock(i + 8, j + 1, k + 1, Block.sand.blockID, 0, 3);
		world.setBlock(i + 8, j + 1, k + 2, Block.sand.blockID, 0, 3);
		world.setBlock(i + 8, j + 1, k + 3, Block.sand.blockID, 0, 3);
		world.setBlock(i + 8, j + 1, k + 7, Block.waterStill.blockID, 8, 3);
		world.setBlock(i + 8, j + 1, k + 9, Block.waterStill.blockID, 8, 3);
		world.setBlock(i + 8, j + 1, k + 13, Block.sand.blockID, 0, 3);
		world.setBlock(i + 8, j + 1, k + 14, Block.sand.blockID, 0, 3);
		world.setBlock(i + 8, j + 1, k + 15, Block.sand.blockID, 0, 3);
		world.setBlock(i + 8, j + 2, k + 7, Block.waterStill.blockID);
		world.setBlock(i + 8, j + 2, k + 9, Block.waterStill.blockID);
		world.setBlock(i + 9, j + 1, k + 1, Block.sand.blockID, 0, 3);
		world.setBlock(i + 9, j + 1, k + 2, Block.sand.blockID, 0, 3);
		world.setBlock(i + 9, j + 1, k + 3, Block.sand.blockID, 0, 3);
		world.setBlock(i + 9, j + 1, k + 7, Block.waterStill.blockID, 9, 3);
		world.setBlock(i + 9, j + 1, k + 8, Block.waterStill.blockID, 8, 3);
		world.setBlock(i + 9, j + 1, k + 9, Block.waterStill.blockID, 9, 3);
		world.setBlock(i + 9, j + 1, k + 13, Block.sand.blockID, 0, 3);
		world.setBlock(i + 9, j + 1, k + 14, Block.sand.blockID, 0, 3);
		world.setBlock(i + 9, j + 1, k + 15, Block.sand.blockID, 0, 3);
		world.setBlock(i + 9, j + 2, k + 7, Block.waterStill.blockID, 1, 3);
		world.setBlock(i + 9, j + 2, k + 8, Block.waterStill.blockID);
		world.setBlock(i + 9, j + 2, k + 9, Block.waterStill.blockID, 1, 3);
		world.setBlock(i + 10, j + 1, k + 1, Block.sand.blockID, 0, 3);
		world.setBlock(i + 10, j + 1, k + 2, Block.sand.blockID, 0, 3);
		world.setBlock(i + 10, j + 1, k + 3, Block.sand.blockID, 0, 3);
		world.setBlock(i + 10, j + 1, k + 4, Block.sand.blockID, 0, 3);
		world.setBlock(i + 10, j + 1, k + 12, Block.sand.blockID, 0, 3);
		world.setBlock(i + 10, j + 1, k + 13, Block.sand.blockID, 0, 3);
		world.setBlock(i + 10, j + 1, k + 14, Block.sand.blockID, 0, 3);
		world.setBlock(i + 10, j + 1, k + 15, Block.sand.blockID, 0, 3);
		world.setBlock(i + 11, j + 1, k + 0, Block.sand.blockID, 0, 3);
		world.setBlock(i + 11, j + 1, k + 2, Block.sand.blockID, 0, 3);
		world.setBlock(i + 11, j + 1, k + 3, Block.sand.blockID, 0, 3);
		world.setBlock(i + 11, j + 1, k + 4, Block.sand.blockID, 0, 3);
		world.setBlock(i + 11, j + 1, k + 5, Block.sand.blockID, 0, 3);
		world.setBlock(i + 11, j + 1, k + 11, Block.sand.blockID, 0, 3);
		world.setBlock(i + 11, j + 1, k + 12, Block.sand.blockID, 0, 3);
		world.setBlock(i + 11, j + 1, k + 13, Block.sand.blockID, 0, 3);
		world.setBlock(i + 11, j + 1, k + 14, Block.sand.blockID, 0, 3);
		world.setBlock(i + 11, j + 1, k + 16, Block.sand.blockID, 0, 3);
		world.setBlock(i + 12, j + 1, k + 0, Block.sand.blockID, 0, 3);
		world.setBlock(i + 12, j + 1, k + 2, Block.sand.blockID, 0, 3);
		world.setBlock(i + 12, j + 1, k + 3, Block.sand.blockID, 0, 3);
		world.setBlock(i + 12, j + 1, k + 4, Block.sand.blockID, 0, 3);
		world.setBlock(i + 12, j + 1, k + 5, Block.sand.blockID, 0, 3);
		world.setBlock(i + 12, j + 1, k + 6, Block.sand.blockID, 0, 3);
		world.setBlock(i + 12, j + 1, k + 10, Block.sand.blockID, 0, 3);
		world.setBlock(i + 12, j + 1, k + 11, Block.sand.blockID, 0, 3);
		world.setBlock(i + 12, j + 1, k + 12, Block.sand.blockID, 0, 3);
		world.setBlock(i + 12, j + 1, k + 13, Block.sand.blockID, 0, 3);
		world.setBlock(i + 12, j + 1, k + 14, Block.sand.blockID, 0, 3);
		world.setBlock(i + 12, j + 1, k + 16, Block.sand.blockID, 0, 3);
		world.setBlock(i + 13, j + 1, k + 0, Block.sand.blockID, 0, 3);
		world.setBlock(i + 13, j + 1, k + 1, Block.sand.blockID, 0, 3);
		world.setBlock(i + 13, j + 1, k + 3, Block.sand.blockID, 0, 3);
		world.setBlock(i + 13, j + 1, k + 4, Block.sand.blockID, 0, 3);
		world.setBlock(i + 13, j + 1, k + 5, Block.sand.blockID, 0, 3);
		world.setBlock(i + 13, j + 1, k + 6, Block.sand.blockID, 0, 3);
		world.setBlock(i + 13, j + 1, k + 7, Block.sand.blockID, 0, 3);
		world.setBlock(i + 13, j + 1, k + 8, Block.sand.blockID, 0, 3);
		world.setBlock(i + 13, j + 1, k + 9, Block.sand.blockID, 0, 3);
		world.setBlock(i + 13, j + 1, k + 10, Block.sand.blockID, 0, 3);
		world.setBlock(i + 13, j + 1, k + 11, Block.sand.blockID, 0, 3);
		world.setBlock(i + 13, j + 1, k + 12, Block.sand.blockID, 0, 3);
		world.setBlock(i + 13, j + 1, k + 13, Block.sand.blockID, 0, 3);
		world.setBlock(i + 13, j + 1, k + 15, Block.sand.blockID, 0, 3);
		world.setBlock(i + 13, j + 1, k + 16, Block.sand.blockID, 0, 3);
		world.setBlock(i + 14, j + 1, k + 0, Block.sand.blockID, 0, 3);
		world.setBlock(i + 14, j + 1, k + 1, Block.sand.blockID, 0, 3);
		world.setBlock(i + 14, j + 1, k + 2, Block.sand.blockID, 0, 3);
		world.setBlock(i + 14, j + 1, k + 4, Block.sand.blockID, 0, 3);
		world.setBlock(i + 14, j + 1, k + 5, Block.sand.blockID, 0, 3);
		world.setBlock(i + 14, j + 1, k + 6, Block.sand.blockID, 0, 3);
		world.setBlock(i + 14, j + 1, k + 7, Block.sand.blockID, 0, 3);
		world.setBlock(i + 14, j + 1, k + 8, Block.sand.blockID, 0, 3);
		world.setBlock(i + 14, j + 1, k + 9, Block.sand.blockID, 0, 3);
		world.setBlock(i + 14, j + 1, k + 10, Block.sand.blockID, 0, 3);
		world.setBlock(i + 14, j + 1, k + 11, Block.sand.blockID, 0, 3);
		world.setBlock(i + 14, j + 1, k + 12, Block.sand.blockID, 0, 3);
		world.setBlock(i + 14, j + 1, k + 14, Block.sand.blockID, 0, 3);
		world.setBlock(i + 14, j + 1, k + 15, Block.sand.blockID, 0, 3);
		world.setBlock(i + 14, j + 1, k + 16, Block.sand.blockID, 0, 3);
		world.setBlock(i + 15, j + 1, k + 0, Block.sand.blockID, 0, 3);
		world.setBlock(i + 15, j + 1, k + 1, Block.sand.blockID, 0, 3);
		world.setBlock(i + 15, j + 1, k + 2, Block.sand.blockID, 0, 3);
		world.setBlock(i + 15, j + 1, k + 3, Block.sand.blockID, 0, 3);
		world.setBlock(i + 15, j + 1, k + 6, Block.sand.blockID, 0, 3);
		world.setBlock(i + 15, j + 1, k + 7, Block.sand.blockID, 0, 3);
		world.setBlock(i + 15, j + 1, k + 8, Block.sand.blockID, 0, 3);
		world.setBlock(i + 15, j + 1, k + 9, Block.sand.blockID, 0, 3);
		world.setBlock(i + 15, j + 1, k + 10, Block.sand.blockID, 0, 3);
		world.setBlock(i + 15, j + 1, k + 13, Block.sand.blockID, 0, 3);
		world.setBlock(i + 15, j + 1, k + 14, Block.sand.blockID, 0, 3);
		world.setBlock(i + 15, j + 1, k + 15, Block.sand.blockID, 0, 3);
		world.setBlock(i + 15, j + 1, k + 16, Block.sand.blockID, 0, 3);
		world.setBlock(i + 16, j + 1, k + 0, Block.sand.blockID, 0, 3);
		world.setBlock(i + 16, j + 1, k + 1, Block.sand.blockID, 0, 3);
		world.setBlock(i + 16, j + 1, k + 2, Block.sand.blockID, 0, 3);
		world.setBlock(i + 16, j + 1, k + 3, Block.sand.blockID, 0, 3);
		world.setBlock(i + 16, j + 1, k + 4, Block.sand.blockID, 0, 3);
		world.setBlock(i + 16, j + 1, k + 5, Block.sand.blockID, 0, 3);
		world.setBlock(i + 16, j + 1, k + 11, Block.sand.blockID, 0, 3);
		world.setBlock(i + 16, j + 1, k + 12, Block.sand.blockID, 0, 3);
		world.setBlock(i + 16, j + 1, k + 13, Block.sand.blockID, 0, 3);
		world.setBlock(i + 16, j + 1, k + 14, Block.sand.blockID, 0, 3);
		world.setBlock(i + 16, j + 1, k + 15, Block.sand.blockID, 0, 3);
		world.setBlock(i + 16, j + 1, k + 16, Block.sand.blockID, 0, 3);
		
		j++;
		
		//Air
		world.setBlock(i + 0, j + 1, k + 7, 0);
		world.setBlock(i + 0, j + 1, k + 8, 0);
		world.setBlock(i + 0, j + 1, k + 9, 0);
		world.setBlock(i + 0, j + 1, k + 17, 0);
		world.setBlock(i + 0, j + 2, k + 7, 0);
		world.setBlock(i + 0, j + 2, k + 8, 0);
		world.setBlock(i + 0, j + 2, k + 9, 0);
		world.setBlock(i + 0, j + 2, k + 17, 0);
		world.setBlock(i + 0, j + 3, k + 17, 0);
		world.setBlock(i + 0, j + 4, k + 17, 0);
		world.setBlock(i + 0, j + 5, k + 17, 0);
		world.setBlock(i + 0, j + 6, k + 17, 0);
		world.setBlock(i + 1, j + 1, k + 6, 0);
		world.setBlock(i + 1, j + 1, k + 7, 0);
		world.setBlock(i + 1, j + 1, k + 8, 0);
		world.setBlock(i + 1, j + 1, k + 9, 0);
		world.setBlock(i + 1, j + 1, k + 10, 0);
		world.setBlock(i + 1, j + 1, k + 17, 0);
		world.setBlock(i + 1, j + 2, k + 6, 0);
		world.setBlock(i + 1, j + 2, k + 7, 0);
		world.setBlock(i + 1, j + 2, k + 8, 0);
		world.setBlock(i + 1, j + 2, k + 9, 0);
		world.setBlock(i + 1, j + 2, k + 10, 0);;
		world.setBlock(i + 1, j + 2, k + 17, 0);
		world.setBlock(i + 1, j + 3, k + 7, 0);
		world.setBlock(i + 1, j + 3, k + 8, 0);
		world.setBlock(i + 1, j + 3, k + 9, 0);
		world.setBlock(i + 1, j + 3, k + 17, 0);
		world.setBlock(i + 1, j + 4, k + 17, 0);
		world.setBlock(i + 1, j + 5, k + 17, 0);
		world.setBlock(i + 1, j + 6, k + 17, 0);
		world.setBlock(i + 2, j + 1, k + 4, 0);
		world.setBlock(i + 2, j + 1, k + 5, 0);
		world.setBlock(i + 2, j + 1, k + 6, 0);
		world.setBlock(i + 2, j + 1, k + 7, 0);
		world.setBlock(i + 2, j + 1, k + 8, 0);
		world.setBlock(i + 2, j + 1, k + 9, 0);
		world.setBlock(i + 2, j + 1, k + 10, 0);
		world.setBlock(i + 2, j + 1, k + 11, 0);
		world.setBlock(i + 2, j + 1, k + 12, 0);
		world.setBlock(i + 2, j + 1, k + 17, 0);
		world.setBlock(i + 2, j + 2, k + 4, 0);
		world.setBlock(i + 2, j + 2, k + 5, 0);
		world.setBlock(i + 2, j + 2, k + 6, 0);
		world.setBlock(i + 2, j + 2, k + 7, 0);
		world.setBlock(i + 2, j + 2, k + 8, 0);
		world.setBlock(i + 2, j + 2, k + 9, 0);
		world.setBlock(i + 2, j + 2, k + 10, 0);
		world.setBlock(i + 2, j + 2, k + 11, 0);
		world.setBlock(i + 2, j + 2, k + 12, 0);
		world.setBlock(i + 2, j + 2, k + 17, 0);
		world.setBlock(i + 2, j + 3, k + 6, 0);
		world.setBlock(i + 2, j + 3, k + 7, 0);
		world.setBlock(i + 2, j + 3, k + 8, 0);
		world.setBlock(i + 2, j + 3, k + 9, 0);
		world.setBlock(i + 2, j + 3, k + 10, 0);
		world.setBlock(i + 2, j + 3, k + 17, 0);
		world.setBlock(i + 2, j + 4, k + 17, 0);
		world.setBlock(i + 2, j + 5, k + 17, 0);
		world.setBlock(i + 2, j + 6, k + 17, 0);
		world.setBlock(i + 3, j + 1, k + 3, 0);
		world.setBlock(i + 3, j + 1, k + 4, 0);
		world.setBlock(i + 3, j + 1, k + 5, 0);
		world.setBlock(i + 3, j + 1, k + 6, 0);
		world.setBlock(i + 3, j + 1, k + 7, 0);
		world.setBlock(i + 3, j + 1, k + 8, 0);
		world.setBlock(i + 3, j + 1, k + 9, 0);
		world.setBlock(i + 3, j + 1, k + 10, 0);
		world.setBlock(i + 3, j + 1, k + 11, 0);
		world.setBlock(i + 3, j + 1, k + 12, 0);
		world.setBlock(i + 3, j + 1, k + 13, 0);
		world.setBlock(i + 3, j + 1, k + 17, 0);
		world.setBlock(i + 3, j + 2, k + 3, 0);
		world.setBlock(i + 3, j + 2, k + 4, 0);
		world.setBlock(i + 3, j + 2, k + 5, 0);
		world.setBlock(i + 3, j + 2, k + 6, 0);
		world.setBlock(i + 3, j + 2, k + 7, 0);
		world.setBlock(i + 3, j + 2, k + 8, 0);
		world.setBlock(i + 3, j + 2, k + 9, 0);
		world.setBlock(i + 3, j + 2, k + 10, 0);
		world.setBlock(i + 3, j + 2, k + 11, 0);
		world.setBlock(i + 3, j + 2, k + 12, 0);
		world.setBlock(i + 3, j + 2, k + 13, 0);
		world.setBlock(i + 3, j + 2, k + 17, 0);
		world.setBlock(i + 3, j + 3, k + 4, 0);
		world.setBlock(i + 3, j + 3, k + 5, 0);
		world.setBlock(i + 3, j + 3, k + 6, 0);
		world.setBlock(i + 3, j + 3, k + 7, 0);
		world.setBlock(i + 3, j + 3, k + 8, 0);
		world.setBlock(i + 3, j + 3, k + 9, 0);
		world.setBlock(i + 3, j + 3, k + 10, 0);
		world.setBlock(i + 3, j + 3, k + 11, 0);
		world.setBlock(i + 3, j + 3, k + 12, 0);
		world.setBlock(i + 3, j + 3, k + 17, 0);
		world.setBlock(i + 3, j + 4, k + 6, 0);
		world.setBlock(i + 3, j + 4, k + 7, 0);
		world.setBlock(i + 3, j + 4, k + 8, 0);
		world.setBlock(i + 3, j + 4, k + 9, 0);
		world.setBlock(i + 3, j + 4, k + 10, 0);
		world.setBlock(i + 3, j + 4, k + 17, 0);
		world.setBlock(i + 3, j + 5, k + 17, 0);
		world.setBlock(i + 3, j + 6, k + 17, 0);
		world.setBlock(i + 4, j + 1, k + 2, 0);
		world.setBlock(i + 4, j + 1, k + 3, 0);
		world.setBlock(i + 4, j + 1, k + 4, 0);
		world.setBlock(i + 4, j + 1, k + 5, 0);
		world.setBlock(i + 4, j + 1, k + 6, 0);
		world.setBlock(i + 4, j + 1, k + 7, 0);
		world.setBlock(i + 4, j + 1, k + 8, 0);
		world.setBlock(i + 4, j + 1, k + 9, 0);
		world.setBlock(i + 4, j + 1, k + 10, 0);
		world.setBlock(i + 4, j + 1, k + 11, 0);
		world.setBlock(i + 4, j + 1, k + 12, 0);
		world.setBlock(i + 4, j + 1, k + 13, 0);
		world.setBlock(i + 4, j + 1, k + 14, 0);
		world.setBlock(i + 4, j + 1, k + 17, 0);
		world.setBlock(i + 4, j + 2, k + 2, 0);
		world.setBlock(i + 4, j + 2, k + 3, 0);
		world.setBlock(i + 4, j + 2, k + 4, 0);
		world.setBlock(i + 4, j + 2, k + 5, 0);
		world.setBlock(i + 4, j + 2, k + 6, 0);
		world.setBlock(i + 4, j + 2, k + 7, 0);
		world.setBlock(i + 4, j + 2, k + 8, 0);
		world.setBlock(i + 4, j + 2, k + 9, 0);
		world.setBlock(i + 4, j + 2, k + 10, 0);
		world.setBlock(i + 4, j + 2, k + 11, 0);
		world.setBlock(i + 4, j + 2, k + 12, 0);
		world.setBlock(i + 4, j + 2, k + 13, 0);
		world.setBlock(i + 4, j + 2, k + 14, 0);
		world.setBlock(i + 4, j + 2, k + 17, 0);
		world.setBlock(i + 4, j + 3, k + 3, 0);
		world.setBlock(i + 4, j + 3, k + 4, 0);
		world.setBlock(i + 4, j + 3, k + 5, 0);
		world.setBlock(i + 4, j + 3, k + 6, 0);
		world.setBlock(i + 4, j + 3, k + 7, 0);
		world.setBlock(i + 4, j + 3, k + 8, 0);
		world.setBlock(i + 4, j + 3, k + 9, 0);
		world.setBlock(i + 4, j + 3, k + 10, 0);
		world.setBlock(i + 4, j + 3, k + 11, 0);
		world.setBlock(i + 4, j + 3, k + 12, 0);
		world.setBlock(i + 4, j + 3, k + 13, 0);
		world.setBlock(i + 4, j + 3, k + 17, 0);
		world.setBlock(i + 4, j + 4, k + 4, 0);
		world.setBlock(i + 4, j + 4, k + 5, 0);
		world.setBlock(i + 4, j + 4, k + 6, 0);
		world.setBlock(i + 4, j + 4, k + 7, 0);
		world.setBlock(i + 4, j + 4, k + 8, 0);
		world.setBlock(i + 4, j + 4, k + 9, 0);
		world.setBlock(i + 4, j + 4, k + 10, 0);
		world.setBlock(i + 4, j + 4, k + 11, 0);
		world.setBlock(i + 4, j + 4, k + 12, 0);
		world.setBlock(i + 4, j + 4, k + 17, 0);
		world.setBlock(i + 4, j + 5, k + 17, 0);
		world.setBlock(i + 4, j + 6, k + 17, 0);
		world.setBlock(i + 5, j + 1, k + 2, 0);
		world.setBlock(i + 5, j + 1, k + 3, 0);
		world.setBlock(i + 5, j + 1, k + 4, 0);
		world.setBlock(i + 5, j + 1, k + 5, 0);
		world.setBlock(i + 5, j + 1, k + 6, 0);
		world.setBlock(i + 5, j + 1, k + 7, 0);
		world.setBlock(i + 5, j + 1, k + 8, 0);
		world.setBlock(i + 5, j + 1, k + 9, 0);
		world.setBlock(i + 5, j + 1, k + 10, 0);
		world.setBlock(i + 5, j + 1, k + 11, 0);
		world.setBlock(i + 5, j + 1, k + 12, 0);
		world.setBlock(i + 5, j + 1, k + 13, 0);
		world.setBlock(i + 5, j + 1, k + 14, 0);
		world.setBlock(i + 5, j + 1, k + 17, 0);
		world.setBlock(i + 5, j + 2, k + 2, 0);
		world.setBlock(i + 5, j + 2, k + 3, 0);
		world.setBlock(i + 5, j + 2, k + 4, 0);
		world.setBlock(i + 5, j + 2, k + 5, 0);
		world.setBlock(i + 5, j + 2, k + 6, 0);
		world.setBlock(i + 5, j + 2, k + 7, 0);
		world.setBlock(i + 5, j + 2, k + 8, 0);
		world.setBlock(i + 5, j + 2, k + 9, 0);
		world.setBlock(i + 5, j + 2, k + 10, 0);
		world.setBlock(i + 5, j + 2, k + 11, 0);
		world.setBlock(i + 5, j + 2, k + 12, 0);
		world.setBlock(i + 5, j + 2, k + 13, 0);
		world.setBlock(i + 5, j + 2, k + 14, 0);
		world.setBlock(i + 5, j + 2, k + 17, 0);
		world.setBlock(i + 5, j + 3, k + 3, 0);
		world.setBlock(i + 5, j + 3, k + 4, 0);
		world.setBlock(i + 5, j + 3, k + 5, 0);
		world.setBlock(i + 5, j + 3, k + 6, 0);
		world.setBlock(i + 5, j + 3, k + 7, 0);
		world.setBlock(i + 5, j + 3, k + 8, 0);
		world.setBlock(i + 5, j + 3, k + 9, 0);
		world.setBlock(i + 5, j + 3, k + 10, 0);
		world.setBlock(i + 5, j + 3, k + 11, 0);
		world.setBlock(i + 5, j + 3, k + 12, 0);
		world.setBlock(i + 5, j + 3, k + 13, 0);
		world.setBlock(i + 5, j + 3, k + 17, 0);
		world.setBlock(i + 5, j + 4, k + 4, 0);
		world.setBlock(i + 5, j + 4, k + 5, 0);
		world.setBlock(i + 5, j + 4, k + 6, 0);
		world.setBlock(i + 5, j + 4, k + 7, 0);
		world.setBlock(i + 5, j + 4, k + 8, 0);
		world.setBlock(i + 5, j + 4, k + 9, 0);
		world.setBlock(i + 5, j + 4, k + 10, 0);
		world.setBlock(i + 5, j + 4, k + 11, 0);
		world.setBlock(i + 5, j + 4, k + 12, 0);
		world.setBlock(i + 5, j + 4, k + 17, 0);
		world.setBlock(i + 5, j + 5, k + 6, 0);
		world.setBlock(i + 5, j + 5, k + 7, 0);
		world.setBlock(i + 5, j + 5, k + 8, 0);
		world.setBlock(i + 5, j + 5, k + 9, 0);
		world.setBlock(i + 5, j + 5, k + 10, 0);
		world.setBlock(i + 5, j + 5, k + 17, 0);
		world.setBlock(i + 5, j + 6, k + 17, 0);
		world.setBlock(i + 6, j + 1, k + 1, 0);
		world.setBlock(i + 6, j + 1, k + 2, 0);
		world.setBlock(i + 6, j + 1, k + 3, 0);
		world.setBlock(i + 6, j + 1, k + 4, 0);
		world.setBlock(i + 6, j + 1, k + 5, 0);
		world.setBlock(i + 6, j + 1, k + 6, 0);
		world.setBlock(i + 6, j + 1, k + 7, 0);
		world.setBlock(i + 6, j + 1, k + 8, 0);
		world.setBlock(i + 6, j + 1, k + 9, 0);
		world.setBlock(i + 6, j + 1, k + 10, 0);
		world.setBlock(i + 6, j + 1, k + 11, 0);
		world.setBlock(i + 6, j + 1, k + 12, 0);
		world.setBlock(i + 6, j + 1, k + 13, 0);
		world.setBlock(i + 6, j + 1, k + 14, 0);
		world.setBlock(i + 6, j + 1, k + 15, 0);
		world.setBlock(i + 6, j + 1, k + 17, 0);
		world.setBlock(i + 6, j + 2, k + 1, 0);
		world.setBlock(i + 6, j + 2, k + 2, 0);
		world.setBlock(i + 6, j + 2, k + 3, 0);
		world.setBlock(i + 6, j + 2, k + 4, 0);
		world.setBlock(i + 6, j + 2, k + 5, 0);
		world.setBlock(i + 6, j + 2, k + 6, 0);
		world.setBlock(i + 6, j + 2, k + 7, 0);
		world.setBlock(i + 6, j + 2, k + 8, 0);
		world.setBlock(i + 6, j + 2, k + 9, 0);
		world.setBlock(i + 6, j + 2, k + 10, 0);
		world.setBlock(i + 6, j + 2, k + 11, 0);
		world.setBlock(i + 6, j + 2, k + 12, 0);
		world.setBlock(i + 6, j + 2, k + 13, 0);
		world.setBlock(i + 6, j + 2, k + 14, 0);
		world.setBlock(i + 6, j + 2, k + 15, 0);
		world.setBlock(i + 6, j + 2, k + 17, 0);
		world.setBlock(i + 6, j + 3, k + 2, 0);
		world.setBlock(i + 6, j + 3, k + 3, 0);
		world.setBlock(i + 6, j + 3, k + 4, 0);
		world.setBlock(i + 6, j + 3, k + 5, 0);
		world.setBlock(i + 6, j + 3, k + 6, 0);
		world.setBlock(i + 6, j + 3, k + 7, 0);
		world.setBlock(i + 6, j + 3, k + 8, 0);
		world.setBlock(i + 6, j + 3, k + 9, 0);
		world.setBlock(i + 6, j + 3, k + 10, 0);
		world.setBlock(i + 6, j + 3, k + 11, 0);
		world.setBlock(i + 6, j + 3, k + 12, 0);
		world.setBlock(i + 6, j + 3, k + 13, 0);
		world.setBlock(i + 6, j + 3, k + 14, 0);
		world.setBlock(i + 6, j + 3, k + 17, 0);
		world.setBlock(i + 6, j + 4, k + 3, 0);
		world.setBlock(i + 6, j + 4, k + 4, 0);
		world.setBlock(i + 6, j + 4, k + 5, 0);
		world.setBlock(i + 6, j + 4, k + 6, 0);
		world.setBlock(i + 6, j + 4, k + 7, 0);
		world.setBlock(i + 6, j + 4, k + 8, 0);
		world.setBlock(i + 6, j + 4, k + 9, 0);
		world.setBlock(i + 6, j + 4, k + 10, 0);
		world.setBlock(i + 6, j + 4, k + 11, 0);
		world.setBlock(i + 6, j + 4, k + 12, 0);
		world.setBlock(i + 6, j + 4, k + 13, 0);
		world.setBlock(i + 6, j + 4, k + 17, 0);
		world.setBlock(i + 6, j + 5, k + 5, 0);
		world.setBlock(i + 6, j + 5, k + 6, 0);
		world.setBlock(i + 6, j + 5, k + 7, 0);
		world.setBlock(i + 6, j + 5, k + 8, 0);
		world.setBlock(i + 6, j + 5, k + 9, 0);
		world.setBlock(i + 6, j + 5, k + 10, 0);
		world.setBlock(i + 6, j + 5, k + 11, 0);
		world.setBlock(i + 6, j + 5, k + 17, 0);
		world.setBlock(i + 6, j + 6, k + 17, 0);
		world.setBlock(i + 7, j + 1, k + 1, 0);
		world.setBlock(i + 7, j + 1, k + 2, 0);
		world.setBlock(i + 7, j + 1, k + 3, 0);
		world.setBlock(i + 7, j + 1, k + 4, 0);
		world.setBlock(i + 7, j + 1, k + 5, 0);
		world.setBlock(i + 7, j + 1, k + 6, 0);
		world.setBlock(i + 7, j + 1, k + 10, 0);
		world.setBlock(i + 7, j + 1, k + 11, 0);
		world.setBlock(i + 7, j + 1, k + 12, 0);
		world.setBlock(i + 7, j + 1, k + 13, 0);
		world.setBlock(i + 7, j + 1, k + 14, 0);
		world.setBlock(i + 7, j + 1, k + 15, 0);
		world.setBlock(i + 7, j + 1, k + 17, 0);
		world.setBlock(i + 7, j + 2, k + 1, 0);
		world.setBlock(i + 7, j + 2, k + 2, 0);
		world.setBlock(i + 7, j + 2, k + 3, 0);
		world.setBlock(i + 7, j + 2, k + 4, 0);
		world.setBlock(i + 7, j + 2, k + 5, 0);
		world.setBlock(i + 7, j + 2, k + 6, 0);
		world.setBlock(i + 7, j + 2, k + 7, 0);
		world.setBlock(i + 7, j + 2, k + 8, 0);
		world.setBlock(i + 7, j + 2, k + 9, 0);
		world.setBlock(i + 7, j + 2, k + 10, 0);
		world.setBlock(i + 7, j + 2, k + 11, 0);
		world.setBlock(i + 7, j + 2, k + 12, 0);
		world.setBlock(i + 7, j + 2, k + 13, 0);
		world.setBlock(i + 7, j + 2, k + 14, 0);
		world.setBlock(i + 7, j + 2, k + 15, 0);
		world.setBlock(i + 7, j + 2, k + 17, 0);
		world.setBlock(i + 7, j + 3, k + 2, 0);
		world.setBlock(i + 7, j + 3, k + 3, 0);
		world.setBlock(i + 7, j + 3, k + 4, 0);
		world.setBlock(i + 7, j + 3, k + 5, 0);
		world.setBlock(i + 7, j + 3, k + 6, 0);
		world.setBlock(i + 7, j + 3, k + 7, 0);
		world.setBlock(i + 7, j + 3, k + 8, 0);
		world.setBlock(i + 7, j + 3, k + 9, 0);
		world.setBlock(i + 7, j + 3, k + 10, 0);
		world.setBlock(i + 7, j + 3, k + 11, 0);
		world.setBlock(i + 7, j + 3, k + 12, 0);
		world.setBlock(i + 7, j + 3, k + 13, 0);
		world.setBlock(i + 7, j + 3, k + 14, 0);
		world.setBlock(i + 7, j + 3, k + 17, 0);
		world.setBlock(i + 7, j + 4, k + 3, 0);
		world.setBlock(i + 7, j + 4, k + 4, 0);
		world.setBlock(i + 7, j + 4, k + 5, 0);
		world.setBlock(i + 7, j + 4, k + 6, 0);
		world.setBlock(i + 7, j + 4, k + 7, 0);
		world.setBlock(i + 7, j + 4, k + 8, 0);
		world.setBlock(i + 7, j + 4, k + 9, 0);
		world.setBlock(i + 7, j + 4, k + 10, 0);
		world.setBlock(i + 7, j + 4, k + 11, 0);
		world.setBlock(i + 7, j + 4, k + 12, 0);
		world.setBlock(i + 7, j + 4, k + 13, 0);
		world.setBlock(i + 7, j + 4, k + 17, 0);
		world.setBlock(i + 7, j + 5, k + 5, 0);
		world.setBlock(i + 7, j + 5, k + 6, 0);
		world.setBlock(i + 7, j + 5, k + 7, 0);
		world.setBlock(i + 7, j + 5, k + 8, 0);
		world.setBlock(i + 7, j + 5, k + 9, 0);
		world.setBlock(i + 7, j + 5, k + 10, 0);
		world.setBlock(i + 7, j + 5, k + 11, 0);
		world.setBlock(i + 7, j + 5, k + 17, 0);
		world.setBlock(i + 7, j + 6, k + 17, 0);
		world.setBlock(i + 8, j + 1, k + 1, 0);
		world.setBlock(i + 8, j + 1, k + 2, 0);
		world.setBlock(i + 8, j + 1, k + 3, 0);
		world.setBlock(i + 8, j + 1, k + 4, 0);
		world.setBlock(i + 8, j + 1, k + 5, 0);
		world.setBlock(i + 8, j + 1, k + 6, 0);
		world.setBlock(i + 8, j + 1, k + 10, 0);
		world.setBlock(i + 8, j + 1, k + 11, 0);
		world.setBlock(i + 8, j + 1, k + 12, 0);
		world.setBlock(i + 8, j + 1, k + 13, 0);
		world.setBlock(i + 8, j + 1, k + 14, 0);
		world.setBlock(i + 8, j + 1, k + 15, 0);
		world.setBlock(i + 8, j + 1, k + 17, 0);
		world.setBlock(i + 8, j + 2, k + 1, 0);
		world.setBlock(i + 8, j + 2, k + 2, 0);
		world.setBlock(i + 8, j + 2, k + 3, 0);
		world.setBlock(i + 8, j + 2, k + 4, 0);
		world.setBlock(i + 8, j + 2, k + 5, 0);
		world.setBlock(i + 8, j + 2, k + 6, 0);
		world.setBlock(i + 8, j + 2, k + 7, 0);
		world.setBlock(i + 8, j + 2, k + 9, 0);
		world.setBlock(i + 8, j + 2, k + 10, 0);
		world.setBlock(i + 8, j + 2, k + 11, 0);
		world.setBlock(i + 8, j + 2, k + 12, 0);
		world.setBlock(i + 8, j + 2, k + 13, 0);
		world.setBlock(i + 8, j + 2, k + 14, 0);
		world.setBlock(i + 8, j + 2, k + 15, 0);
		world.setBlock(i + 8, j + 2, k + 17, 0);
		world.setBlock(i + 8, j + 3, k + 2, 0);
		world.setBlock(i + 8, j + 3, k + 3, 0);
		world.setBlock(i + 8, j + 3, k + 4, 0);
		world.setBlock(i + 8, j + 3, k + 5, 0);
		world.setBlock(i + 8, j + 3, k + 6, 0);
		world.setBlock(i + 8, j + 3, k + 7, 0);
		world.setBlock(i + 8, j + 3, k + 9, 0);
		world.setBlock(i + 8, j + 3, k + 10, 0);
		world.setBlock(i + 8, j + 3, k + 11, 0);
		world.setBlock(i + 8, j + 3, k + 12, 0);
		world.setBlock(i + 8, j + 3, k + 13, 0);
		world.setBlock(i + 8, j + 3, k + 14, 0);
		world.setBlock(i + 8, j + 3, k + 17, 0);
		world.setBlock(i + 8, j + 4, k + 3, 0);
		world.setBlock(i + 8, j + 4, k + 4, 0);
		world.setBlock(i + 8, j + 4, k + 5, 0);
		world.setBlock(i + 8, j + 4, k + 6, 0);
		world.setBlock(i + 8, j + 4, k + 7, 0);
		world.setBlock(i + 8, j + 4, k + 8, 0);
		world.setBlock(i + 8, j + 4, k + 9, 0);
		world.setBlock(i + 8, j + 4, k + 10, 0);
		world.setBlock(i + 8, j + 4, k + 11, 0);
		world.setBlock(i + 8, j + 4, k + 12, 0);
		world.setBlock(i + 8, j + 4, k + 13, 0);
		world.setBlock(i + 8, j + 4, k + 17, 0);
		world.setBlock(i + 8, j + 5, k + 5, 0);
		world.setBlock(i + 8, j + 5, k + 6, 0);
		world.setBlock(i + 8, j + 5, k + 7, 0);
		world.setBlock(i + 8, j + 5, k + 8, 0);
		world.setBlock(i + 8, j + 5, k + 9, 0);
		world.setBlock(i + 8, j + 5, k + 10, 0);
		world.setBlock(i + 8, j + 5, k + 11, 0);
		world.setBlock(i + 8, j + 5, k + 17, 0);
		world.setBlock(i + 8, j + 6, k + 17, 0);
		world.setBlock(i + 9, j + 1, k + 1, 0);
		world.setBlock(i + 9, j + 1, k + 2, 0);
		world.setBlock(i + 9, j + 1, k + 3, 0);
		world.setBlock(i + 9, j + 1, k + 4, 0);
		world.setBlock(i + 9, j + 1, k + 5, 0);
		world.setBlock(i + 9, j + 1, k + 6, 0);
		world.setBlock(i + 9, j + 1, k + 10, 0);
		world.setBlock(i + 9, j + 1, k + 11, 0);
		world.setBlock(i + 9, j + 1, k + 12, 0);
		world.setBlock(i + 9, j + 1, k + 13, 0);
		world.setBlock(i + 9, j + 1, k + 14, 0);
		world.setBlock(i + 9, j + 1, k + 15, 0);
		world.setBlock(i + 9, j + 1, k + 17, 0);
		world.setBlock(i + 9, j + 2, k + 1, 0);
		world.setBlock(i + 9, j + 2, k + 2, 0);
		world.setBlock(i + 9, j + 2, k + 3, 0);
		world.setBlock(i + 9, j + 2, k + 4, 0);
		world.setBlock(i + 9, j + 2, k + 5, 0);
		world.setBlock(i + 9, j + 2, k + 6, 0);
		world.setBlock(i + 9, j + 2, k + 7, 0);
		world.setBlock(i + 9, j + 2, k + 8, 0);
		world.setBlock(i + 9, j + 2, k + 9, 0);
		world.setBlock(i + 9, j + 2, k + 10, 0);
		world.setBlock(i + 9, j + 2, k + 11, 0);
		world.setBlock(i + 9, j + 2, k + 12, 0);
		world.setBlock(i + 9, j + 2, k + 13, 0);
		world.setBlock(i + 9, j + 2, k + 14, 0);
		world.setBlock(i + 9, j + 2, k + 15, 0);
		world.setBlock(i + 9, j + 2, k + 17, 0);
		world.setBlock(i + 9, j + 3, k + 2, 0);
		world.setBlock(i + 9, j + 3, k + 3, 0);
		world.setBlock(i + 9, j + 3, k + 4, 0);
		world.setBlock(i + 9, j + 3, k + 5, 0);
		world.setBlock(i + 9, j + 3, k + 6, 0);
		world.setBlock(i + 9, j + 3, k + 7, 0);
		world.setBlock(i + 9, j + 3, k + 8, 0);
		world.setBlock(i + 9, j + 3, k + 9, 0);
		world.setBlock(i + 9, j + 3, k + 10, 0);
		world.setBlock(i + 9, j + 3, k + 11, 0);
		world.setBlock(i + 9, j + 3, k + 12, 0);
		world.setBlock(i + 9, j + 3, k + 13, 0);
		world.setBlock(i + 9, j + 3, k + 14, 0);
		world.setBlock(i + 9, j + 3, k + 17, 0);
		world.setBlock(i + 9, j + 4, k + 3, 0);
		world.setBlock(i + 9, j + 4, k + 4, 0);
		world.setBlock(i + 9, j + 4, k + 5, 0);
		world.setBlock(i + 9, j + 4, k + 6, 0);
		world.setBlock(i + 9, j + 4, k + 7, 0);
		world.setBlock(i + 9, j + 4, k + 8, 0);
		world.setBlock(i + 9, j + 4, k + 9, 0);
		world.setBlock(i + 9, j + 4, k + 10, 0);
		world.setBlock(i + 9, j + 4, k + 11, 0);
		world.setBlock(i + 9, j + 4, k + 12, 0);
		world.setBlock(i + 9, j + 4, k + 13, 0);
		world.setBlock(i + 9, j + 4, k + 17, 0);
		world.setBlock(i + 9, j + 5, k + 5, 0);
		world.setBlock(i + 9, j + 5, k + 6, 0);
		world.setBlock(i + 9, j + 5, k + 7, 0);
		world.setBlock(i + 9, j + 5, k + 8, 0);
		world.setBlock(i + 9, j + 5, k + 9, 0);
		world.setBlock(i + 9, j + 5, k + 10, 0);
		world.setBlock(i + 9, j + 5, k + 11, 0);
		world.setBlock(i + 9, j + 5, k + 17, 0);
		world.setBlock(i + 9, j + 6, k + 17, 0);
		world.setBlock(i + 10, j + 1, k + 1, 0);
		world.setBlock(i + 10, j + 1, k + 2, 0);
		world.setBlock(i + 10, j + 1, k + 3, 0);
		world.setBlock(i + 10, j + 1, k + 4, 0);
		world.setBlock(i + 10, j + 1, k + 5, 0);
		world.setBlock(i + 10, j + 1, k + 6, 0);
		world.setBlock(i + 10, j + 1, k + 7, 0);
		world.setBlock(i + 10, j + 1, k + 8, 0);
		world.setBlock(i + 10, j + 1, k + 9, 0);
		world.setBlock(i + 10, j + 1, k + 10, 0);
		world.setBlock(i + 10, j + 1, k + 11, 0);
		world.setBlock(i + 10, j + 1, k + 12, 0);
		world.setBlock(i + 10, j + 1, k + 13, 0);
		world.setBlock(i + 10, j + 1, k + 14, 0);
		world.setBlock(i + 10, j + 1, k + 15, 0);
		world.setBlock(i + 10, j + 1, k + 17, 0);
		world.setBlock(i + 10, j + 2, k + 1, 0);
		world.setBlock(i + 10, j + 2, k + 2, 0);
		world.setBlock(i + 10, j + 2, k + 3, 0);
		world.setBlock(i + 10, j + 2, k + 4, 0);
		world.setBlock(i + 10, j + 2, k + 5, 0);
		world.setBlock(i + 10, j + 2, k + 6, 0);
		world.setBlock(i + 10, j + 2, k + 7, 0);
		world.setBlock(i + 10, j + 2, k + 8, 0);
		world.setBlock(i + 10, j + 2, k + 9, 0);
		world.setBlock(i + 10, j + 2, k + 10, 0);
		world.setBlock(i + 10, j + 2, k + 11, 0);
		world.setBlock(i + 10, j + 2, k + 12, 0);
		world.setBlock(i + 10, j + 2, k + 13, 0);
		world.setBlock(i + 10, j + 2, k + 14, 0);
		world.setBlock(i + 10, j + 2, k + 15, 0);
		world.setBlock(i + 10, j + 2, k + 17, 0);
		world.setBlock(i + 10, j + 3, k + 2, 0);
		world.setBlock(i + 10, j + 3, k + 3, 0);
		world.setBlock(i + 10, j + 3, k + 4, 0);
		world.setBlock(i + 10, j + 3, k + 5, 0);
		world.setBlock(i + 10, j + 3, k + 6, 0);
		world.setBlock(i + 10, j + 3, k + 7, 0);
		world.setBlock(i + 10, j + 3, k + 8, 0);
		world.setBlock(i + 10, j + 3, k + 9, 0);
		world.setBlock(i + 10, j + 3, k + 10, 0);
		world.setBlock(i + 10, j + 3, k + 11, 0);
		world.setBlock(i + 10, j + 3, k + 12, 0);
		world.setBlock(i + 10, j + 3, k + 13, 0);
		world.setBlock(i + 10, j + 3, k + 14, 0);
		world.setBlock(i + 10, j + 3, k + 17, 0);
		world.setBlock(i + 10, j + 4, k + 3, 0);
		world.setBlock(i + 10, j + 4, k + 4, 0);
		world.setBlock(i + 10, j + 4, k + 5, 0);
		world.setBlock(i + 10, j + 4, k + 6, 0);
		world.setBlock(i + 10, j + 4, k + 7, 0);
		world.setBlock(i + 10, j + 4, k + 8, 0);
		world.setBlock(i + 10, j + 4, k + 9, 0);
		world.setBlock(i + 10, j + 4, k + 10, 0);
		world.setBlock(i + 10, j + 4, k + 11, 0);
		world.setBlock(i + 10, j + 4, k + 12, 0);
		world.setBlock(i + 10, j + 4, k + 13, 0);
		world.setBlock(i + 10, j + 4, k + 17, 0);
		world.setBlock(i + 10, j + 5, k + 5, 0);
		world.setBlock(i + 10, j + 5, k + 6, 0);
		world.setBlock(i + 10, j + 5, k + 7, 0);
		world.setBlock(i + 10, j + 5, k + 8, 0);
		world.setBlock(i + 10, j + 5, k + 9, 0);
		world.setBlock(i + 10, j + 5, k + 10, 0);
		world.setBlock(i + 10, j + 5, k + 11, 0);
		world.setBlock(i + 10, j + 5, k + 17, 0);
		world.setBlock(i + 10, j + 6, k + 17, 0);
		world.setBlock(i + 11, j + 1, k + 2, 0);
		world.setBlock(i + 11, j + 1, k + 3, 0);
		world.setBlock(i + 11, j + 1, k + 4, 0);
		world.setBlock(i + 11, j + 1, k + 5, 0);
		world.setBlock(i + 11, j + 1, k + 6, 0);
		world.setBlock(i + 11, j + 1, k + 7, 0);
		world.setBlock(i + 11, j + 1, k + 8, 0);
		world.setBlock(i + 11, j + 1, k + 9, 0);
		world.setBlock(i + 11, j + 1, k + 10, 0);
		world.setBlock(i + 11, j + 1, k + 11, 0);
		world.setBlock(i + 11, j + 1, k + 12, 0);
		world.setBlock(i + 11, j + 1, k + 13, 0);
		world.setBlock(i + 11, j + 1, k + 14, 0);
		world.setBlock(i + 11, j + 1, k + 17, 0);
		world.setBlock(i + 11, j + 2, k + 2, 0);
		world.setBlock(i + 11, j + 2, k + 3, 0);
		world.setBlock(i + 11, j + 2, k + 4, 0);
		world.setBlock(i + 11, j + 2, k + 5, 0);
		world.setBlock(i + 11, j + 2, k + 6, 0);
		world.setBlock(i + 11, j + 2, k + 7, 0);
		world.setBlock(i + 11, j + 2, k + 8, 0);
		world.setBlock(i + 11, j + 2, k + 9, 0);
		world.setBlock(i + 11, j + 2, k + 10, 0);
		world.setBlock(i + 11, j + 2, k + 11, 0);
		world.setBlock(i + 11, j + 2, k + 12, 0);
		world.setBlock(i + 11, j + 2, k + 13, 0);
		world.setBlock(i + 11, j + 2, k + 14, 0);
		world.setBlock(i + 11, j + 2, k + 17, 0);
		world.setBlock(i + 11, j + 3, k + 3, 0);
		world.setBlock(i + 11, j + 3, k + 4, 0);
		world.setBlock(i + 11, j + 3, k + 5, 0);
		world.setBlock(i + 11, j + 3, k + 6, 0);
		world.setBlock(i + 11, j + 3, k + 7, 0);
		world.setBlock(i + 11, j + 3, k + 8, 0);
		world.setBlock(i + 11, j + 3, k + 9, 0);
		world.setBlock(i + 11, j + 3, k + 10, 0);
		world.setBlock(i + 11, j + 3, k + 11, 0);
		world.setBlock(i + 11, j + 3, k + 12, 0);
		world.setBlock(i + 11, j + 3, k + 13, 0);
		world.setBlock(i + 11, j + 3, k + 17, 0);
		world.setBlock(i + 11, j + 4, k + 4, 0);
		world.setBlock(i + 11, j + 4, k + 5, 0);
		world.setBlock(i + 11, j + 4, k + 6, 0);
		world.setBlock(i + 11, j + 4, k + 7, 0);
		world.setBlock(i + 11, j + 4, k + 8, 0);
		world.setBlock(i + 11, j + 4, k + 9, 0);
		world.setBlock(i + 11, j + 4, k + 10, 0);
		world.setBlock(i + 11, j + 4, k + 11, 0);
		world.setBlock(i + 11, j + 4, k + 12, 0);
		world.setBlock(i + 11, j + 4, k + 17, 0);
		world.setBlock(i + 11, j + 5, k + 6, 0);
		world.setBlock(i + 11, j + 5, k + 7, 0);
		world.setBlock(i + 11, j + 5, k + 8, 0);
		world.setBlock(i + 11, j + 5, k + 9, 0);
		world.setBlock(i + 11, j + 5, k + 10, 0);
		world.setBlock(i + 11, j + 5, k + 17, 0);
		world.setBlock(i + 11, j + 6, k + 17, 0);
		world.setBlock(i + 12, j + 1, k + 2, 0);
		world.setBlock(i + 12, j + 1, k + 3, 0);
		world.setBlock(i + 12, j + 1, k + 4, 0);
		world.setBlock(i + 12, j + 1, k + 5, 0);
		world.setBlock(i + 12, j + 1, k + 6, 0);
		world.setBlock(i + 12, j + 1, k + 7, 0);
		world.setBlock(i + 12, j + 1, k + 8, 0);
		world.setBlock(i + 12, j + 1, k + 9, 0);
		world.setBlock(i + 12, j + 1, k + 10, 0);
		world.setBlock(i + 12, j + 1, k + 11, 0);
		world.setBlock(i + 12, j + 1, k + 12, 0);
		world.setBlock(i + 12, j + 1, k + 13, 0);
		world.setBlock(i + 12, j + 1, k + 14, 0);
		world.setBlock(i + 12, j + 1, k + 17, 0);
		world.setBlock(i + 12, j + 2, k + 2, 0);
		world.setBlock(i + 12, j + 2, k + 3, 0);
		world.setBlock(i + 12, j + 2, k + 4, 0);
		world.setBlock(i + 12, j + 2, k + 5, 0);
		world.setBlock(i + 12, j + 2, k + 6, 0);
		world.setBlock(i + 12, j + 2, k + 7, 0);
		world.setBlock(i + 12, j + 2, k + 8, 0);
		world.setBlock(i + 12, j + 2, k + 9, 0);
		world.setBlock(i + 12, j + 2, k + 10, 0);
		world.setBlock(i + 12, j + 2, k + 11, 0);
		world.setBlock(i + 12, j + 2, k + 12, 0);
		world.setBlock(i + 12, j + 2, k + 13, 0);
		world.setBlock(i + 12, j + 2, k + 14, 0);
		world.setBlock(i + 12, j + 2, k + 17, 0);
		world.setBlock(i + 12, j + 3, k + 3, 0);
		world.setBlock(i + 12, j + 3, k + 4, 0);
		world.setBlock(i + 12, j + 3, k + 5, 0);
		world.setBlock(i + 12, j + 3, k + 6, 0);
		world.setBlock(i + 12, j + 3, k + 7, 0);
		world.setBlock(i + 12, j + 3, k + 8, 0);
		world.setBlock(i + 12, j + 3, k + 9, 0);
		world.setBlock(i + 12, j + 3, k + 10, 0);
		world.setBlock(i + 12, j + 3, k + 11, 0);
		world.setBlock(i + 12, j + 3, k + 12, 0);
		world.setBlock(i + 12, j + 3, k + 13, 0);
		world.setBlock(i + 12, j + 3, k + 17, 0);
		world.setBlock(i + 12, j + 4, k + 4, 0);
		world.setBlock(i + 12, j + 4, k + 5, 0);
		world.setBlock(i + 12, j + 4, k + 6, 0);
		world.setBlock(i + 12, j + 4, k + 7, 0);
		world.setBlock(i + 12, j + 4, k + 8, 0);
		world.setBlock(i + 12, j + 4, k + 9, 0);
		world.setBlock(i + 12, j + 4, k + 10, 0);
		world.setBlock(i + 12, j + 4, k + 11, 0);
		world.setBlock(i + 12, j + 4, k + 12, 0);
		world.setBlock(i + 12, j + 4, k + 17, 0);
		world.setBlock(i + 12, j + 5, k + 17, 0);
		world.setBlock(i + 12, j + 6, k + 17, 0);
		world.setBlock(i + 13, j + 1, k + 3, 0);
		world.setBlock(i + 13, j + 1, k + 4, 0);
		world.setBlock(i + 13, j + 1, k + 5, 0);
		world.setBlock(i + 13, j + 1, k + 6, 0);
		world.setBlock(i + 13, j + 1, k + 7, 0);
		world.setBlock(i + 13, j + 1, k + 8, 0);
		world.setBlock(i + 13, j + 1, k + 9, 0);
		world.setBlock(i + 13, j + 1, k + 10, 0);
		world.setBlock(i + 13, j + 1, k + 11, 0);
		world.setBlock(i + 13, j + 1, k + 12, 0);
		world.setBlock(i + 13, j + 1, k + 13, 0);
		world.setBlock(i + 13, j + 1, k + 17, 0);
		world.setBlock(i + 13, j + 2, k + 3, 0);
		world.setBlock(i + 13, j + 2, k + 4, 0);
		world.setBlock(i + 13, j + 2, k + 5, 0);
		world.setBlock(i + 13, j + 2, k + 6, 0);
		world.setBlock(i + 13, j + 2, k + 7, 0);
		world.setBlock(i + 13, j + 2, k + 8, 0);
		world.setBlock(i + 13, j + 2, k + 9, 0);
		world.setBlock(i + 13, j + 2, k + 10, 0);
		world.setBlock(i + 13, j + 2, k + 11, 0);
		world.setBlock(i + 13, j + 2, k + 12, 0);
		world.setBlock(i + 13, j + 2, k + 13, 0);
		world.setBlock(i + 13, j + 2, k + 17, 0);
		world.setBlock(i + 13, j + 3, k + 4, 0);
		world.setBlock(i + 13, j + 3, k + 5, 0);
		world.setBlock(i + 13, j + 3, k + 6, 0);
		world.setBlock(i + 13, j + 3, k + 7, 0);
		world.setBlock(i + 13, j + 3, k + 8, 0);
		world.setBlock(i + 13, j + 3, k + 9, 0);
		world.setBlock(i + 13, j + 3, k + 10, 0);
		world.setBlock(i + 13, j + 3, k + 11, 0);
		world.setBlock(i + 13, j + 3, k + 12, 0);
		world.setBlock(i + 13, j + 3, k + 17, 0);
		world.setBlock(i + 13, j + 4, k + 6, 0);
		world.setBlock(i + 13, j + 4, k + 7, 0);
		world.setBlock(i + 13, j + 4, k + 8, 0);
		world.setBlock(i + 13, j + 4, k + 9, 0);
		world.setBlock(i + 13, j + 4, k + 10, 0);
		world.setBlock(i + 13, j + 4, k + 17, 0);
		world.setBlock(i + 13, j + 5, k + 17, 0);
		world.setBlock(i + 13, j + 6, k + 17, 0);
		world.setBlock(i + 14, j + 1, k + 4, 0);
		world.setBlock(i + 14, j + 1, k + 5, 0);
		world.setBlock(i + 14, j + 1, k + 6, 0);
		world.setBlock(i + 14, j + 1, k + 7, 0);
		world.setBlock(i + 14, j + 1, k + 8, 0);
		world.setBlock(i + 14, j + 1, k + 9, 0);
		world.setBlock(i + 14, j + 1, k + 10, 0);
		world.setBlock(i + 14, j + 1, k + 11, 0);
		world.setBlock(i + 14, j + 1, k + 12, 0);
		world.setBlock(i + 14, j + 1, k + 17, 0);
		world.setBlock(i + 14, j + 2, k + 4, 0);
		world.setBlock(i + 14, j + 2, k + 5, 0);
		world.setBlock(i + 14, j + 2, k + 6, 0);
		world.setBlock(i + 14, j + 2, k + 7, 0);
		world.setBlock(i + 14, j + 2, k + 8, 0);
		world.setBlock(i + 14, j + 2, k + 9, 0);
		world.setBlock(i + 14, j + 2, k + 10, 0);
		world.setBlock(i + 14, j + 2, k + 11, 0);
		world.setBlock(i + 14, j + 2, k + 12, 0);
		world.setBlock(i + 14, j + 2, k + 17, 0);
		world.setBlock(i + 14, j + 3, k + 6, 0);
		world.setBlock(i + 14, j + 3, k + 7, 0);
		world.setBlock(i + 14, j + 3, k + 8, 0);
		world.setBlock(i + 14, j + 3, k + 9, 0);
		world.setBlock(i + 14, j + 3, k + 10, 0);
		world.setBlock(i + 14, j + 3, k + 17, 0);
		world.setBlock(i + 14, j + 4, k + 17, 0);
		world.setBlock(i + 14, j + 5, k + 17, 0);
		world.setBlock(i + 14, j + 6, k + 17, 0);
		world.setBlock(i + 15, j + 1, k + 6, 0);
		world.setBlock(i + 15, j + 1, k + 7, 0);
		world.setBlock(i + 15, j + 1, k + 8, 0);
		world.setBlock(i + 15, j + 1, k + 9, 0);
		world.setBlock(i + 15, j + 1, k + 10, 0);
		world.setBlock(i + 15, j + 1, k + 17, 0);
		world.setBlock(i + 15, j + 2, k + 6, 0);
		world.setBlock(i + 15, j + 2, k + 7, 0);
		world.setBlock(i + 15, j + 2, k + 8, 0);
		world.setBlock(i + 15, j + 2, k + 9, 0);
		world.setBlock(i + 15, j + 2, k + 10, 0);
		world.setBlock(i + 15, j + 2, k + 17, 0);
		world.setBlock(i + 15, j + 3, k + 17, 0);
		world.setBlock(i + 15, j + 4, k + 17, 0);
		world.setBlock(i + 15, j + 5, k + 17, 0);
		world.setBlock(i + 15, j + 6, k + 17, 0);
		world.setBlock(i + 16, j + 1, k + 17, 0);
		world.setBlock(i + 16, j + 2, k + 17, 0);
		world.setBlock(i + 16, j + 3, k + 17, 0);
		world.setBlock(i + 16, j + 4, k + 17, 0);
		world.setBlock(i + 16, j + 5, k + 17, 0);
		world.setBlock(i + 16, j + 6, k + 17, 0);
		world.setBlock(i + 17, j + 1, k + 0, 0);
		world.setBlock(i + 17, j + 1, k + 1, 0);
		world.setBlock(i + 17, j + 1, k + 2, 0);
		world.setBlock(i + 17, j + 1, k + 3, 0);
		world.setBlock(i + 17, j + 1, k + 4, 0);
		world.setBlock(i + 17, j + 1, k + 5, 0);
		world.setBlock(i + 17, j + 1, k + 6, 0);
		world.setBlock(i + 17, j + 1, k + 7, 0);
		world.setBlock(i + 17, j + 1, k + 8, 0);
		world.setBlock(i + 17, j + 1, k + 9, 0);
		world.setBlock(i + 17, j + 1, k + 10, 0);
		world.setBlock(i + 17, j + 1, k + 11, 0);
		world.setBlock(i + 17, j + 1, k + 12, 0);
		world.setBlock(i + 17, j + 1, k + 13, 0);
		world.setBlock(i + 17, j + 1, k + 14, 0);
		world.setBlock(i + 17, j + 1, k + 15, 0);
		world.setBlock(i + 17, j + 1, k + 16, 0);
		world.setBlock(i + 17, j + 1, k + 17, 0);
		world.setBlock(i + 17, j + 2, k + 0, 0);
		world.setBlock(i + 17, j + 2, k + 1, 0);
		world.setBlock(i + 17, j + 2, k + 2, 0);
		world.setBlock(i + 17, j + 2, k + 3, 0);
		world.setBlock(i + 17, j + 2, k + 4, 0);
		world.setBlock(i + 17, j + 2, k + 5, 0);
		world.setBlock(i + 17, j + 2, k + 6, 0);
		world.setBlock(i + 17, j + 2, k + 7, 0);
		world.setBlock(i + 17, j + 2, k + 8, 0);
		world.setBlock(i + 17, j + 2, k + 9, 0);
		world.setBlock(i + 17, j + 2, k + 10, 0);
		world.setBlock(i + 17, j + 2, k + 11, 0);
		world.setBlock(i + 17, j + 2, k + 12, 0);
		world.setBlock(i + 17, j + 2, k + 13, 0);
		world.setBlock(i + 17, j + 2, k + 14, 0);
		world.setBlock(i + 17, j + 2, k + 15, 0);
		world.setBlock(i + 17, j + 2, k + 16, 0);
		world.setBlock(i + 17, j + 2, k + 17, 0);
		world.setBlock(i + 17, j + 3, k + 0, 0);
		world.setBlock(i + 17, j + 3, k + 1, 0);
		world.setBlock(i + 17, j + 3, k + 2, 0);
		world.setBlock(i + 17, j + 3, k + 3, 0);
		world.setBlock(i + 17, j + 3, k + 4, 0);
		world.setBlock(i + 17, j + 3, k + 5, 0);
		world.setBlock(i + 17, j + 3, k + 6, 0);
		world.setBlock(i + 17, j + 3, k + 7, 0);
		world.setBlock(i + 17, j + 3, k + 8, 0);
		world.setBlock(i + 17, j + 3, k + 9, 0);
		world.setBlock(i + 17, j + 3, k + 10, 0);
		world.setBlock(i + 17, j + 3, k + 11, 0);
		world.setBlock(i + 17, j + 3, k + 12, 0);
		world.setBlock(i + 17, j + 3, k + 13, 0);
		world.setBlock(i + 17, j + 3, k + 14, 0);
		world.setBlock(i + 17, j + 3, k + 15, 0);
		world.setBlock(i + 17, j + 3, k + 16, 0);
		world.setBlock(i + 17, j + 3, k + 17, 0);
		world.setBlock(i + 17, j + 4, k + 0, 0);
		world.setBlock(i + 17, j + 4, k + 1, 0);
		world.setBlock(i + 17, j + 4, k + 2, 0);
		world.setBlock(i + 17, j + 4, k + 3, 0);
		world.setBlock(i + 17, j + 4, k + 4, 0);
		world.setBlock(i + 17, j + 4, k + 5, 0);
		world.setBlock(i + 17, j + 4, k + 6, 0);
		world.setBlock(i + 17, j + 4, k + 7, 0);
		world.setBlock(i + 17, j + 4, k + 8, 0);
		world.setBlock(i + 17, j + 4, k + 9, 0);
		world.setBlock(i + 17, j + 4, k + 10, 0);
		world.setBlock(i + 17, j + 4, k + 11, 0);
		world.setBlock(i + 17, j + 4, k + 12, 0);
		world.setBlock(i + 17, j + 4, k + 13, 0);
		world.setBlock(i + 17, j + 4, k + 14, 0);
		world.setBlock(i + 17, j + 4, k + 15, 0);
		world.setBlock(i + 17, j + 4, k + 16, 0);
		world.setBlock(i + 17, j + 4, k + 17, 0);
		world.setBlock(i + 17, j + 5, k + 0, 0);
		world.setBlock(i + 17, j + 5, k + 1, 0);
		world.setBlock(i + 17, j + 5, k + 2, 0);
		world.setBlock(i + 17, j + 5, k + 3, 0);
		world.setBlock(i + 17, j + 5, k + 4, 0);
		world.setBlock(i + 17, j + 5, k + 5, 0);
		world.setBlock(i + 17, j + 5, k + 6, 0);
		world.setBlock(i + 17, j + 5, k + 7, 0);
		world.setBlock(i + 17, j + 5, k + 8, 0);
		world.setBlock(i + 17, j + 5, k + 9, 0);
		world.setBlock(i + 17, j + 5, k + 10, 0);
		world.setBlock(i + 17, j + 5, k + 11, 0);
		world.setBlock(i + 17, j + 5, k + 12, 0);
		world.setBlock(i + 17, j + 5, k + 13, 0);
		world.setBlock(i + 17, j + 5, k + 14, 0);
		world.setBlock(i + 17, j + 5, k + 15, 0);
		world.setBlock(i + 17, j + 5, k + 16, 0);
		world.setBlock(i + 17, j + 5, k + 17, 0);
		world.setBlock(i + 17, j + 6, k + 0, 0);
		world.setBlock(i + 17, j + 6, k + 1, 0);
		world.setBlock(i + 17, j + 6, k + 2, 0);
		world.setBlock(i + 17, j + 6, k + 3, 0);
		world.setBlock(i + 17, j + 6, k + 4, 0);
		world.setBlock(i + 17, j + 6, k + 5, 0);
		world.setBlock(i + 17, j + 6, k + 6, 0);
		world.setBlock(i + 17, j + 6, k + 7, 0);
		world.setBlock(i + 17, j + 6, k + 8, 0);
		world.setBlock(i + 17, j + 6, k + 9, 0);
		world.setBlock(i + 17, j + 6, k + 10, 0);
		world.setBlock(i + 17, j + 6, k + 11, 0);
		world.setBlock(i + 17, j + 6, k + 12, 0);
		world.setBlock(i + 17, j + 6, k + 13, 0);
		world.setBlock(i + 17, j + 6, k + 14, 0);
		world.setBlock(i + 17, j + 6, k + 15, 0);
		world.setBlock(i + 17, j + 6, k + 16, 0);
		world.setBlock(i + 17, j + 6, k + 17, 0);
	}

}